Workbook

Sheet README
A1: Ucell — модель роста ARPU архивной базы
A3: Как пользоваться
A4: 1. Замените ЖЁЛТЫЕ ячейки на листе Inputs фактом от аналитиков (docs/09_data_request_for_analysts.md).
A5: 2. Лист Initiatives: синие ячейки — параметры инициатив (модальные значения бенчмарков). После пилотов подставьте фактические конверсии/отток.
A6: 3. Лист Monthly — помесячный движок на 24 мес.; лист Portfolio — итоги портфеля, динамика ARPU, график.
A7: 4. Лист AB_Calculator — размер выборок для пилотов; лист MC_Results — вероятности из Монте-Карло (значения из Python).
A8: 5. После изменения допущений в коде: python model/arpu_model.py && python model/build_excel.py
A10: Легенда
A11: Синий текст — ввод · Чёрный — формула · Зелёный — ссылка на другой лист · Жёлтая заливка — ключевая гипотеза, заменить фактом
A13: Единицы и определения
A14: Деньги — сум (UZS) без НДС 12%, если не указано «с НДС». Курс — лист Inputs.
A15: ARPU считается по КОГОРТЕ абонентов, бывших на архивных ТП на дату T0: мигрировавшие на актуальные ТП остаются в когорте.
... A20: adoption — добровольное принятие оффера (миграция, допродажа); reprice — изменение условий ТП для целевой группы (stay/downgrade/churn); relative — относительный прирост выручки всей когорты (платформа).

Sheet Inputs
A1: Базовые допущения
A3: Параметр | C3: Значение | D3: Ед. | E3: Источник / комментарий
A4: Абонентская база Ucell | C4: 11000000 | D4: абон. | E4: Ucell: >10,9 млн на начало 2026 (итоги 2025, kun.uz 25.02.2026)
A5: Доля абонентов на архивных ТП | C5: 0.4 | D5: % | E5: HYPOTHESIS — заменить фактом (запрос D1)
A6: Доля активных среди архивных (доход за 30 дн.) | C6: 0.8 | D6: % | E6: HYPOTHESIS — запрос D1
A7: Активная архивная когорта (N) | C7: =C4*C5*C6 -> 3520000 | D7: абон. | E7: Формула
A8: ARPU архивной когорты (ARPU0, net) | C8: =SUMPRODUCT(C17:C21,D17:D21) -> 18500 | D8: сум/мес | E8: Средневзвешенный по сегментам (ниже)
A9: Месячный отток архивной когорты (c) | C9: 0.015 | D9: % | E9: HYPOTHESIS — запрос D4
A10: НДС | C10: 0.12 | D10: % | E10: НК РУз: 12%
A11: Курс, сум за 1 USD | C11: 12100 | D11: сум | E11: ЦБ РУз, 2026: 11 950–12 205
A12: Рынок мобильной связи РУз, абонентов | C12: 36500000 | D12: абон. | E12: HYPOTHESIS: 35,6 млн на конец 2024 + рост
A13: Выручка когорты в месяц (R0 мес. 0) | C13: =C7*C8 -> 65120000000 | D13: сум/мес | E13: Формула
A15: Сегменты архивной когорты (HYPOTHESIS — проверить кластеризацией, запрос D2)
A16: Код | B16: Сегмент | C16: Доля когорты | D16: ARPU net, сум | E16: Абонентов | F16: Выручка/мес, сум
A17: S1 | B17: Спящие / почти нулевые (2-я SIM, ARPU<5k) | C17: 0.2 | D17: 3000 | E17: =$C$7*C17 -> 704000 | F17: =E17*D17 -> 2112000000
A18: S2 | B18: PAYG / голосовые, много кнопочных 2G/3G | C18: 0.2 | D18: 10000 | E18: =$C$7*C18 -> 704000 | F18: =E18*D18 -> 7040000000
A19: S3 | B19: Недооценённые старые пакеты (платят мало, потребляют много) | C19: 0.3 | D19: 21000 | E19: =$C$7*C19 -> 1056000 | F19: =E19*D19 -> 22176000000
A20: S4 | B20: Старые пакеты mid/high + докупка пакетов | C20: 0.2 | D20: 40000 | E20: =$C$7*C20 -> 704000 | F20: =E20*D20 -> 28160000000
A21: S5 | B21: Социально защищённые (жен. 55+, муж. 60+) | C21: 0.1 | D21: 16000 | E21: =$C$7*C21 -> 352000 | F21: =E21*D21 -> 5632000000
A22: Итого | C22: =SUM(C17:C21) -> 1 | E22: =SUM(E17:E21) -> 3520000 | F22: =SUM(F17:F21) -> 65120000000
A23: Проверка: сумма долей = 100% | C23: =IF(ABS(C22-1)<0.0001,"OK","ОШИБКА: доли ≠ 100%") -> OK

Sheet Initiatives
A1: Инициативы: параметры (синие) → производные (чёрные) → итоги из листа Monthly (зелёные)
A3: Параметр | B3: Ключ | C3: A1 | D3: A2 | E3: A3 | F3: A4 | G3: A5 | H3: A6 | I3: A7 | J3: A8 | K3: B1 | L3: B2 | M3: B3 | N3: B4 | O3: B5
A4: Название | B4: name | C4: «Ucell 30 — Upgrade»: мягкая миграция с подарком | D4: Точечная индексация недооценённых архивных ТП (more-for-more) | E4: PAYG → суточные/недельные микропакеты | F4: Smart add-on: пакет-«бустер» в момент исчерпания (opt-in автопродление) | G4: Контент-надстройка (Yandex Plus / OVVA / Ucell TV) для архивных ТП | H4: Реактивация спящих архивных SIM (win-back оффер) | I4: «Musofir»: пакеты роуминга/OTP для трудовых мигрантов на архивных ТП | J4: ОПЦИЯ: ежегодная индексация архивных пакетов на инфляцию (волна 2) | K4: AI Next-Best-Offer: персональные офферы в реальном времени (RTD/CVM) | L4: «Ucell Oila»: семейный/групповой аккаунт с общим пакетом | M4: Sunset-программа: вывод устаревших семейств ТП с ценовой защитой | N4: Апгрейд 2G/3G → 4G-смартфон в рассрочку (BNPL-партнёр) | O4: Персональные лимиты «Mobil avans» на ML-скоринге
A5: Группа (EASY/HARD) | B5: group | C5: EASY | D5: EASY | E5: EASY | F5: EASY | G5: EASY | H5: EASY | I5: EASY | J5: EASY | K5: HARD | L5: HARD | M5: HARD | N5: HARD | O5: HARD
A6: Тип механики | B6: type | C6: adoption | D6: reprice | E6: adoption | F6: adoption | G6: adoption | H6: adoption | I6: adoption | J6: reprice | K6: relative | L6: adoption | M6: reprice | N6: adoption | O6: adoption
A7: Сложность биллинг/интеграции (1–5) | B7: complexity | C7: 1 | D7: 1 | E7: 2 | F7: 2 | G7: 2 | H7: 1 | I7: 2 | J7: 1 | K7: 4 | L7: 4 | M7: 5 | N7: 4 | O7: 3
A8: Опция вне базового портфеля (1=да) | B8: optional | C8: 0 | D8: 0 | E8: 0 | F8: 0 | G8: 0 | H8: 0 | I8: 0 | J8: 1 | K8: 0 | L8: 0 | M8: 0 | N8: 0 | O8: 0
A9: ARPU целевого сегмента, сум | B9: segment_arpu | C9: 21000 | D9: 21000 | E9: 10000 | F9: 28000 | G9: 28000 | H9: 3000 | I9: 15000 | J9: 28000 | K9: 0 | L9: 28000 | M9: 15000 | N9: 10000 | O9: 14000
A10: Доля целевой группы от когорты | B10: eligible_share | C10: 0.46 | D10: 0.22 | E10: 0.2 | F10: 0.15 | G10: 0.35 | H10: 0.2 | I10: 0.06 | J10: 0.38 | K10: 0 | L10: 0.2 | M10: 0.25 | N10: 0.08 | O10: 0.3
A11: Охват коммуникацией | B11: reach | C11: 0.85 | D11: 0 | E11: 0.8 | F11: 0.9 | G11: 0.8 | H11: 0.7 | I11: 0.8 | J11: 0 | K11: 0 | L11: 0.8 | M11: 0 | N11: 0.7 | O11: 0.9
A12: Конверсия (take-up) | B12: takeup | C12: 0.12 | D12: 0 | E12: 0.15 | F12: 0.12 | G12: 0.025 | H12: 0.06 | I12: 0.18 | J12: 0 | K12: 0 | L12: 0.04 | M12: 0 | N12: 0.05 | O12: 0.18
A13: Каннибализация (сделали бы и так) | B13: cannibal | C13: 0.2 | D13: 0 | E13: 0.2 | F13: 0.45 | G13: 0.2 | H13: 0.2 | I13: 0.25 | J13: 0 | K13: 0 | L13: 0.1 | M13: 0 | N13: 0.35 | O13: 0.5
A14: ΔARPU на адоптера, сум/мес | B14: delta | C14: 6500 | D14: 0 | E14: 2500 | F14: 7500 | G14: 12000 | H14: 7000 | I14: 7000 | J14: 0 | K14: 0 | L14: 22000 | M14: 0 | N14: 10000 | O14: 3000
A15: Доп. отток от изменения/контакта | B15: churn_incr | C15: 0.002 | D15: 0.025 | E15: 0 | F15: 0 | G15: 0 | H15: 0 | I15: 0 | J15: 0.01 | K15: 0 | L15: 0 | M15: 0.04 | N15: 0 | O15: 0
A16: Снижение оттока адоптеров (отн.) | B16: churn_red | C16: 0.1 | D16: 0 | E16: 0.05 | F16: 0.05 | G16: 0.25 | H16: 0 | I16: 0.2 | J16: 0 | K16: 0 | L16: 0.3 | M16: 0 | N16: 0.2 | O16: 0.1
A17: Доля адоптеров, активных через 6 мес. (A6) | B17: adopter_decay_6m | C17: 1 | D17: 1 | E17: 1 | F17: 1 | G17: 1 | H17: 0.65 | I17: 1 | J17: 1 | K17: 1 | L17: 1 | M17: 1 | N17: 1 | O17: 1
A18: Повышение абонплаты, сум с НДС | B18: price_up_gross | C18: 0 | D18: 5000 | E18: 0 | F18: 0 | G18: 0 | H18: 0 | I18: 0 | J18: 2000 | K18: 0 | L18: 0 | M18: 6500 | N18: 0 | O18: 0
... A35: Вероятность запуска как задумано | B35: exec_prob | C35: 0.92 | D35: 0.8 | E35: 0.9 | F35: 0.9 | G35: 0.85 | H35: 0.92 | I35: 0.9 | J35: 0.65 | K35: 0.65 | L35: 0.65 | M35: 0.6 | N35: 0.6 | O35: 0.7
A37: ПРОИЗВОДНЫЕ
A38: Целевая группа, абон. | B38: elig | C38: =Inputs!$C$7*C$10 -> 1619200 | D38: =Inputs!$C$7*D$10 -> 774400 | E38: =Inputs!$C$7*E$10 -> 704000 | F38: =Inputs!$C$7*F$10 -> 528000 | G38: =Inputs!$C$7*G$10 -> 1232000 | H38: =Inputs!$C$7*H$10 -> 704000 | I38: =Inputs!$C$7*I$10 -> 211200 | J38: =Inputs!$C$7*J$10 -> 1337600 | ... O38: =Inputs!$C$7*O$10 -> 1056000
A39: Охвачено коммуникацией, абон. | B39: contacted | C39: =IF(C$6="adoption",C$38*C$11,IF(C$6="reprice",C$38,0)) -> 1376320 | D39: =IF(D$6="adoption",D$38*D$11,IF(D$6="reprice",D$38,0)) -> 774400 | E39: =IF(E$6="adoption",E$38*E$11,IF(E$6="reprice",E$38,0)) -> 563200 | F39: =IF(F$6="adoption",F$38*F$11,IF(F$6="reprice",F$38,0)) -> 475200 | G39: =IF(G$6="adoption",G$38*G$11,IF(G$6="reprice",G$38,0)) -> 985600 | H39: =IF(H$6="adoption",H$38*H$11,IF(H$6="reprice",H$38,0)) -> 492800 | I39: =IF(I$6="adoption",I$38*I$11,IF(I$6="reprice",I$38,0)) -> 168960 | J39: =IF(J$6="adoption",J$38*J$11,IF(J$6="reprice",J$38,0)) -> 1337600 | ... O39: =IF(O$6="adoption",O$38*O$11,IF(O$6="reprice",O$38,0)) -> 950400
A40: Адоптеры при полном наборе (инкр.), абон. | B40: a_final | C40: =IF(C$6="adoption",C$39*C$12*(1-C$13),0) -> 132126.72 | D40: =IF(D$6="adoption",D$39*D$12*(1-D$13),0) -> 0 | E40: =IF(E$6="adoption",E$39*E$12*(1-E$13),0) -> 67584 | F40: =IF(F$6="adoption",F$39*F$12*(1-F$13),0) -> 31363.2 | G40: =IF(G$6="adoption",G$39*G$12*(1-G$13),0) -> 19712 | H40: =IF(H$6="adoption",H$39*H$12*(1-H$13),0) -> 23654.4 | I40: =IF(I$6="adoption",I$39*I$12*(1-I$13),0) -> 22809.6 | J40: =IF(J$6="adoption",J$39*J$12*(1-J$13),0) -> 0 | ... O40: =IF(O$6="adoption",O$39*O$12*(1-O$13),0) -> 85536
A41: reprice: остаются и платят больше, абон. | B41: stay | C41: =IF(C$6="reprice",C$38*(1-C$19-C$15),0) -> 0 | D41: =IF(D$6="reprice",D$38*(1-D$19-D$15),0) -> 693088 | E41: =IF(E$6="reprice",E$38*(1-E$19-E$15),0) -> 0 | F41: =IF(F$6="reprice",F$38*(1-F$19-F$15),0) -> 0 | G41: =IF(G$6="reprice",G$38*(1-G$19-G$15),0) -> 0 | H41: =IF(H$6="reprice",H$38*(1-H$19-H$15),0) -> 0 | I41: =IF(I$6="reprice",I$38*(1-I$19-I$15),0) -> 0 | J41: =IF(J$6="reprice",J$38*(1-J$19-J$15),0) -> 1270720 | ... O41: =IF(O$6="reprice",O$38*(1-O$19-O$15),0) -> 0
A42: reprice: ушли на более дешёвый ТП, абон. | B42: down | C42: =IF(C$6="reprice",C$38*C$19,0) -> 0 | D42: =IF(D$6="reprice",D$38*D$19,0) -> 61952 | E42: =IF(E$6="reprice",E$38*E$19,0) -> 0 | F42: =IF(F$6="reprice",F$38*F$19,0) -> 0 | G42: =IF(G$6="reprice",G$38*G$19,0) -> 0 | H42: =IF(H$6="reprice",H$38*H$19,0) -> 0 | I42: =IF(I$6="reprice",I$38*I$19,0) -> 0 | J42: =IF(J$6="reprice",J$38*J$19,0) -> 53504 | ... O42: =IF(O$6="reprice",O$38*O$19,0) -> 0
A43: Доп. отток всего, абон. | B43: lost_total | C43: =IF(C$6="relative",0,C$39*C$15) -> 2752.64 | D43: =IF(D$6="relative",0,D$39*D$15) -> 19360 | E43: =IF(E$6="relative",0,E$39*E$15) -> 0 | F43: =IF(F$6="relative",0,F$39*F$15) -> 0 | G43: =IF(G$6="relative",0,G$39*G$15) -> 0 | H43: =IF(H$6="relative",0,H$39*H$15) -> 0 | I43: =IF(I$6="relative",0,I$39*I$15) -> 0 | J43: =IF(J$6="relative",0,J$39*J$15) -> 13376 | ... O43: =IF(O$6="relative",0,O$39*O$15) -> 0
A44: Повышение абонплаты net, сум | B44: up_net | C44: =C$18/(1+Inputs!$C$10) -> 0 | D44: =D$18/(1+Inputs!$C$10) -> 4464.2857 | E44: =E$18/(1+Inputs!$C$10) -> 0 | F44: =F$18/(1+Inputs!$C$10) -> 0 | G44: =G$18/(1+Inputs!$C$10) -> 0 | H44: =H$18/(1+Inputs!$C$10) -> 0 | I44: =I$18/(1+Inputs!$C$10) -> 0 | J44: =J$18/(1+Inputs!$C$10) -> 1785.7143 | ... O44: =O$18/(1+Inputs!$C$10) -> 0
A45: Темп «засыпания» адоптеров, в мес. | B45: decay_m | C45: =1-C$17^(1/6) -> 0 | D45: =1-D$17^(1/6) -> 0 | E45: =1-E$17^(1/6) -> 0 | F45: =1-F$17^(1/6) -> 0 | G45: =1-G$17^(1/6) -> 0 | H45: =1-H$17^(1/6) -> 0.069280329 | I45: =1-I$17^(1/6) -> 0 | J45: =1-J$17^(1/6) -> 0 | ... O45: =1-O$17^(1/6) -> 0
A46: Месяцев подготовки (разовые затраты) | B46: build | C46: =MAX(C$33-1,1) -> 1 | D46: =MAX(D$33-1,1) -> 1 | E46: =MAX(E$33-1,1) -> 1 | F46: =MAX(F$33-1,1) -> 1 | G46: =MAX(G$33-1,1) -> 2 | H46: =MAX(H$33-1,1) -> 1 | I46: =MAX(I$33-1,1) -> 2 | J46: =MAX(J$33-1,1) -> 13 | ... O46: =MAX(O$33-1,1) -> 5
A47: Месяцев распределения доп. оттока | B47: K | C47: =IF(C$6="reprice",2,3) -> 3 | D47: =IF(D$6="reprice",2,3) -> 2 | E47: =IF(E$6="reprice",2,3) -> 3 | F47: =IF(F$6="reprice",2,3) -> 3 | G47: =IF(G$6="reprice",2,3) -> 3 | H47: =IF(H$6="reprice",2,3) -> 3 | I47: =IF(I$6="reprice",2,3) -> 3 | J47: =IF(J$6="reprice",2,3) -> 2 | ... O47: =IF(O$6="reprice",2,3) -> 3
A48: Месяц оценки (12-й после запуска, ≤24) | B48: eval_m | C48: =MIN(C$33+11,24) -> 13 | D48: =MIN(D$33+11,24) -> 13 | E48: =MIN(E$33+11,24) -> 13 | F48: =MIN(F$33+11,24) -> 13 | G48: =MIN(G$33+11,24) -> 14 | H48: =MIN(H$33+11,24) -> 13 | I48: =MIN(I$33+11,24) -> 14 | J48: =MIN(J$33+11,24) -> 24 | ... O48: =MIN(O$33+11,24) -> 17
A50: ИТОГИ (из листа Monthly)
A51: Выручка Y1 (мес. 1–12), сум | B51: rev1 | C51: =SUM(Monthly!C14:N14)+SUM(Monthly!C15:N15) -> 7.3179048e+09 | D51: =SUM(Monthly!C28:N28)+SUM(Monthly!C29:N29) -> 2.5719985e+10 | E51: =SUM(Monthly!C42:N42)+SUM(Monthly!C43:N43) -> 1.6057907e+09 | F51: =SUM(Monthly!C56:N56)+SUM(Monthly!C57:N57) -> 2.3391784e+09 | G51: =SUM(Monthly!C70:N70)+SUM(Monthly!C71:N71) -> 1.9896857e+09 | H51: =SUM(Monthly!C84:N84)+SUM(Monthly!C85:N85) -> 1.1529593e+09 | I51: =SUM(Monthly!C98:N98)+SUM(Monthly!C99:N99) -> 1.4043123e+09 | J51: =SUM(Monthly!C112:N112)+SUM(Monthly!C113:N113) -> 0 | K51: =SUM(Monthly!C126:N126)+SUM(Monthly!C127:N127) -> 6.1807245e+09 | L51: =SUM(Monthly!C140:N140)+SUM(Monthly!C141:N141) -> 1.3505551e+09 | M51: =SUM(Monthly!C154:N154)+SUM(Monthly!C155:N155) -> 3.9521429e+09 | N51: =SUM(Monthly!C168:N168)+SUM(Monthly!C169:N169) -> 2.2088416e+08 | O51: =SUM(Monthly!C182:N182)+SUM(Monthly!C183:N183) -> 1.5139852e+09
A52: Выручка Y2 (мес. 13–24), сум | B52: rev2 | C52: =SUM(Monthly!O14:Z14)+SUM(Monthly!O15:Z15) -> 8.4716185e+09 | D52: =SUM(Monthly!O28:Z28)+SUM(Monthly!O29:Z29) -> 2.3397644e+10 | E52: =SUM(Monthly!O42:Z42)+SUM(Monthly!O43:Z43) -> 1.7005611e+09 | F52: =SUM(Monthly!O56:Z56)+SUM(Monthly!O57:Z57) -> 2.3467208e+09 | G52: =SUM(Monthly!O70:Z70)+SUM(Monthly!O71:Z71) -> 2.7143398e+09 | H52: =SUM(Monthly!O84:Z84)+SUM(Monthly!O85:Z85) -> 5.4151312e+08 | I52: =SUM(Monthly!O98:Z98)+SUM(Monthly!O99:Z99) -> 1.756884e+09 | J52: =SUM(Monthly!O112:Z112)+SUM(Monthly!O113:Z113) -> 1.8414311e+10 | K52: =SUM(Monthly!O126:Z126)+SUM(Monthly!O127:Z127) -> 2.210659e+10 | L52: =SUM(Monthly!O140:Z140)+SUM(Monthly!O141:Z141) -> 6.2165895e+09 | M52: =SUM(Monthly!O154:Z154)+SUM(Monthly!O155:Z155) -> 4.0127466e+10 | N52: =SUM(Monthly!O168:Z168)+SUM(Monthly!O169:Z169) -> 7.0858929e+08 | O52: =SUM(Monthly!O182:Z182)+SUM(Monthly!O183:Z183) -> 2.8469061e+09
A53: Run-rate выручки/год на мес. 24, сум | B53: runrate | C53: =(Monthly!Z14+Monthly!Z15)*12 -> 8.0688544e+09 | D53: =(Monthly!Z28+Monthly!Z29)*12 -> 2.150208e+10 | E53: =(Monthly!Z42+Monthly!Z43)*12 -> 1.5951189e+09 | F53: =(Monthly!Z56+Monthly!Z57)*12 -> 2.1989019e+09 | G53: =(Monthly!Z70+Monthly!Z71)*12 -> 2.6558431e+09 | H53: =(Monthly!Z84+Monthly!Z85)*12 -> 3.2110096e+08 | I53: =(Monthly!Z98+Monthly!Z99)*12 -> 1.6952985e+09 | J53: =(Monthly!Z112+Monthly!Z113)*12 -> 1.84129e+10 | K53: =(Monthly!Z126+Monthly!Z127)*12 -> 2.2631817e+10 | L53: =(Monthly!Z140+Monthly!Z141)*12 -> 6.0070844e+09 | M53: =(Monthly!Z154+Monthly!Z155)*12 -> 3.6876533e+10 | N53: =(Monthly!Z168+Monthly!Z169)*12 -> 6.7321956e+08 | O53: =(Monthly!Z182+Monthly!Z183)*12 -> 2.7352683e+09
A54: Run-rate выручки/год, USD | B54: runrate_usd | C54: =C$53/Inputs!$C$11 -> 666847.47 | D54: =D$53/Inputs!$C$11 -> 1777031.4 | E54: =E$53/Inputs!$C$11 -> 131828.01 | F54: =F$53/Inputs!$C$11 -> 181727.43 | G54: =G$53/Inputs!$C$11 -> 219491.17 | H54: =H$53/Inputs!$C$11 -> 26537.269 | I54: =I$53/Inputs!$C$11 -> 140107.31 | J54: =J$53/Inputs!$C$11 -> 1521727.2 | ... O54: =O$53/Inputs!$C$11 -> 226055.23
A55: Затраты за 24 мес., сум | B55: cost24 | C55: =SUM(Monthly!C16:Z16) -> 1560701440 | D55: =SUM(Monthly!C30:Z30) -> 6.2643797e+09 | E55: =SUM(Monthly!C44:Z44) -> 1.0984466e+09 | F55: =SUM(Monthly!C58:Z58) -> 9.0744142e+08 | G55: =SUM(Monthly!C72:Z72) -> 567840000 | H55: =SUM(Monthly!C86:Z86) -> 524883200 | I55: =SUM(Monthly!C100:Z100) -> 395344000 | J55: =SUM(Monthly!C114:Z114) -> 1.6912965e+09 | K55: =SUM(Monthly!C128:Z128) -> 11550000000 | L55: =SUM(Monthly!C142:Z142) -> 6.4981167e+09 | M55: =SUM(Monthly!C156:Z156) -> 1.0025933e+10 | N55: =SUM(Monthly!C170:Z170) -> 3.6525564e+09 | O55: =SUM(Monthly!C184:Z184) -> 3307520000
A56: Вклад (маржа − затраты) за 24 мес., сум | B56: contrib24 | C56: =SUM(Monthly!C17:Z17) -> 1.1860393e+10 | D56: =SUM(Monthly!C31:Z31) -> 4.2853249e+10 | E56: =SUM(Monthly!C45:Z45) -> 1.7119524e+09 | F56: =SUM(Monthly!C59:Z59) -> 3.0755729e+09 | G56: =SUM(Monthly!C73:Z73) -> 8.4336762e+08 | H56: =SUM(Monthly!C87:Z87) -> 9.1541833e+08 | I56: =SUM(Monthly!C101:Z101) -> 1.5013738e+09 | J56: =SUM(Monthly!C115:Z115) -> 1.6723015e+10 | K56: =SUM(Monthly!C129:Z129) -> 1.2494218e+10 | L56: =SUM(Monthly!C143:Z143) -> -66043748 | M56: =SUM(Monthly!C157:Z157) -> 3.4053675e+10 | N56: =SUM(Monthly!C171:Z171) -> -2.862504e+09 | O56: =SUM(Monthly!C185:Z185) -> -2.5489609e+08
A57: ROI за 24 мес. (вклад / затраты) | B57: roi | C57: =IF(C$55>0,C$56/C$55,0) -> 7.5993993 | D57: =IF(D$55>0,D$56/D$55,0) -> 6.8407809 | E57: =IF(E$55>0,E$56/E$55,0) -> 1.5585212 | F57: =IF(F$55>0,F$56/F$55,0) -> 3.3892798 | G57: =IF(G$55>0,G$56/G$55,0) -> 1.4852205 | H57: =IF(H$55>0,H$56/H$55,0) -> 1.744042 | I57: =IF(I$55>0,I$56/I$55,0) -> 3.797639 | J57: =IF(J$55>0,J$56/J$55,0) -> 9.8876894 | ... O57: =IF(O$55>0,O$56/O$55,0) -> -0.077065623
A58: ΔARPU когорты на месяц оценки | B58: upl_eval | C58: =(INDEX(Monthly!$C$5:$Z$5,1,C$48)+INDEX(Monthly!$C$14:$Z$14,1,C$48))/(INDEX(Monthly!$C$4:$Z$4,1,C$48)+INDEX(Monthly!$C$18:$Z$18,1,C$48))/Inputs!$C$8-1 -> 0.014079405 | D58: =(INDEX(Monthly!$C$5:$Z$5,1,D$48)+INDEX(Monthly!$C$28:$Z$28,1,D$48))/(INDEX(Monthly!$C$4:$Z$4,1,D$48)+INDEX(Monthly!$C$32:$Z$32,1,D$48))/Inputs!$C$8-1 -> 0.045519115 | E58: =(INDEX(Monthly!$C$5:$Z$5,1,E$48)+INDEX(Monthly!$C$42:$Z$42,1,E$48))/(INDEX(Monthly!$C$4:$Z$4,1,E$48)+INDEX(Monthly!$C$46:$Z$46,1,E$48))/Inputs!$C$8-1 -> 0.0026650034 | F58: =(INDEX(Monthly!$C$5:$Z$5,1,F$48)+INDEX(Monthly!$C$56:$Z$56,1,F$48))/(INDEX(Monthly!$C$4:$Z$4,1,F$48)+INDEX(Monthly!$C$60:$Z$60,1,F$48))/Inputs!$C$8-1 -> 0.0038192832 | G58: =(INDEX(Monthly!$C$5:$Z$5,1,G$48)+INDEX(Monthly!$C$70:$Z$70,1,G$48))/(INDEX(Monthly!$C$4:$Z$4,1,G$48)+INDEX(Monthly!$C$74:$Z$74,1,G$48))/Inputs!$C$8-1 -> 0.0041433641 | H58: =(INDEX(Monthly!$C$5:$Z$5,1,H$48)+INDEX(Monthly!$C$84:$Z$84,1,H$48))/(INDEX(Monthly!$C$4:$Z$4,1,H$48)+INDEX(Monthly!$C$88:$Z$88,1,H$48))/Inputs!$C$8-1 -> 0.001300974 | I58: =(INDEX(Monthly!$C$5:$Z$5,1,I$48)+INDEX(Monthly!$C$98:$Z$98,1,I$48))/(INDEX(Monthly!$C$4:$Z$4,1,I$48)+INDEX(Monthly!$C$102:$Z$102,1,I$48))/Inputs!$C$8-1 -> 0.0026445083 | J58: =(INDEX(Monthly!$C$5:$Z$5,1,J$48)+INDEX(Monthly!$C$112:$Z$112,1,J$48))/(INDEX(Monthly!$C$4:$Z$4,1,J$48)+INDEX(Monthly!$C$116:$Z$116,1,J$48))/Inputs!$C$8-1 -> 0.038780132 | K58: =(INDEX(Monthly!$C$5:$Z$5,1,K$48)+INDEX(Monthly!$C$126:$Z$126,1,K$48))/(INDEX(Monthly!$C$4:$Z$4,1,K$48)+INDEX(Monthly!$C$130:$Z$130,1,K$48))/Inputs!$C$8-1 -> 0.029765596 | L58: =(INDEX(Monthly!$C$5:$Z$5,1,L$48)+INDEX(Monthly!$C$140:$Z$140,1,L$48))/(INDEX(Monthly!$C$4:$Z$4,1,L$48)+INDEX(Monthly!$C$144:$Z$144,1,L$48))/Inputs!$C$8-1 -> 0.0085341902 | M58: =(INDEX(Monthly!$C$5:$Z$5,1,M$48)+INDEX(Monthly!$C$154:$Z$154,1,M$48))/(INDEX(Monthly!$C$4:$Z$4,1,M$48)+INDEX(Monthly!$C$158:$Z$158,1,M$48))/Inputs!$C$8-1 -> 0.080881056 | N58: =(INDEX(Monthly!$C$5:$Z$5,1,N$48)+INDEX(Monthly!$C$168:$Z$168,1,N$48))/(INDEX(Monthly!$C$4:$Z$4,1,N$48)+INDEX(Monthly!$C$172:$Z$172,1,N$48))/Inputs!$C$8-1 -> 0.0011404358 | O58: =(INDEX(Monthly!$C$5:$Z$5,1,O$48)+INDEX(Monthly!$C$182:$Z$182,1,O$48))/(INDEX(Monthly!$C$4:$Z$4,1,O$48)+INDEX(Monthly!$C$186:$Z$186,1,O$48))/Inputs!$C$8-1 -> 0.0043452665
A59: ΔARPU когорты на мес. 24 | B59: upl24 | C59: =(Monthly!Z$5+Monthly!Z14)/(Monthly!Z$4+Monthly!Z18)/Inputs!$C$8-1 -> 0.014399468 | D59: =(Monthly!Z$5+Monthly!Z28)/(Monthly!Z$4+Monthly!Z32)/Inputs!$C$8-1 -> 0.045519115 | E59: =(Monthly!Z$5+Monthly!Z42)/(Monthly!Z$4+Monthly!Z46)/Inputs!$C$8-1 -> 0.0026093627 | F59: =(Monthly!Z$5+Monthly!Z56)/(Monthly!Z$4+Monthly!Z60)/Inputs!$C$8-1 -> 0.0038910367 | G59: =(Monthly!Z$5+Monthly!Z70)/(Monthly!Z$4+Monthly!Z74)/Inputs!$C$8-1 -> 0.0044219761 | H59: =(Monthly!Z$5+Monthly!Z84)/(Monthly!Z$4+Monthly!Z88)/Inputs!$C$8-1 -> 0.00059057687 | I59: =(Monthly!Z$5+Monthly!Z98)/(Monthly!Z$4+Monthly!Z102)/Inputs!$C$8-1 -> 0.0026853683 | J59: =(Monthly!Z$5+Monthly!Z112)/(Monthly!Z$4+Monthly!Z116)/Inputs!$C$8-1 -> 0.038780132 | K59: =(Monthly!Z$5+Monthly!Z126)/(Monthly!Z$4+Monthly!Z130)/Inputs!$C$8-1 -> 0.029655258 | L59: =(Monthly!Z$5+Monthly!Z140)/(Monthly!Z$4+Monthly!Z144)/Inputs!$C$8-1 -> 0.0087538549 | M59: =(Monthly!Z$5+Monthly!Z154)/(Monthly!Z$4+Monthly!Z158)/Inputs!$C$8-1 -> 0.080881056 | N59: =(Monthly!Z$5+Monthly!Z168)/(Monthly!Z$4+Monthly!Z172)/Inputs!$C$8-1 -> 0.0011436099 | O59: =(Monthly!Z$5+Monthly!Z182)/(Monthly!Z$4+Monthly!Z186)/Inputs!$C$8-1 -> 0.0043201933
...

Sheet Monthly
A1: Помесячный движок, 24 мес. (формулы; сум без НДС)
A3: Месяц | C3: 1 | D3: 2 | E3: 3 | F3: 4 | G3: 5 | H3: 6 | I3: 7 | J3: 8 | K3: 9 | L3: 10 | M3: 11 | N3: 12 | O3: 13 | P3: 14 | Q3: 15 | R3: 16 | S3: 17 | T3: 18 | U3: 19 | V3: 20 | W3: 21 | X3: 22 | Y3: 23 | Z3: 24
A4: S0: абоненты когорты без инициатив | C4: =Inputs!$C$7*(1-Inputs!$C$9)^C$3 -> 3467200 | D4: =Inputs!$C$7*(1-Inputs!$C$9)^D$3 -> 3415192 | E4: =Inputs!$C$7*(1-Inputs!$C$9)^E$3 -> 3363964.1 | F4: =Inputs!$C$7*(1-Inputs!$C$9)^F$3 -> 3313504.7 | G4: =Inputs!$C$7*(1-Inputs!$C$9)^G$3 -> 3263802.1 | H4: =Inputs!$C$7*(1-Inputs!$C$9)^H$3 -> 3214845.1 | I4: =Inputs!$C$7*(1-Inputs!$C$9)^I$3 -> 3166622.4 | J4: =Inputs!$C$7*(1-Inputs!$C$9)^J$3 -> 3119123 | ... Z4: =Inputs!$C$7*(1-Inputs!$C$9)^Z$3 -> 2449132
A5: R0: выручка когорты без инициатив | C5: =C4*Inputs!$C$8 -> 64143200000 | D5: =D4*Inputs!$C$8 -> 63181052000 | E5: =E4*Inputs!$C$8 -> 62233336220 | F5: =F4*Inputs!$C$8 -> 6.1299836e+10 | G5: =G4*Inputs!$C$8 -> 6.0380339e+10 | H5: =H4*Inputs!$C$8 -> 5.9474634e+10 | I5: =I4*Inputs!$C$8 -> 5.8582514e+10 | J5: =J4*Inputs!$C$8 -> 5.7703776e+10 | ... Z5: =Z4*Inputs!$C$8 -> 4.5308942e+10
A7: A1 — «Ucell 30 — Upgrade»: мягкая миграция с подарком
A8: Доля набора | B8: f | C8: =IF(C$3<Initiatives!$C$33,0,MIN((C$3-Initiatives!$C$33+1)/Initiatives!$C$34,1)) -> 0 | D8: =IF(D$3<Initiatives!$C$33,0,MIN((D$3-Initiatives!$C$33+1)/Initiatives!$C$34,1)) -> 0.25 | E8: =IF(E$3<Initiatives!$C$33,0,MIN((E$3-Initiatives!$C$33+1)/Initiatives!$C$34,1)) -> 0.5 | F8: =IF(F$3<Initiatives!$C$33,0,MIN((F$3-Initiatives!$C$33+1)/Initiatives!$C$34,1)) -> 0.75 | G8: =IF(G$3<Initiatives!$C$33,0,MIN((G$3-Initiatives!$C$33+1)/Initiatives!$C$34,1)) -> 1 | H8: =IF(H$3<Initiatives!$C$33,0,MIN((H$3-Initiatives!$C$33+1)/Initiatives!$C$34,1)) -> 1 | I8: =IF(I$3<Initiatives!$C$33,0,MIN((I$3-Initiatives!$C$33+1)/Initiatives!$C$34,1)) -> 1 | J8: =IF(J$3<Initiatives!$C$33,0,MIN((J$3-Initiatives!$C$33+1)/Initiatives!$C$34,1)) -> 1 | ... Z8: =IF(Z$3<Initiatives!$C$33,0,MIN((Z$3-Initiatives!$C$33+1)/Initiatives!$C$34,1)) -> 1
A9: Адоптеры (цель) | B9: target | C9: =Initiatives!$C$40*C8 -> 0 | D9: =Initiatives!$C$40*D8 -> 33031.68 | E9: =Initiatives!$C$40*E8 -> 66063.36 | F9: =Initiatives!$C$40*F8 -> 99095.04 | G9: =Initiatives!$C$40*G8 -> 132126.72 | H9: =Initiatives!$C$40*H8 -> 132126.72 | I9: =Initiatives!$C$40*I8 -> 132126.72 | J9: =Initiatives!$C$40*J8 -> 132126.72 | ... Z9: =Initiatives!$C$40*Z8 -> 132126.72
A10: Новые адоптеры | B10: new | C10: =MAX(C9-N(B9),0) -> 0 | D10: =MAX(D9-N(C9),0) -> 33031.68 | E10: =MAX(E9-N(D9),0) -> 33031.68 | F10: =MAX(F9-N(E9),0) -> 33031.68 | G10: =MAX(G9-N(F9),0) -> 33031.68 | H10: =MAX(H9-N(G9),0) -> 0 | I10: =MAX(I9-N(H9),0) -> 0 | J10: =MAX(J9-N(I9),0) -> 0 | ... Z10: =MAX(Z9-N(Y9),0) -> 0
A11: Удержанные (эффект оттока) | B11: R | C11: =IF(Initiatives!$C$6="adoption",N(B11)*(1-Inputs!$C$9)+N(B12)*Inputs!$C$9*Initiatives!$C$16,IF(Initiatives!$C$6="relative",N(B11)*(1-Inputs!$C$9)+C$4*Inputs!$C$9*Initiatives!$C$23*C8,0)) -> 0 | D11: =IF(Initiatives!$C$6="adoption",N(C11)*(1-Inputs!$C$9)+N(C12)*Inputs!$C$9*Initiatives!$C$16,IF(Initiatives!$C$6="relative",N(C11)*(1-Inputs!$C$9)+D$4*Inputs!$C$9*Initiatives!$C$23*D8,0)) -> 0 | E11: =IF(Initiatives!$C$6="adoption",N(D11)*(1-Inputs!$C$9)+N(D12)*Inputs!$C$9*Initiatives!$C$16,IF(Initiatives!$C$6="relative",N(D11)*(1-Inputs!$C$9)+E$4*Inputs!$C$9*Initiatives!$C$23*E8,0)) -> 49.54752 | F11: =IF(Initiatives!$C$6="adoption",N(E11)*(1-Inputs!$C$9)+N(E12)*Inputs!$C$9*Initiatives!$C$16,IF(Initiatives!$C$6="relative",N(E11)*(1-Inputs!$C$9)+F$4*Inputs!$C$9*Initiatives!$C$23*F8,0)) -> 147.23046 | G11: =IF(Initiatives!$C$6="adoption",N(F11)*(1-Inputs!$C$9)+N(F12)*Inputs!$C$9*Initiatives!$C$16,IF(Initiatives!$C$6="relative",N(F11)*(1-Inputs!$C$9)+G$4*Inputs!$C$9*Initiatives!$C$23*G8,0)) -> 291.66691 | H11: =IF(Initiatives!$C$6="adoption",N(G11)*(1-Inputs!$C$9)+N(G12)*Inputs!$C$9*Initiatives!$C$16,IF(Initiatives!$C$6="relative",N(G11)*(1-Inputs!$C$9)+H$4*Inputs!$C$9*Initiatives!$C$23*H8,0)) -> 481.50464 | I11: =IF(Initiatives!$C$6="adoption",N(H11)*(1-Inputs!$C$9)+N(H12)*Inputs!$C$9*Initiatives!$C$16,IF(Initiatives!$C$6="relative",N(H11)*(1-Inputs!$C$9)+I$4*Inputs!$C$9*Initiatives!$C$23*I8,0)) -> 665.87293 | J11: =IF(Initiatives!$C$6="adoption",N(I11)*(1-Inputs!$C$9)+N(I12)*Inputs!$C$9*Initiatives!$C$16,IF(Initiatives!$C$6="relative",N(I11)*(1-Inputs!$C$9)+J$4*Inputs!$C$9*Initiatives!$C$23*J8,0)) -> 844.88921 | ... Z11: =IF(Initiatives!$C$6="adoption",N(Y11)*(1-Inputs!$C$9)+N(Y12)*Inputs!$C$9*Initiatives!$C$16,IF(Initiatives!$C$6="relative",N(Y11)*(1-Inputs!$C$9)+Z$4*Inputs!$C$9*Initiatives!$C$23*Z8,0)) -> 3068.8738
A12: Пул адоптеров | B12: pool | C12: =N(B12)*(1-Initiatives!$C$45)*(1-Inputs!$C$9*(1-Initiatives!$C$16))+C10 -> 0 | D12: =N(C12)*(1-Initiatives!$C$45)*(1-Inputs!$C$9*(1-Initiatives!$C$16))+D10 -> 33031.68 | E12: =N(D12)*(1-Initiatives!$C$45)*(1-Inputs!$C$9*(1-Initiatives!$C$16))+E10 -> 65617.432 | F12: =N(E12)*(1-Initiatives!$C$45)*(1-Inputs!$C$9*(1-Initiatives!$C$16))+F10 -> 97763.277 | G12: =N(F12)*(1-Initiatives!$C$45)*(1-Inputs!$C$9*(1-Initiatives!$C$16))+G10 -> 129475.15 | H12: =N(G12)*(1-Initiatives!$C$45)*(1-Inputs!$C$9*(1-Initiatives!$C$16))+H10 -> 127727.24 | I12: =N(H12)*(1-Initiatives!$C$45)*(1-Inputs!$C$9*(1-Initiatives!$C$16))+I10 -> 126002.92 | J12: =N(I12)*(1-Initiatives!$C$45)*(1-Inputs!$C$9*(1-Initiatives!$C$16))+J10 -> 124301.88 | ... Z12: =N(Y12)*(1-Initiatives!$C$45)*(1-Inputs!$C$9*(1-Initiatives!$C$16))+Z10 -> 100007.17
A13: Потерянные из-за инициативы | B13: L | C13: =N(B13)*(1-Inputs!$C$9)+IF(AND(C$3>=Initiatives!$C$33,C$3<Initiatives!$C$33+Initiatives!$C$47),Initiatives!$C$43/Initiatives!$C$47,0) -> 0 | D13: =N(C13)*(1-Inputs!$C$9)+IF(AND(D$3>=Initiatives!$C$33,D$3<Initiatives!$C$33+Initiatives!$C$47),Initiatives!$C$43/Initiatives!$C$47,0) -> 917.54667 | E13: =N(D13)*(1-Inputs!$C$9)+IF(AND(E$3>=Initiatives!$C$33,E$3<Initiatives!$C$33+Initiatives!$C$47),Initiatives!$C$43/Initiatives!$C$47,0) -> 1821.3301 | F13: =N(E13)*(1-Inputs!$C$9)+IF(AND(F$3>=Initiatives!$C$33,F$3<Initiatives!$C$33+Initiatives!$C$47),Initiatives!$C$43/Initiatives!$C$47,0) -> 2711.5568 | G13: =N(F13)*(1-Inputs!$C$9)+IF(AND(G$3>=Initiatives!$C$33,G$3<Initiatives!$C$33+Initiatives!$C$47),Initiatives!$C$43/Initiatives!$C$47,0) -> 2670.8835 | H13: =N(G13)*(1-Inputs!$C$9)+IF(AND(H$3>=Initiatives!$C$33,H$3<Initiatives!$C$33+Initiatives!$C$47),Initiatives!$C$43/Initiatives!$C$47,0) -> 2630.8202 | I13: =N(H13)*(1-Inputs!$C$9)+IF(AND(I$3>=Initiatives!$C$33,I$3<Initiatives!$C$33+Initiatives!$C$47),Initiatives!$C$43/Initiatives!$C$47,0) -> 2591.3579 | J13: =N(I13)*(1-Inputs!$C$9)+IF(AND(J$3>=Initiatives!$C$33,J$3<Initiatives!$C$33+Initiatives!$C$47),Initiatives!$C$43/Initiatives!$C$47,0) -> 2552.4876 | ... Z13: =N(Y13)*(1-Inputs!$C$9)+IF(AND(Z$3>=Initiatives!$C$33,Z$3<Initiatives!$C$33+Initiatives!$C$47),Initiatives!$C$43/Initiatives!$C$47,0) -> 2004.2105
A14: Инкр. выручка когорты | B14: rev | C14: =IF(Initiatives!$C$6="adoption",C12*Initiatives!$C$14+C11*Initiatives!$C$9-C13*Initiatives!$C$9,IF(Initiatives!$C$6="reprice",IF(C$3>=Initiatives!$C$33,(Initiatives!$C$41*Initiatives!$C$44+Initiatives!$C$42*Initiatives!$C$20)*(1-Inputs!$C$9)^(C$3-Initiatives!$C$33),0)-C13*Initiatives!$C$9,C$5*Initiatives!$C$22*C8+C11*Inputs!$C$8)) -> 0 | D14: =IF(Initiatives!$C$6="adoption",D12*Initiatives!$C$14+D11*Initiatives!$C$9-D13*Initiatives!$C$9,IF(Initiatives!$C$6="reprice",IF(D$3>=Initiatives!$C$33,(Initiatives!$C$41*Initiatives!$C$44+Initiatives!$C$42*Initiatives!$C$20)*(1-Inputs!$C$9)^(D$3-Initiatives!$C$33),0)-D13*Initiatives!$C$9,D$5*Initiatives!$C$22*D8+D11*Inputs!$C$8)) -> 195437440 | E14: =IF(Initiatives!$C$6="adoption",E12*Initiatives!$C$14+E11*Initiatives!$C$9-E13*Initiatives!$C$9,IF(Initiatives!$C$6="reprice",IF(E$3>=Initiatives!$C$33,(Initiatives!$C$41*Initiatives!$C$44+Initiatives!$C$42*Initiatives!$C$20)*(1-Inputs!$C$9)^(E$3-Initiatives!$C$33),0)-E13*Initiatives!$C$9,E$5*Initiatives!$C$22*E8+E11*Inputs!$C$8)) -> 3.8930588e+08 | F14: =IF(Initiatives!$C$6="adoption",F12*Initiatives!$C$14+F11*Initiatives!$C$9-F13*Initiatives!$C$9,IF(Initiatives!$C$6="reprice",IF(F$3>=Initiatives!$C$33,(Initiatives!$C$41*Initiatives!$C$44+Initiatives!$C$42*Initiatives!$C$20)*(1-Inputs!$C$9)^(F$3-Initiatives!$C$33),0)-F13*Initiatives!$C$9,F$5*Initiatives!$C$22*F8+F11*Inputs!$C$8)) -> 5.8161045e+08 | G14: =IF(Initiatives!$C$6="adoption",G12*Initiatives!$C$14+G11*Initiatives!$C$9-G13*Initiatives!$C$9,IF(Initiatives!$C$6="reprice",IF(G$3>=Initiatives!$C$33,(Initiatives!$C$41*Initiatives!$C$44+Initiatives!$C$42*Initiatives!$C$20)*(1-Inputs!$C$9)^(G$3-Initiatives!$C$33),0)-G13*Initiatives!$C$9,G$5*Initiatives!$C$22*G8+G11*Inputs!$C$8)) -> 7.9162494e+08 | H14: =IF(Initiatives!$C$6="adoption",H12*Initiatives!$C$14+H11*Initiatives!$C$9-H13*Initiatives!$C$9,IF(Initiatives!$C$6="reprice",IF(H$3>=Initiatives!$C$33,(Initiatives!$C$41*Initiatives!$C$44+Initiatives!$C$42*Initiatives!$C$20)*(1-Inputs!$C$9)^(H$3-Initiatives!$C$33),0)-H13*Initiatives!$C$9,H$5*Initiatives!$C$22*H8+H11*Inputs!$C$8)) -> 7.8509142e+08 | I14: =IF(Initiatives!$C$6="adoption",I12*Initiatives!$C$14+I11*Initiatives!$C$9-I13*Initiatives!$C$9,IF(Initiatives!$C$6="reprice",IF(I$3>=Initiatives!$C$33,(Initiatives!$C$41*Initiatives!$C$44+Initiatives!$C$42*Initiatives!$C$20)*(1-Inputs!$C$9)^(I$3-Initiatives!$C$33),0)-I13*Initiatives!$C$9,I$5*Initiatives!$C$22*I8+I11*Inputs!$C$8)) -> 7.785838e+08 | J14: =IF(Initiatives!$C$6="adoption",J12*Initiatives!$C$14+J11*Initiatives!$C$9-J13*Initiatives!$C$9,IF(Initiatives!$C$6="reprice",IF(J$3>=Initiatives!$C$33,(Initiatives!$C$41*Initiatives!$C$44+Initiatives!$C$42*Initiatives!$C$20)*(1-Inputs!$C$9)^(J$3-Initiatives!$C$33),0)-J13*Initiatives!$C$9,J$5*Initiatives!$C$22*J8+J11*Inputs!$C$8)) -> 7.7210266e+08 | ... Z14: =IF(Initiatives!$C$6="adoption",Z12*Initiatives!$C$14+Z11*Initiatives!$C$9-Z13*Initiatives!$C$9,IF(Initiatives!$C$6="reprice",IF(Z$3>=Initiatives!$C$33,(Initiatives!$C$41*Initiatives!$C$44+Initiatives!$C$42*Initiatives!$C$20)*(1-Inputs!$C$9)^(Z$3-Initiatives!$C$33),0)-Z13*Initiatives!$C$9,Z$5*Initiatives!$C$22*Z8+Z11*Inputs!$C$8)) -> 6.7240453e+08
A15: Выручка новых линий | B15: rev_ext | C15: =C12*Initiatives!$C$24*Initiatives!$C$25 -> 0 | D15: =D12*Initiatives!$C$24*Initiatives!$C$25 -> 0 | E15: =E12*Initiatives!$C$24*Initiatives!$C$25 -> 0 | F15: =F12*Initiatives!$C$24*Initiatives!$C$25 -> 0 | G15: =G12*Initiatives!$C$24*Initiatives!$C$25 -> 0 | H15: =H12*Initiatives!$C$24*Initiatives!$C$25 -> 0 | I15: =I12*Initiatives!$C$24*Initiatives!$C$25 -> 0 | J15: =J12*Initiatives!$C$24*Initiatives!$C$25 -> 0 | ... Z15: =Z12*Initiatives!$C$24*Initiatives!$C$25 -> 0
A16: Затраты | B16: cost | C16: =IF(C$3<=Initiatives!$C$46,Initiatives!$C$29/Initiatives!$C$46,0)+IF(C$3>=Initiatives!$C$33,Initiatives!$C$30,0)+IF(C$3=Initiatives!$C$33,Initiatives!$C$39*Initiatives!$C$26,0)+C10*Initiatives!$C$27+C12*Initiatives!$C$28+IF(AND(Initiatives!$C$6="reprice",C$3>=Initiatives!$C$33),Initiatives!$C$41*Initiatives!$C$21*(1-Inputs!$C$9)^(C$3-Initiatives!$C$33)-Initiatives!$C$31,0) -> 400000000 | D16: =IF(D$3<=Initiatives!$C$46,Initiatives!$C$29/Initiatives!$C$46,0)+IF(D$3>=Initiatives!$C$33,Initiatives!$C$30,0)+IF(D$3=Initiatives!$C$33,Initiatives!$C$39*Initiatives!$C$26,0)+D10*Initiatives!$C$27+D12*Initiatives!$C$28+IF(AND(Initiatives!$C$6="reprice",D$3>=Initiatives!$C$33),Initiatives!$C$41*Initiatives!$C$21*(1-Inputs!$C$9)^(D$3-Initiatives!$C$33)-Initiatives!$C$31,0) -> 302511360 | E16: =IF(E$3<=Initiatives!$C$46,Initiatives!$C$29/Initiatives!$C$46,0)+IF(E$3>=Initiatives!$C$33,Initiatives!$C$30,0)+IF(E$3=Initiatives!$C$33,Initiatives!$C$39*Initiatives!$C$26,0)+E10*Initiatives!$C$27+E12*Initiatives!$C$28+IF(AND(Initiatives!$C$6="reprice",E$3>=Initiatives!$C$33),Initiatives!$C$41*Initiatives!$C$21*(1-Inputs!$C$9)^(E$3-Initiatives!$C$33)-Initiatives!$C$31,0) -> 96063360 | F16: =IF(F$3<=Initiatives!$C$46,Initiatives!$C$29/Initiatives!$C$46,0)+IF(F$3>=Initiatives!$C$33,Initiatives!$C$30,0)+IF(F$3=Initiatives!$C$33,Initiatives!$C$39*Initiatives!$C$26,0)+F10*Initiatives!$C$27+F12*Initiatives!$C$28+IF(AND(Initiatives!$C$6="reprice",F$3>=Initiatives!$C$33),Initiatives!$C$41*Initiatives!$C$21*(1-Inputs!$C$9)^(F$3-Initiatives!$C$33)-Initiatives!$C$31,0) -> 96063360 | G16: =IF(G$3<=Initiatives!$C$46,Initiatives!$C$29/Initiatives!$C$46,0)+IF(G$3>=Initiatives!$C$33,Initiatives!$C$30,0)+IF(G$3=Initiatives!$C$33,Initiatives!$C$39*Initiatives!$C$26,0)+G10*Initiatives!$C$27+G12*Initiatives!$C$28+IF(AND(Initiatives!$C$6="reprice",G$3>=Initiatives!$C$33),Initiatives!$C$41*Initiatives!$C$21*(1-Inputs!$C$9)^(G$3-Initiatives!$C$33)-Initiatives!$C$31,0) -> 96063360 | H16: =IF(H$3<=Initiatives!$C$46,Initiatives!$C$29/Initiatives!$C$46,0)+IF(H$3>=Initiatives!$C$33,Initiatives!$C$30,0)+IF(H$3=Initiatives!$C$33,Initiatives!$C$39*Initiatives!$C$26,0)+H10*Initiatives!$C$27+H12*Initiatives!$C$28+IF(AND(Initiatives!$C$6="reprice",H$3>=Initiatives!$C$33),Initiatives!$C$41*Initiatives!$C$21*(1-Inputs!$C$9)^(H$3-Initiatives!$C$33)-Initiatives!$C$31,0) -> 30000000 | I16: =IF(I$3<=Initiatives!$C$46,Initiatives!$C$29/Initiatives!$C$46,0)+IF(I$3>=Initiatives!$C$33,Initiatives!$C$30,0)+IF(I$3=Initiatives!$C$33,Initiatives!$C$39*Initiatives!$C$26,0)+I10*Initiatives!$C$27+I12*Initiatives!$C$28+IF(AND(Initiatives!$C$6="reprice",I$3>=Initiatives!$C$33),Initiatives!$C$41*Initiatives!$C$21*(1-Inputs!$C$9)^(I$3-Initiatives!$C$33)-Initiatives!$C$31,0) -> 30000000 | J16: =IF(J$3<=Initiatives!$C$46,Initiatives!$C$29/Initiatives!$C$46,0)+IF(J$3>=Initiatives!$C$33,Initiatives!$C$30,0)+IF(J$3=Initiatives!$C$33,Initiatives!$C$39*Initiatives!$C$26,0)+J10*Initiatives!$C$27+J12*Initiatives!$C$28+IF(AND(Initiatives!$C$6="reprice",J$3>=Initiatives!$C$33),Initiatives!$C$41*Initiatives!$C$21*(1-Inputs!$C$9)^(J$3-Initiatives!$C$33)-Initiatives!$C$31,0) -> 30000000 | ... Z16: =IF(Z$3<=Initiatives!$C$46,Initiatives!$C$29/Initiatives!$C$46,0)+IF(Z$3>=Initiatives!$C$33,Initiatives!$C$30,0)+IF(Z$3=Initiatives!$C$33,Initiatives!$C$39*Initiatives!$C$26,0)+Z10*Initiatives!$C$27+Z12*Initiatives!$C$28+IF(AND(Initiatives!$C$6="reprice",Z$3>=Initiatives!$C$33),Initiatives!$C$41*Initiatives!$C$21*(1-Inputs!$C$9)^(Z$3-Initiatives!$C$33)-Initiatives!$C$31,0) -> 30000000
A17: Вклад | B17: contrib | C17: =(C14+C15)*Initiatives!$C$32-C16 -> -400000000 | D17: =(D14+D15)*Initiatives!$C$32-D16 -> -136389536 | E17: =(E14+E15)*Initiatives!$C$32-E16 -> 2.3484663e+08 | F17: =(F14+F15)*Initiatives!$C$32-F16 -> 3.9830552e+08 | G17: =(G14+G15)*Initiatives!$C$32-G16 -> 5.7681784e+08 | H17: =(H14+H15)*Initiatives!$C$32-H16 -> 6.3732771e+08 | I17: =(I14+I15)*Initiatives!$C$32-I16 -> 6.3179623e+08 | J17: =(J14+J15)*Initiatives!$C$32-J16 -> 6.2628726e+08 | ... Z17: =(Z14+Z15)*Initiatives!$C$32-Z16 -> 5.4154385e+08
A18: Δ абонентов когорты | B18: dsubs | C18: =C11-C13 -> 0 | D18: =D11-D13 -> -917.54667 | E18: =E11-E13 -> -1771.7826 | F18: =F11-F13 -> -2564.3264 | G18: =G11-G13 -> -2379.2166 | H18: =H11-H13 -> -2149.3156 | I18: =I11-I13 -> -1925.485 | J18: =J11-J13 -> -1707.5984 | ... Z18: =Z11-Z13 -> 1064.6633
A19: Новые линии | B19: dsubs_ext | C19: =C12*Initiatives!$C$24 -> 0 | D19: =D12*Initiatives!$C$24 -> 0 | E19: =E12*Initiatives!$C$24 -> 0 | F19: =F12*Initiatives!$C$24 -> 0 | G19: =G12*Initiatives!$C$24 -> 0 | H19: =H12*Initiatives!$C$24 -> 0 | I19: =I12*Initiatives!$C$24 -> 0 | J19: =J12*Initiatives!$C$24 -> 0 | ... Z19: =Z12*Initiatives!$C$24 -> 0
A21: A2 — Точечная индексация недооценённых архивных ТП (more-for-more)
A22: Доля набора | B22: f | C22: =IF(C$3<Initiatives!$D$33,0,MIN((C$3-Initiatives!$D$33+1)/Initiatives!$D$34,1)) -> 0 | D22: =IF(D$3<Initiatives!$D$33,0,MIN((D$3-Initiatives!$D$33+1)/Initiatives!$D$34,1)) -> 1 | E22: =IF(E$3<Initiatives!$D$33,0,MIN((E$3-Initiatives!$D$33+1)/Initiatives!$D$34,1)) -> 1 | F22: =IF(F$3<Initiatives!$D$33,0,MIN((F$3-Initiatives!$D$33+1)/Initiatives!$D$34,1)) -> 1 | G22: =IF(G$3<Initiatives!$D$33,0,MIN((G$3-Initiatives!$D$33+1)/Initiatives!$D$34,1)) -> 1 | H22: =IF(H$3<Initiatives!$D$33,0,MIN((H$3-Initiatives!$D$33+1)/Initiatives!$D$34,1)) -> 1 | I22: =IF(I$3<Initiatives!$D$33,0,MIN((I$3-Initiatives!$D$33+1)/Initiatives!$D$34,1)) -> 1 | J22: =IF(J$3<Initiatives!$D$33,0,MIN((J$3-Initiatives!$D$33+1)/Initiatives!$D$34,1)) -> 1 | ... Z22: =IF(Z$3<Initiatives!$D$33,0,MIN((Z$3-Initiatives!$D$33+1)/Initiatives!$D$34,1)) -> 1
A23: Адоптеры (цель) | B23: target | C23: =Initiatives!$D$40*C22 -> 0 | D23: =Initiatives!$D$40*D22 -> 0 | E23: =Initiatives!$D$40*E22 -> 0 | F23: =Initiatives!$D$40*F22 -> 0 | G23: =Initiatives!$D$40*G22 -> 0 | H23: =Initiatives!$D$40*H22 -> 0 | I23: =Initiatives!$D$40*I22 -> 0 | J23: =Initiatives!$D$40*J22 -> 0 | ... Z23: =Initiatives!$D$40*Z22 -> 0
A24: Новые адоптеры | B24: new | C24: =MAX(C23-N(B23),0) -> 0 | D24: =MAX(D23-N(C23),0) -> 0 | E24: =MAX(E23-N(D23),0) -> 0 | F24: =MAX(F23-N(E23),0) -> 0 | G24: =MAX(G23-N(F23),0) -> 0 | H24: =MAX(H23-N(G23),0) -> 0 | I24: =MAX(I23-N(H23),0) -> 0 | J24: =MAX(J23-N(I23),0) -> 0 | ... Z24: =MAX(Z23-N(Y23),0) -> 0
A25: Удержанные (эффект оттока) | B25: R | C25: =IF(Initiatives!$D$6="adoption",N(B25)*(1-Inputs!$C$9)+N(B26)*Inputs!$C$9*Initiatives!$D$16,IF(Initiatives!$D$6="relative",N(B25)*(1-Inputs!$C$9)+C$4*Inputs!$C$9*Initiatives!$D$23*C22,0)) -> 0 | D25: =IF(Initiatives!$D$6="adoption",N(C25)*(1-Inputs!$C$9)+N(C26)*Inputs!$C$9*Initiatives!$D$16,IF(Initiatives!$D$6="relative",N(C25)*(1-Inputs!$C$9)+D$4*Inputs!$C$9*Initiatives!$D$23*D22,0)) -> 0 | E25: =IF(Initiatives!$D$6="adoption",N(D25)*(1-Inputs!$C$9)+N(D26)*Inputs!$C$9*Initiatives!$D$16,IF(Initiatives!$D$6="relative",N(D25)*(1-Inputs!$C$9)+E$4*Inputs!$C$9*Initiatives!$D$23*E22,0)) -> 0 | F25: =IF(Initiatives!$D$6="adoption",N(E25)*(1-Inputs!$C$9)+N(E26)*Inputs!$C$9*Initiatives!$D$16,IF(Initiatives!$D$6="relative",N(E25)*(1-Inputs!$C$9)+F$4*Inputs!$C$9*Initiatives!$D$23*F22,0)) -> 0 | G25: =IF(Initiatives!$D$6="adoption",N(F25)*(1-Inputs!$C$9)+N(F26)*Inputs!$C$9*Initiatives!$D$16,IF(Initiatives!$D$6="relative",N(F25)*(1-Inputs!$C$9)+G$4*Inputs!$C$9*Initiatives!$D$23*G22,0)) -> 0 | H25: =IF(Initiatives!$D$6="adoption",N(G25)*(1-Inputs!$C$9)+N(G26)*Inputs!$C$9*Initiatives!$D$16,IF(Initiatives!$D$6="relative",N(G25)*(1-Inputs!$C$9)+H$4*Inputs!$C$9*Initiatives!$D$23*H22,0)) -> 0 | I25: =IF(Initiatives!$D$6="adoption",N(H25)*(1-Inputs!$C$9)+N(H26)*Inputs!$C$9*Initiatives!$D$16,IF(Initiatives!$D$6="relative",N(H25)*(1-Inputs!$C$9)+I$4*Inputs!$C$9*Initiatives!$D$23*I22,0)) -> 0 | J25: =IF(Initiatives!$D$6="adoption",N(I25)*(1-Inputs!$C$9)+N(I26)*Inputs!$C$9*Initiatives!$D$16,IF(Initiatives!$D$6="relative",N(I25)*(1-Inputs!$C$9)+J$4*Inputs!$C$9*Initiatives!$D$23*J22,0)) -> 0 | ... Z25: =IF(Initiatives!$D$6="adoption",N(Y25)*(1-Inputs!$C$9)+N(Y26)*Inputs!$C$9*Initiatives!$D$16,IF(Initiatives!$D$6="relative",N(Y25)*(1-Inputs!$C$9)+Z$4*Inputs!$C$9*Initiatives!$D$23*Z22,0)) -> 0
A26: Пул адоптеров | B26: pool | C26: =N(B26)*(1-Initiatives!$D$45)*(1-Inputs!$C$9*(1-Initiatives!$D$16))+C24 -> 0 | D26: =N(C26)*(1-Initiatives!$D$45)*(1-Inputs!$C$9*(1-Initiatives!$D$16))+D24 -> 0 | E26: =N(D26)*(1-Initiatives!$D$45)*(1-Inputs!$C$9*(1-Initiatives!$D$16))+E24 -> 0 | F26: =N(E26)*(1-Initiatives!$D$45)*(1-Inputs!$C$9*(1-Initiatives!$D$16))+F24 -> 0 | G26: =N(F26)*(1-Initiatives!$D$45)*(1-Inputs!$C$9*(1-Initiatives!$D$16))+G24 -> 0 | H26: =N(G26)*(1-Initiatives!$D$45)*(1-Inputs!$C$9*(1-Initiatives!$D$16))+H24 -> 0 | I26: =N(H26)*(1-Initiatives!$D$45)*(1-Inputs!$C$9*(1-Initiatives!$D$16))+I24 -> 0 | J26: =N(I26)*(1-Initiatives!$D$45)*(1-Inputs!$C$9*(1-Initiatives!$D$16))+J24 -> 0 | ... Z26: =N(Y26)*(1-Initiatives!$D$45)*(1-Inputs!$C$9*(1-Initiatives!$D$16))+Z24 -> 0
A27: Потерянные из-за инициативы | B27: L | C27: =N(B27)*(1-Inputs!$C$9)+IF(AND(C$3>=Initiatives!$D$33,C$3<Initiatives!$D$33+Initiatives!$D$47),Initiatives!$D$43/Initiatives!$D$47,0) -> 0 | D27: =N(C27)*(1-Inputs!$C$9)+IF(AND(D$3>=Initiatives!$D$33,D$3<Initiatives!$D$33+Initiatives!$D$47),Initiatives!$D$43/Initiatives!$D$47,0) -> 9680 | E27: =N(D27)*(1-Inputs!$C$9)+IF(AND(E$3>=Initiatives!$D$33,E$3<Initiatives!$D$33+Initiatives!$D$47),Initiatives!$D$43/Initiatives!$D$47,0) -> 19214.8 | F27: =N(E27)*(1-Inputs!$C$9)+IF(AND(F$3>=Initiatives!$D$33,F$3<Initiatives!$D$33+Initiatives!$D$47),Initiatives!$D$43/Initiatives!$D$47,0) -> 18926.578 | G27: =N(F27)*(1-Inputs!$C$9)+IF(AND(G$3>=Initiatives!$D$33,G$3<Initiatives!$D$33+Initiatives!$D$47),Initiatives!$D$43/Initiatives!$D$47,0) -> 18642.679 | H27: =N(G27)*(1-Inputs!$C$9)+IF(AND(H$3>=Initiatives!$D$33,H$3<Initiatives!$D$33+Initiatives!$D$47),Initiatives!$D$43/Initiatives!$D$47,0) -> 18363.039 | I27: =N(H27)*(1-Inputs!$C$9)+IF(AND(I$3>=Initiatives!$D$33,I$3<Initiatives!$D$33+Initiatives!$D$47),Initiatives!$D$43/Initiatives!$D$47,0) -> 18087.594 | J27: =N(I27)*(1-Inputs!$C$9)+IF(AND(J$3>=Initiatives!$D$33,J$3<Initiatives!$D$33+Initiatives!$D$47),Initiatives!$D$43/Initiatives!$D$47,0) -> 17816.28 | ... Z27: =N(Y27)*(1-Inputs!$C$9)+IF(AND(Z$3>=Initiatives!$D$33,Z$3<Initiatives!$D$33+Initiatives!$D$47),Initiatives!$D$43/Initiatives!$D$47,0) -> 13989.323
A28: Инкр. выручка когорты | B28: rev | C28: =IF(Initiatives!$D$6="adoption",C26*Initiatives!$D$14+C25*Initiatives!$D$9-C27*Initiatives!$D$9,IF(Initiatives!$D$6="reprice",IF(C$3>=Initiatives!$D$33,(Initiatives!$D$41*Initiatives!$D$44+Initiatives!$D$42*Initiatives!$D$20)*(1-Inputs!$C$9)^(C$3-Initiatives!$D$33),0)-C27*Initiatives!$D$9,C$5*Initiatives!$D$22*C22+C25*Inputs!$C$8)) -> 0 | D28: =IF(Initiatives!$D$6="adoption",D26*Initiatives!$D$14+D25*Initiatives!$D$9-D27*Initiatives!$D$9,IF(Initiatives!$D$6="reprice",IF(D$3>=Initiatives!$D$33,(Initiatives!$D$41*Initiatives!$D$44+Initiatives!$D$42*Initiatives!$D$20)*(1-Inputs!$C$9)^(D$3-Initiatives!$D$33),0)-D27*Initiatives!$D$9,D$5*Initiatives!$D$22*D22+D25*Inputs!$C$8)) -> 2.7050069e+09 | E28: =IF(Initiatives!$D$6="adoption",E26*Initiatives!$D$14+E25*Initiatives!$D$9-E27*Initiatives!$D$9,IF(Initiatives!$D$6="reprice",IF(E$3>=Initiatives!$D$33,(Initiatives!$D$41*Initiatives!$D$44+Initiatives!$D$42*Initiatives!$D$20)*(1-Inputs!$C$9)^(E$3-Initiatives!$D$33),0)-E27*Initiatives!$D$9,E$5*Initiatives!$D$22*E22+E25*Inputs!$C$8)) -> 2.4611518e+09 | F28: =IF(Initiatives!$D$6="adoption",F26*Initiatives!$D$14+F25*Initiatives!$D$9-F27*Initiatives!$D$9,IF(Initiatives!$D$6="reprice",IF(F$3>=Initiatives!$D$33,(Initiatives!$D$41*Initiatives!$D$44+Initiatives!$D$42*Initiatives!$D$20)*(1-Inputs!$C$9)^(F$3-Initiatives!$D$33),0)-F27*Initiatives!$D$9,F$5*Initiatives!$D$22*F22+F25*Inputs!$C$8)) -> 2.4242345e+09 | G28: =IF(Initiatives!$D$6="adoption",G26*Initiatives!$D$14+G25*Initiatives!$D$9-G27*Initiatives!$D$9,IF(Initiatives!$D$6="reprice",IF(G$3>=Initiatives!$D$33,(Initiatives!$D$41*Initiatives!$D$44+Initiatives!$D$42*Initiatives!$D$20)*(1-Inputs!$C$9)^(G$3-Initiatives!$D$33),0)-G27*Initiatives!$D$9,G$5*Initiatives!$D$22*G22+G25*Inputs!$C$8)) -> 2.387871e+09 | H28: =IF(Initiatives!$D$6="adoption",H26*Initiatives!$D$14+H25*Initiatives!$D$9-H27*Initiatives!$D$9,IF(Initiatives!$D$6="reprice",IF(H$3>=Initiatives!$D$33,(Initiatives!$D$41*Initiatives!$D$44+Initiatives!$D$42*Initiatives!$D$20)*(1-Inputs!$C$9)^(H$3-Initiatives!$D$33),0)-H27*Initiatives!$D$9,H$5*Initiatives!$D$22*H22+H25*Inputs!$C$8)) -> 2.3520529e+09 | I28: =IF(Initiatives!$D$6="adoption",I26*Initiatives!$D$14+I25*Initiatives!$D$9-I27*Initiatives!$D$9,IF(Initiatives!$D$6="reprice",IF(I$3>=Initiatives!$D$33,(Initiatives!$D$41*Initiatives!$D$44+Initiatives!$D$42*Initiatives!$D$20)*(1-Inputs!$C$9)^(I$3-Initiatives!$D$33),0)-I27*Initiatives!$D$9,I$5*Initiatives!$D$22*I22+I25*Inputs!$C$8)) -> 2.3167721e+09 | J28: =IF(Initiatives!$D$6="adoption",J26*Initiatives!$D$14+J25*Initiatives!$D$9-J27*Initiatives!$D$9,IF(Initiatives!$D$6="reprice",IF(J$3>=Initiatives!$D$33,(Initiatives!$D$41*Initiatives!$D$44+Initiatives!$D$42*Initiatives!$D$20)*(1-Inputs!$C$9)^(J$3-Initiatives!$D$33),0)-J27*Initiatives!$D$9,J$5*Initiatives!$D$22*J22+J25*Inputs!$C$8)) -> 2.2820205e+09 | ... Z28: =IF(Initiatives!$D$6="adoption",Z26*Initiatives!$D$14+Z25*Initiatives!$D$9-Z27*Initiatives!$D$9,IF(Initiatives!$D$6="reprice",IF(Z$3>=Initiatives!$D$33,(Initiatives!$D$41*Initiatives!$D$44+Initiatives!$D$42*Initiatives!$D$20)*(1-Inputs!$C$9)^(Z$3-Initiatives!$D$33),0)-Z27*Initiatives!$D$9,Z$5*Initiatives!$D$22*Z22+Z25*Inputs!$C$8)) -> 1.79184e+09
A29: Выручка новых линий | B29: rev_ext | C29: =C26*Initiatives!$D$24*Initiatives!$D$25 -> 0 | D29: =D26*Initiatives!$D$24*Initiatives!$D$25 -> 0 | E29: =E26*Initiatives!$D$24*Initiatives!$D$25 -> 0 | F29: =F26*Initiatives!$D$24*Initiatives!$D$25 -> 0 | G29: =G26*Initiatives!$D$24*Initiatives!$D$25 -> 0 | H29: =H26*Initiatives!$D$24*Initiatives!$D$25 -> 0 | I29: =I26*Initiatives!$D$24*Initiatives!$D$25 -> 0 | J29: =J26*Initiatives!$D$24*Initiatives!$D$25 -> 0 | ... Z29: =Z26*Initiatives!$D$24*Initiatives!$D$25 -> 0
A30: Затраты | B30: cost | C30: =IF(C$3<=Initiatives!$D$46,Initiatives!$D$29/Initiatives!$D$46,0)+IF(C$3>=Initiatives!$D$33,Initiatives!$D$30,0)+IF(C$3=Initiatives!$D$33,Initiatives!$D$39*Initiatives!$D$26,0)+C24*Initiatives!$D$27+C26*Initiatives!$D$28+IF(AND(Initiatives!$D$6="reprice",C$3>=Initiatives!$D$33),Initiatives!$D$41*Initiatives!$D$21*(1-Inputs!$C$9)^(C$3-Initiatives!$D$33)-Initiatives!$D$31,0) -> 300000000 | D30: =IF(D$3<=Initiatives!$D$46,Initiatives!$D$29/Initiatives!$D$46,0)+IF(D$3>=Initiatives!$D$33,Initiatives!$D$30,0)+IF(D$3=Initiatives!$D$33,Initiatives!$D$39*Initiatives!$D$26,0)+D24*Initiatives!$D$27+D26*Initiatives!$D$28+IF(AND(Initiatives!$D$6="reprice",D$3>=Initiatives!$D$33),Initiatives!$D$41*Initiatives!$D$21*(1-Inputs!$C$9)^(D$3-Initiatives!$D$33)-Initiatives!$D$31,0) -> 374675200 | E30: =IF(E$3<=Initiatives!$D$46,Initiatives!$D$29/Initiatives!$D$46,0)+IF(E$3>=Initiatives!$D$33,Initiatives!$D$30,0)+IF(E$3=Initiatives!$D$33,Initiatives!$D$39*Initiatives!$D$26,0)+E24*Initiatives!$D$27+E26*Initiatives!$D$28+IF(AND(Initiatives!$D$6="reprice",E$3>=Initiatives!$D$33),Initiatives!$D$41*Initiatives!$D$21*(1-Inputs!$C$9)^(E$3-Initiatives!$D$33)-Initiatives!$D$31,0) -> 293076672 | F30: =IF(F$3<=Initiatives!$D$46,Initiatives!$D$29/Initiatives!$D$46,0)+IF(F$3>=Initiatives!$D$33,Initiatives!$D$30,0)+IF(F$3=Initiatives!$D$33,Initiatives!$D$39*Initiatives!$D$26,0)+F24*Initiatives!$D$27+F26*Initiatives!$D$28+IF(AND(Initiatives!$D$6="reprice",F$3>=Initiatives!$D$33),Initiatives!$D$41*Initiatives!$D$21*(1-Inputs!$C$9)^(F$3-Initiatives!$D$33)-Initiatives!$D$31,0) -> 2.8898052e+08 | G30: =IF(G$3<=Initiatives!$D$46,Initiatives!$D$29/Initiatives!$D$46,0)+IF(G$3>=Initiatives!$D$33,Initiatives!$D$30,0)+IF(G$3=Initiatives!$D$33,Initiatives!$D$39*Initiatives!$D$26,0)+G24*Initiatives!$D$27+G26*Initiatives!$D$28+IF(AND(Initiatives!$D$6="reprice",G$3>=Initiatives!$D$33),Initiatives!$D$41*Initiatives!$D$21*(1-Inputs!$C$9)^(G$3-Initiatives!$D$33)-Initiatives!$D$31,0) -> 2.8494581e+08 | H30: =IF(H$3<=Initiatives!$D$46,Initiatives!$D$29/Initiatives!$D$46,0)+IF(H$3>=Initiatives!$D$33,Initiatives!$D$30,0)+IF(H$3=Initiatives!$D$33,Initiatives!$D$39*Initiatives!$D$26,0)+H24*Initiatives!$D$27+H26*Initiatives!$D$28+IF(AND(Initiatives!$D$6="reprice",H$3>=Initiatives!$D$33),Initiatives!$D$41*Initiatives!$D$21*(1-Inputs!$C$9)^(H$3-Initiatives!$D$33)-Initiatives!$D$31,0) -> 2.8097163e+08 | I30: =IF(I$3<=Initiatives!$D$46,Initiatives!$D$29/Initiatives!$D$46,0)+IF(I$3>=Initiatives!$D$33,Initiatives!$D$30,0)+IF(I$3=Initiatives!$D$33,Initiatives!$D$39*Initiatives!$D$26,0)+I24*Initiatives!$D$27+I26*Initiatives!$D$28+IF(AND(Initiatives!$D$6="reprice",I$3>=Initiatives!$D$33),Initiatives!$D$41*Initiatives!$D$21*(1-Inputs!$C$9)^(I$3-Initiatives!$D$33)-Initiatives!$D$31,0) -> 2.7705705e+08 | J30: =IF(J$3<=Initiatives!$D$46,Initiatives!$D$29/Initiatives!$D$46,0)+IF(J$3>=Initiatives!$D$33,Initiatives!$D$30,0)+IF(J$3=Initiatives!$D$33,Initiatives!$D$39*Initiatives!$D$26,0)+J24*Initiatives!$D$27+J26*Initiatives!$D$28+IF(AND(Initiatives!$D$6="reprice",J$3>=Initiatives!$D$33),Initiatives!$D$41*Initiatives!$D$21*(1-Inputs!$C$9)^(J$3-Initiatives!$D$33)-Initiatives!$D$31,0) -> 2.732012e+08 | ... Z30: =IF(Z$3<=Initiatives!$D$46,Initiatives!$D$29/Initiatives!$D$46,0)+IF(Z$3>=Initiatives!$D$33,Initiatives!$D$30,0)+IF(Z$3=Initiatives!$D$33,Initiatives!$D$39*Initiatives!$D$26,0)+Z24*Initiatives!$D$27+Z26*Initiatives!$D$28+IF(AND(Initiatives!$D$6="reprice",Z$3>=Initiatives!$D$33),Initiatives!$D$41*Initiatives!$D$21*(1-Inputs!$C$9)^(Z$3-Initiatives!$D$33)-Initiatives!$D$31,0) -> 2.188133e+08
A31: Вклад | B31: contrib | C31: =(C28+C29)*Initiatives!$D$32-C30 -> -300000000 | D31: =(D28+D29)*Initiatives!$D$32-D30 -> 2.3303317e+09 | E31: =(E28+E29)*Initiatives!$D$32-E30 -> 2.1680751e+09 | F31: =(F28+F29)*Initiatives!$D$32-F30 -> 2.135254e+09 | G31: =(G28+G29)*Initiatives!$D$32-G30 -> 2.1029251e+09 | H31: =(H28+H29)*Initiatives!$D$32-H30 -> 2.0710813e+09 | I31: =(I28+I29)*Initiatives!$D$32-I30 -> 2.0397151e+09 | J31: =(J28+J29)*Initiatives!$D$32-J30 -> 2.0088193e+09 | ... Z31: =(Z28+Z29)*Initiatives!$D$32-Z30 -> 1.5730267e+09
A32: Δ абонентов когорты | B32: dsubs | C32: =C25-C27 -> 0 | D32: =D25-D27 -> -9680 | E32: =E25-E27 -> -19214.8 | F32: =F25-F27 -> -18926.578 | G32: =G25-G27 -> -18642.679 | H32: =H25-H27 -> -18363.039 | I32: =I25-I27 -> -18087.594 | J32: =J25-J27 -> -17816.28 | ... Z32: =Z25-Z27 -> -13989.323
A33: Новые линии | B33: dsubs_ext | C33: =C26*Initiatives!$D$24 -> 0 | D33: =D26*Initiatives!$D$24 -> 0 | E33: =E26*Initiatives!$D$24 -> 0 | F33: =F26*Initiatives!$D$24 -> 0 | G33: =G26*Initiatives!$D$24 -> 0 | H33: =H26*Initiatives!$D$24 -> 0 | I33: =I26*Initiatives!$D$24 -> 0 | J33: =J26*Initiatives!$D$24 -> 0 | ... Z33: =Z26*Initiatives!$D$24 -> 0
A35: A3 — PAYG → суточные/недельные микропакеты
A36: Доля набора | B36: f | C36: =IF(C$3<Initiatives!$E$33,0,MIN((C$3-Initiatives!$E$33+1)/Initiatives!$E$34,1)) -> 0 | D36: =IF(D$3<Initiatives!$E$33,0,MIN((D$3-Initiatives!$E$33+1)/Initiatives!$E$34,1)) -> 0.33333333 | E36: =IF(E$3<Initiatives!$E$33,0,MIN((E$3-Initiatives!$E$33+1)/Initiatives!$E$34,1)) -> 0.66666667 | F36: =IF(F$3<Initiatives!$E$33,0,MIN((F$3-Initiatives!$E$33+1)/Initiatives!$E$34,1)) -> 1 | G36: =IF(G$3<Initiatives!$E$33,0,MIN((G$3-Initiatives!$E$33+1)/Initiatives!$E$34,1)) -> 1 | H36: =IF(H$3<Initiatives!$E$33,0,MIN((H$3-Initiatives!$E$33+1)/Initiatives!$E$34,1)) -> 1 | I36: =IF(I$3<Initiatives!$E$33,0,MIN((I$3-Initiatives!$E$33+1)/Initiatives!$E$34,1)) -> 1 | J36: =IF(J$3<Initiatives!$E$33,0,MIN((J$3-Initiatives!$E$33+1)/Initiatives!$E$34,1)) -> 1 | ... Z36: =IF(Z$3<Initiatives!$E$33,0,MIN((Z$3-Initiatives!$E$33+1)/Initiatives!$E$34,1)) -> 1
A37: Адоптеры (цель) | B37: target | C37: =Initiatives!$E$40*C36 -> 0 | D37: =Initiatives!$E$40*D36 -> 22528 | E37: =Initiatives!$E$40*E36 -> 45056 | F37: =Initiatives!$E$40*F36 -> 67584 | G37: =Initiatives!$E$40*G36 -> 67584 | H37: =Initiatives!$E$40*H36 -> 67584 | I37: =Initiatives!$E$40*I36 -> 67584 | J37: =Initiatives!$E$40*J36 -> 67584 | ... Z37: =Initiatives!$E$40*Z36 -> 67584
A38: Новые адоптеры | B38: new | C38: =MAX(C37-N(B37),0) -> 0 | D38: =MAX(D37-N(C37),0) -> 22528 | E38: =MAX(E37-N(D37),0) -> 22528 | F38: =MAX(F37-N(E37),0) -> 22528 | G38: =MAX(G37-N(F37),0) -> 0 | H38: =MAX(H37-N(G37),0) -> 0 | I38: =MAX(I37-N(H37),0) -> 0 | J38: =MAX(J37-N(I37),0) -> 0 | ... Z38: =MAX(Z37-N(Y37),0) -> 0
A39: Удержанные (эффект оттока) | B39: R | C39: =IF(Initiatives!$E$6="adoption",N(B39)*(1-Inputs!$C$9)+N(B40)*Inputs!$C$9*Initiatives!$E$16,IF(Initiatives!$E$6="relative",N(B39)*(1-Inputs!$C$9)+C$4*Inputs!$C$9*Initiatives!$E$23*C36,0)) -> 0 | D39: =IF(Initiatives!$E$6="adoption",N(C39)*(1-Inputs!$C$9)+N(C40)*Inputs!$C$9*Initiatives!$E$16,IF(Initiatives!$E$6="relative",N(C39)*(1-Inputs!$C$9)+D$4*Inputs!$C$9*Initiatives!$E$23*D36,0)) -> 0 | E39: =IF(Initiatives!$E$6="adoption",N(D39)*(1-Inputs!$C$9)+N(D40)*Inputs!$C$9*Initiatives!$E$16,IF(Initiatives!$E$6="relative",N(D39)*(1-Inputs!$C$9)+E$4*Inputs!$C$9*Initiatives!$E$23*E36,0)) -> 16.896 | F39: =IF(Initiatives!$E$6="adoption",N(E39)*(1-Inputs!$C$9)+N(E40)*Inputs!$C$9*Initiatives!$E$16,IF(Initiatives!$E$6="relative",N(E39)*(1-Inputs!$C$9)+F$4*Inputs!$C$9*Initiatives!$E$23*F36,0)) -> 50.193792 | G39: =IF(Initiatives!$E$6="adoption",N(F39)*(1-Inputs!$C$9)+N(F40)*Inputs!$C$9*Initiatives!$E$16,IF(Initiatives!$E$6="relative",N(F39)*(1-Inputs!$C$9)+G$4*Inputs!$C$9*Initiatives!$E$23*G36,0)) -> 99.410012 | H39: =IF(Initiatives!$E$6="adoption",N(G39)*(1-Inputs!$C$9)+N(G40)*Inputs!$C$9*Initiatives!$E$16,IF(Initiatives!$E$6="relative",N(G39)*(1-Inputs!$C$9)+H$4*Inputs!$C$9*Initiatives!$E$23*H36,0)) -> 147.17593 | I39: =IF(Initiatives!$E$6="adoption",N(H39)*(1-Inputs!$C$9)+N(H40)*Inputs!$C$9*Initiatives!$E$16,IF(Initiatives!$E$6="relative",N(H39)*(1-Inputs!$C$9)+I$4*Inputs!$C$9*Initiatives!$E$23*I36,0)) -> 193.52344 | J39: =IF(Initiatives!$E$6="adoption",N(I39)*(1-Inputs!$C$9)+N(I40)*Inputs!$C$9*Initiatives!$E$16,IF(Initiatives!$E$6="relative",N(I39)*(1-Inputs!$C$9)+J$4*Inputs!$C$9*Initiatives!$E$23*J36,0)) -> 238.48383 | ... Z39: =IF(Initiatives!$E$6="adoption",N(Y39)*(1-Inputs!$C$9)+N(Y40)*Inputs!$C$9*Initiatives!$E$16,IF(Initiatives!$E$6="relative",N(Y39)*(1-Inputs!$C$9)+Z$4*Inputs!$C$9*Initiatives!$E$23*Z36,0)) -> 792.47852
A40: Пул адоптеров | B40: pool | C40: =N(B40)*(1-Initiatives!$E$45)*(1-Inputs!$C$9*(1-Initiatives!$E$16))+C38 -> 0 | D40: =N(C40)*(1-Initiatives!$E$45)*(1-Inputs!$C$9*(1-Initiatives!$E$16))+D38 -> 22528 | E40: =N(D40)*(1-Initiatives!$E$45)*(1-Inputs!$C$9*(1-Initiatives!$E$16))+E38 -> 44734.976 | F40: =N(E40)*(1-Initiatives!$E$45)*(1-Inputs!$C$9*(1-Initiatives!$E$16))+F38 -> 66625.503 | G40: =N(F40)*(1-Initiatives!$E$45)*(1-Inputs!$C$9*(1-Initiatives!$E$16))+G38 -> 65676.089 | H40: =N(G40)*(1-Initiatives!$E$45)*(1-Inputs!$C$9*(1-Initiatives!$E$16))+H38 -> 64740.205 | I40: =N(H40)*(1-Initiatives!$E$45)*(1-Inputs!$C$9*(1-Initiatives!$E$16))+I38 -> 63817.657 | J40: =N(I40)*(1-Initiatives!$E$45)*(1-Inputs!$C$9*(1-Initiatives!$E$16))+J38 -> 62908.255 | ... Z40: =N(Y40)*(1-Initiatives!$E$45)*(1-Inputs!$C$9*(1-Initiatives!$E$16))+Z38 -> 50000.715
A41: Потерянные из-за инициативы | B41: L | C41: =N(B41)*(1-Inputs!$C$9)+IF(AND(C$3>=Initiatives!$E$33,C$3<Initiatives!$E$33+Initiatives!$E$47),Initiatives!$E$43/Initiatives!$E$47,0) -> 0 | D41: =N(C41)*(1-Inputs!$C$9)+IF(AND(D$3>=Initiatives!$E$33,D$3<Initiatives!$E$33+Initiatives!$E$47),Initiatives!$E$43/Initiatives!$E$47,0) -> 0 | E41: =N(D41)*(1-Inputs!$C$9)+IF(AND(E$3>=Initiatives!$E$33,E$3<Initiatives!$E$33+Initiatives!$E$47),Initiatives!$E$43/Initiatives!$E$47,0) -> 0 | F41: =N(E41)*(1-Inputs!$C$9)+IF(AND(F$3>=Initiatives!$E$33,F$3<Initiatives!$E$33+Initiatives!$E$47),Initiatives!$E$43/Initiatives!$E$47,0) -> 0 | G41: =N(F41)*(1-Inputs!$C$9)+IF(AND(G$3>=Initiatives!$E$33,G$3<Initiatives!$E$33+Initiatives!$E$47),Initiatives!$E$43/Initiatives!$E$47,0) -> 0 | H41: =N(G41)*(1-Inputs!$C$9)+IF(AND(H$3>=Initiatives!$E$33,H$3<Initiatives!$E$33+Initiatives!$E$47),Initiatives!$E$43/Initiatives!$E$47,0) -> 0 | I41: =N(H41)*(1-Inputs!$C$9)+IF(AND(I$3>=Initiatives!$E$33,I$3<Initiatives!$E$33+Initiatives!$E$47),Initiatives!$E$43/Initiatives!$E$47,0) -> 0 | J41: =N(I41)*(1-Inputs!$C$9)+IF(AND(J$3>=Initiatives!$E$33,J$3<Initiatives!$E$33+Initiatives!$E$47),Initiatives!$E$43/Initiatives!$E$47,0) -> 0 | ... Z41: =N(Y41)*(1-Inputs!$C$9)+IF(AND(Z$3>=Initiatives!$E$33,Z$3<Initiatives!$E$33+Initiatives!$E$47),Initiatives!$E$43/Initiatives!$E$47,0) -> 0
A42: Инкр. выручка когорты | B42: rev | C42: =IF(Initiatives!$E$6="adoption",C40*Initiatives!$E$14+C39*Initiatives!$E$9-C41*Initiatives!$E$9,IF(Initiatives!$E$6="reprice",IF(C$3>=Initiatives!$E$33,(Initiatives!$E$41*Initiatives!$E$44+Initiatives!$E$42*Initiatives!$E$20)*(1-Inputs!$C$9)^(C$3-Initiatives!$E$33),0)-C41*Initiatives!$E$9,C$5*Initiatives!$E$22*C36+C39*Inputs!$C$8)) -> 0 | D42: =IF(Initiatives!$E$6="adoption",D40*Initiatives!$E$14+D39*Initiatives!$E$9-D41*Initiatives!$E$9,IF(Initiatives!$E$6="reprice",IF(D$3>=Initiatives!$E$33,(Initiatives!$E$41*Initiatives!$E$44+Initiatives!$E$42*Initiatives!$E$20)*(1-Inputs!$C$9)^(D$3-Initiatives!$E$33),0)-D41*Initiatives!$E$9,D$5*Initiatives!$E$22*D36+D39*Inputs!$C$8)) -> 56320000 | E42: =IF(Initiatives!$E$6="adoption",E40*Initiatives!$E$14+E39*Initiatives!$E$9-E41*Initiatives!$E$9,IF(Initiatives!$E$6="reprice",IF(E$3>=Initiatives!$E$33,(Initiatives!$E$41*Initiatives!$E$44+Initiatives!$E$42*Initiatives!$E$20)*(1-Inputs!$C$9)^(E$3-Initiatives!$E$33),0)-E41*Initiatives!$E$9,E$5*Initiatives!$E$22*E36+E39*Inputs!$C$8)) -> 112006400 | F42: =IF(Initiatives!$E$6="adoption",F40*Initiatives!$E$14+F39*Initiatives!$E$9-F41*Initiatives!$E$9,IF(Initiatives!$E$6="reprice",IF(F$3>=Initiatives!$E$33,(Initiatives!$E$41*Initiatives!$E$44+Initiatives!$E$42*Initiatives!$E$20)*(1-Inputs!$C$9)^(F$3-Initiatives!$E$33),0)-F41*Initiatives!$E$9,F$5*Initiatives!$E$22*F36+F39*Inputs!$C$8)) -> 1.6706569e+08 | G42: =IF(Initiatives!$E$6="adoption",G40*Initiatives!$E$14+G39*Initiatives!$E$9-G41*Initiatives!$E$9,IF(Initiatives!$E$6="reprice",IF(G$3>=Initiatives!$E$33,(Initiatives!$E$41*Initiatives!$E$44+Initiatives!$E$42*Initiatives!$E$20)*(1-Inputs!$C$9)^(G$3-Initiatives!$E$33),0)-G41*Initiatives!$E$9,G$5*Initiatives!$E$22*G36+G39*Inputs!$C$8)) -> 1.6518432e+08 | H42: =IF(Initiatives!$E$6="adoption",H40*Initiatives!$E$14+H39*Initiatives!$E$9-H41*Initiatives!$E$9,IF(Initiatives!$E$6="reprice",IF(H$3>=Initiatives!$E$33,(Initiatives!$E$41*Initiatives!$E$44+Initiatives!$E$42*Initiatives!$E$20)*(1-Inputs!$C$9)^(H$3-Initiatives!$E$33),0)-H41*Initiatives!$E$9,H$5*Initiatives!$E$22*H36+H39*Inputs!$C$8)) -> 1.6332227e+08 | I42: =IF(Initiatives!$E$6="adoption",I40*Initiatives!$E$14+I39*Initiatives!$E$9-I41*Initiatives!$E$9,IF(Initiatives!$E$6="reprice",IF(I$3>=Initiatives!$E$33,(Initiatives!$E$41*Initiatives!$E$44+Initiatives!$E$42*Initiatives!$E$20)*(1-Inputs!$C$9)^(I$3-Initiatives!$E$33),0)-I41*Initiatives!$E$9,I$5*Initiatives!$E$22*I36+I39*Inputs!$C$8)) -> 1.6147938e+08 | J42: =IF(Initiatives!$E$6="adoption",J40*Initiatives!$E$14+J39*Initiatives!$E$9-J41*Initiatives!$E$9,IF(Initiatives!$E$6="reprice",IF(J$3>=Initiatives!$E$33,(Initiatives!$E$41*Initiatives!$E$44+Initiatives!$E$42*Initiatives!$E$20)*(1-Inputs!$C$9)^(J$3-Initiatives!$E$33),0)-J41*Initiatives!$E$9,J$5*Initiatives!$E$22*J36+J39*Inputs!$C$8)) -> 1.5965548e+08 | ... Z42: =IF(Initiatives!$E$6="adoption",Z40*Initiatives!$E$14+Z39*Initiatives!$E$9-Z41*Initiatives!$E$9,IF(Initiatives!$E$6="reprice",IF(Z$3>=Initiatives!$E$33,(Initiatives!$E$41*Initiatives!$E$44+Initiatives!$E$42*Initiatives!$E$20)*(1-Inputs!$C$9)^(Z$3-Initiatives!$E$33),0)-Z41*Initiatives!$E$9,Z$5*Initiatives!$E$22*Z36+Z39*Inputs!$C$8)) -> 1.3292657e+08
A43: Выручка новых линий | B43: rev_ext | C43: =C40*Initiatives!$E$24*Initiatives!$E$25 -> 0 | D43: =D40*Initiatives!$E$24*Initiatives!$E$25 -> 0 | E43: =E40*Initiatives!$E$24*Initiatives!$E$25 -> 0 | F43: =F40*Initiatives!$E$24*Initiatives!$E$25 -> 0 | G43: =G40*Initiatives!$E$24*Initiatives!$E$25 -> 0 | H43: =H40*Initiatives!$E$24*Initiatives!$E$25 -> 0 | I43: =I40*Initiatives!$E$24*Initiatives!$E$25 -> 0 | J43: =J40*Initiatives!$E$24*Initiatives!$E$25 -> 0 | ... Z43: =Z40*Initiatives!$E$24*Initiatives!$E$25 -> 0
