Workbook

Sheet Как заполнять
A1: Карточка инициативы: от идеи к бизнес-кейсу
A3: Путь инициативы
A4: 1. Идея → 2. Карточка (этот файл) → 3. Ревью у руководителя (15–20 мин) → 4. Передача финансам → 5. Бизнес-кейс (NPV / IRR) → 6. Инвест-комитет / SteerCo
A6: Что заполняете вы (PM)
A7: Блок 1 — одностраничник: проблема с цифрой, цель, сегмент, механика, доказательства, гипотеза, сроки, риски, какое решение нужно.
A8: Блок 2 — драйверы: каждое число в трёх сценариях, с источником, уверенностью и владельцем данных. Финансы считают по вашим драйверам, поэтому драйвер без источника = вопрос на ревью.
A9: Блок 3 — быстрый расчёт: проверка порядка цифр до финмодели (без дисконтирования, налогов и амортизации — это делают финансы).
A10: Блоки 4–6 — вопросы к финансам, KPI и стоп-критерии, чек-лист готовности (≥ 80% → можно передавать).
A12: Что делают финансы (не делайте за них)
A13: NPV / IRR / дисконтирование, налоги, амортизация CAPEX, аллокация общих затрат, учёт по МСФО, итоговый P&L и влияние на EBITDA.
A15: Легенда
A16: Синий текст — ввод; чёрный — формулы; жёлтая заливка — не заполнено; списки выбора — Статус, Уверенность, Да / Нет.
... A19: Примеры I1–I4 заполнены по v2 (гипотезы до данных). Числа — ориентиры; замените фактом из выгрузок аналитиков.

Sheet Портфель
A1: Портфель инициатив — сводка для руководителя
A3: Общие допущения
A4: Курс, сум за 1 USD | B4: 12100
A5: НДС | B5: 0.12
A8: ID | B8: Инициатива | C8: Статус | D8: Старт, мес. | E8: Выручка 1-й год | F8: Вклад 24м: база | G8: Вклад 24м: пессимист | H8: Вклад 24м: оптимист | I8: CAPEX | J8: Окупаемость, мес. | K8: ΔARPU базы | L8: Уверенность | M8: Сложность (1–5) | N8: Приоритет | O8: Готовность к финансам
A9: I1 | B9: =I1!B5 -> I1 Sunset / Migration старых неэффективных линеек → ТП дороже на 10–15% | C9: =I1!B8 -> Discovery | D9: =I1!B30 -> 6 | E9: =I1!B49 -> 1.4744023e+10 | F9: =I1!B52 -> 36978640000 | G9: =I1!C52 -> -6927150000 | H9: =I1!D52 -> 124462920000 | I9: =I1!B32 -> 5000000000 | J9: =I1!B53 -> 2.0843934 | K9: =I1!B55 -> 0.041166023 | L9: Средняя | M9: 4 | N9: =F9/1000000000*IF(L9="Высокая",1,IF(L9="Средняя",0.7,0.4))/MAX(1,M9) -> 6.471262 | O9: =I1!B85 -> 0.5
A10: I2 | B10: =I2!B5 -> I2 More-for-More для когорты недооценённых линеек | C10: =I2!B8 -> Готово к финансам | D10: =I2!B30 -> 2 | E10: =I2!B49 -> 2.5017269e+10 | F10: =I2!B52 -> 4.8178816e+10 | G10: =I2!C52 -> 3.1526674e+09 | H10: =I2!D52 -> 9.3735321e+10 | I10: =I2!B32 -> 300000000 | J10: =I2!B53 -> 0.1360858 | K10: =I2!B55 -> 0.038417181 | L10: Высокая | M10: 1 | N10: =F10/1000000000*IF(L10="Высокая",1,IF(L10="Средняя",0.7,0.4))/MAX(1,M10) -> 48.178816 | O10: =I2!B85 -> 0.8
A11: I3 | B11: =I3!B5 -> I3 Бустер при исчерпании трафика + роуминг-пакет по акции | C11: =I3!B8 -> Готово к финансам | D11: =I3!B30 -> 2 | E11: =I3!B49 -> 4107583700 | F11: =I3!B52 -> 5.379428e+09 | G11: =I3!C52 -> 1.5711429e+08 | H11: =I3!D52 -> 2.2450828e+10 | I11: =I3!B32 -> 500000000 | J11: =I3!B53 -> 1.8645876 | K11: =I3!B55 -> 0.0063077145 | L11: Высокая | M11: 2 | N11: =F11/1000000000*IF(L11="Высокая",1,IF(L11="Средняя",0.7,0.4))/MAX(1,M11) -> 2.689714 | O11: =I3!B85 -> 0.7
A12: I4 | B12: =I4!B5 -> I4 Ucell Club — программа лояльности (MVP → масштаб) | C12: =I4!B8 -> Discovery | D12: =I4!B30 -> 11 | E12: =I4!B49 -> 1.9888393e+09 | F12: =I4!B52 -> -4.7555946e+08 | G12: =I4!C52 -> -2.6783482e+10 | H12: =I4!D52 -> 4.0699107e+10 | I12: =I4!B32 -> 6500000000 | J12: =I4!B53 -> 8.5629772 | K12: =I4!B55 -> 0.060975015 | L12: Низкая | M12: 4 | N12: =F12/1000000000*IF(L12="Высокая",1,IF(L12="Средняя",0.7,0.4))/MAX(1,M12) -> -0.047555946 | O12: =I4!B85 -> 0.4
B13: Итого (база) | E13: =SUM(E9:E12) -> 4.5857714e+10 | F13: =SUM(F9:F12) -> 9.0061325e+10 | G13: =SUM(G9:G12) -> -3.040085e+10 | H13: =SUM(H9:H12) -> 2.8134818e+11 | I13: =SUM(I9:I12) -> 12300000000
A15: Приоритет = вклад 24м (млрд) × уверенность (1 / 0,7 / 0,4) / сложность. Это ориентир для разговора, не решение.

Sheet I1
A1: Карточка инициативы · I1
A2: Синее — ввод, чёрное — формулы. Блок 1 — для руководителя, блоки 2–4 — для передачи финансам.
A4: 1. ОДНОСТРАНИЧНИК ДЛЯ РУКОВОДИТЕЛЯ
A5: Название | B5: I1 Sunset / Migration старых неэффективных линеек → ТП дороже на 10–15%
A6: Владелец (PM) | B6: [ФИО, PM тарифных планов]
A7: Дата / версия | B7: 09.10.2026 · v0.3
A8: Статус | B8: Discovery
A9: Проблема (1–2 предложения, с цифрой) | B9: ~30% архивной базы (~1,06 млн) на старых линейках с низкой абонплатой (~20 тыс.) и дорогим сопровождением; ARPU когорты 18 500 сум.
A10: Цель и метрика успеха | B10: ARPU архивной когорты +5% за 12 мес. после старта; доп. отток ≤ 5%; −30% тарифных кодов.
A11: Целевой сегмент | B11: Абоненты неэффективных архивных линеек (без соцгруппы ж 55+, м 60+); список — из анализа D3.
A12: Что делаем (механика) | B12: T−60: «выберите сами» + бонус Loyalty; T−15: уведомление (было → стало); T0: перевод на ближайший ТП +10–15%; T+30: right-size. Две волны: апр и июл 2027.
A13: Почему сработает (бенчмарки, данные) | B13: T-Mobile (grandfathered → новые планы), Airtel, Telenor (ARPU +4%), РФ (индексация архива). Ucell 02/2026 — естественный эксперимент.
A14: Гипотеза: «Если…, то…, потому что…» | B14: Если перевести неэффективные линейки на ТП +10–15% с большим объёмом и бесплатной сменой, то ARPU когорты вырастет на ~5–6%, потому что ≥85% останутся на новом ТП.
A15: Срок запуска и ключевые этапы | B15: Mapping и биллинг: дек 2026 – мар 2027; волна 1 — апр 2027; разбор — май; волна 2 — июл 2027.
A16: Ключевые риски и как снижаем | B16: Регулятор (15 дней, социсключение, досье); отток (волны, контроль 5%); нагрузка на КЦ (скрипты, самообслуживание).
A17: Какое решение нужно от руководителя | B17: Согласовать направление и передать в финансы для бизнес-кейса; выделить ресурс биллинга на mapping.
A19: 2. ДРАЙВЕРЫ ДЛЯ ФИНАНСОВ (каждое число — с источником и уверенностью)
A20: Параметр | B20: База | C20: Пессимист | D20: Оптимист | E20: Ед. | F20: Источник / как получено | G20: Уверенность | H20: Кто даёт данные
A21: Размер целевой группы | B21: 1056000 | C21: 880000 | D21: 1408000 | E21: абон. | F21: Гипотеза: 30% когорты; факт — D1/D3 | G21: Средняя | H21: Аналитика
A22: Охват коммуникацией | B22: 1 | C22: 1 | D22: 1 | E22: % | G22: Высокая | H22: Продукт
A23: Принимают предложение / остаются на новом условии | B23: 0.89 | C23: 0.81 | D23: 0.945 | E23: % | F23: 1 − даунгрейд − отток | G23: Средняя | H23: Аналитика / пилот
A24: Каннибализация (сделали бы и без нас) | B24: 0 | C24: 0 | D24: 0 | E24: % | G24: Низкая | H24: Аналитика
A25: Прирост платежа на принявшего, с НДС | B25: 4000 | C25: 2700 | D25: 6500 | E25: сум/мес | F25: +12,5% к ~20 тыс. + апсейл 12% × 10 тыс. | G25: Средняя | H25: Продукт / прайсинг
A26: Доля даунгрейда (уходят на ТП дешевле) | B26: 0.08 | C26: 0.14 | D26: 0.04 | E26: % | F26: Бенчмарки; калибровка D7 | G26: Средняя | H26: Аналитика (D7)
A27: Потеря платежа при даунгрейде, с НДС | B27: 2240 | C27: 4480 | D27: 0 | E27: сум/мес | G27: Низкая | H27: Продукт
A28: Доп. отток из-за инициативы | B28: 0.03 | C28: 0.05 | D28: 0.015 | E28: % | F28: AT&T/T-Mobile/Индия; D7 | G28: Средняя | H28: Аналитика (D7)
A29: Платёж уходящих, с НДС | B29: 17920 | C29: 17920 | D29: 17920 | E29: сум/мес | G29: Низкая | H29: Продукт
A30: Месяц старта эффекта (1 = первый месяц программы) | B30: 6 | C30: 6 | D30: 6 | E30: мес. | G30: Высокая | H30: Продукт
A31: Месяцев до полного эффекта | B31: 4 | C31: 4 | D31: 4 | E31: мес. | G31: Низкая | H31: Продукт
A32: Разовые затраты (CAPEX / внедрение) | B32: 5000000000 | C32: 8000000000 | D32: 3000000000 | E32: сум | F32: Оценка биллинга (запросить) | G32: Средняя | H32: IT / биллинг / маркетинг
A33: Постоянные затраты в месяц (OPEX) | B33: 0 | C33: 30000000 | D33: -30000000 | E33: сум/мес | F33: OPEX 30 млн − экономия сопровождения ~60 млн | G33: Средняя | H33: Владельцы затрат
A34: Переменные затраты на принявшего | B34: 300 | C34: 600 | D34: 100 | E34: сум/мес | G34: Низкая | H34: Сеть / финансы
A35: Маржинальность доп. выручки | B35: 1 | C35: 1 | D35: 1 | E35: % | G35: Высокая | H35: Финансы
A36: База для ΔARPU: абонентов | B36: 3520000 | C36: 3520000 | D36: 3520000 | E36: абон. | F36: Архивная когорта T0 | G36: Средняя | H36: Продукт
A37: База для ΔARPU: ARPU без НДС | B37: 18500 | C37: 18500 | D37: 18500 | E37: сум/мес | G37: Высокая | H37: Продукт
A39: 3. БЫСТРЫЙ РАСЧЁТ (sanity-check до финмодели; финансы уточнят NPV, налоги, амортизацию)
A40: Показатель | B40: База | C40: Пессимист | D40: Оптимист | E40: Ед. | F40: Как считается
A41: Принявших, абон. | B41: =B21*B22*B23*(1-B24) -> 939840 | C41: =IF(C21="",$B21,C21)*IF(C22="",$B22,C22)*IF(C23="",$B23,C23)*(1-IF(C24="",$B24,C24)) -> 712800 | D41: =IF(D21="",$B21,D21)*IF(D22="",$B22,D22)*IF(D23="",$B23,D23)*(1-IF(D24="",$B24,D24)) -> 1330560 | E41: абон. | F41: Размер × охват × принятие × (1 − каннибализация)
A42: Даунгрейд, абон. | B42: =B21*B26 -> 84480 | C42: =IF(C21="",$B21,C21)*IF(C26="",$B26,C26) -> 123200 | D42: =IF(D21="",$B21,D21)*IF(D26="",$B26,D26) -> 56320 | E42: абон. | F42: Размер × доля даунгрейда
A43: Ушедших, абон. | B43: =B21*B28 -> 31680 | C43: =IF(C21="",$B21,C21)*IF(C28="",$B28,C28) -> 44000 | D43: =IF(D21="",$B21,D21)*IF(D28="",$B28,D28) -> 21120 | E43: абон. | F43: Размер × доп. отток
...

Sheet I2
A1: Карточка инициативы · I2
A2: Синее — ввод, чёрное — формулы. Блок 1 — для руководителя, блоки 2–4 — для передачи финансам.
A4: 1. ОДНОСТРАНИЧНИК ДЛЯ РУКОВОДИТЕЛЯ
A5: Название | B5: I2 More-for-More для когорты недооценённых линеек
A6: Владелец (PM) | B6: [ФИО, PM тарифных планов]
A7: Дата / версия | B7: 09.10.2026 · v0.3
A8: Статус | B8: Готово к финансам
A9: Проблема (1–2 предложения, с цифрой) | B9: ~22% архивной базы (~775 тыс.) используют пакет полностью, но платят ниже актуальной линейки на 4–6 тыс. сум.
A10: Цель и метрика успеха | B10: ARPU когорты +4% за 12 мес.; даунгрейд ≤ 12%; доп. отток ≤ 3%; жалобы ≤ 2× нормы.
A11: Целевой сегмент | B11: Недооценённые архивные линейки (использование пакета ≥ 60%), без соцгруппы и без ТП волны 02/2026.
A12: Что делаем (механика) | B12: +4 000…6 000 сум к абонплате + больше ГБ; бесплатный right-size рядом; уведомление ≥ 15 дней; пилот 10% с holdout → масштаб.
A13: Почему сработает (бенчмарки, данные) | B13: РФ (+10–20% на архиве), AT&T, T-Mobile, Индия, Казахстан; Ucell 02/2026 (+5 000 с +ГБ).
A14: Гипотеза: «Если…, то…, потому что…» | B14: Если поднять абонплату на 4–6 тыс. с добавлением ГБ и дать бесплатную альтернативу, то ≥ 85% останутся, потому что ценность пакета растёт и цена ниже актуальной линейки.
A15: Срок запуска и ключевые этапы | B15: Пилот 10% — дек 2026; разбор — 27.01.2027; масштаб — фев 2027.
A16: Ключевые риски и как снижаем | B16: Комитет по конкуренции (точечность, досье); негатив «ненужные ГБ» (right-size); отток (стоп-критерий 1,5 п.п.).
A17: Какое решение нужно от руководителя | B17: Утвердить пилот 10% в декабре и передать драйверы в финансы.
A19: 2. ДРАЙВЕРЫ ДЛЯ ФИНАНСОВ (каждое число — с источником и уверенностью)
A20: Параметр | B20: База | C20: Пессимист | D20: Оптимист | E20: Ед. | F20: Источник / как получено | G20: Уверенность | H20: Кто даёт данные
A21: Размер целевой группы | B21: 774400 | C21: 634000 | D21: 915000 | E21: абон. | F21: Гипотеза: 22% когорты; факт — D3 | G21: Средняя | H21: Аналитика
A22: Охват коммуникацией | B22: 1 | C22: 1 | D22: 1 | E22: % | G22: Высокая | H22: Продукт
A23: Принимают предложение / остаются на новом условии | B23: 0.895 | C23: 0.81 | D23: 0.95 | E23: % | G23: Низкая | H23: Аналитика / пилот
A24: Каннибализация (сделали бы и без нас) | B24: 0 | C24: 0 | D24: 0 | E24: % | G24: Низкая | H24: Аналитика
A25: Прирост платежа на принявшего, с НДС | B25: 5000 | C25: 4000 | D25: 6000 | E25: сум/мес | F25: Решение по прайсу | G25: Средняя | H25: Продукт / прайсинг
A26: Доля даунгрейда (уходят на ТП дешевле) | B26: 0.08 | C26: 0.15 | D26: 0.04 | E26: % | F26: Бенчмарки; D7 | G26: Средняя | H26: Аналитика (D7)
A27: Потеря платежа при даунгрейде, с НДС | B27: 3360 | C27: 6720 | D27: 0 | E27: сум/мес | G27: Низкая | H27: Продукт
A28: Доп. отток из-за инициативы | B28: 0.025 | C28: 0.05 | D28: 0.01 | E28: % | F28: Бенчмарки; D7 | G28: Средняя | H28: Аналитика (D7)
A29: Платёж уходящих, с НДС | B29: 23520 | C29: 23520 | D29: 23520 | E29: сум/мес | G29: Низкая | H29: Продукт
A30: Месяц старта эффекта (1 = первый месяц программы) | B30: 2 | C30: 2 | D30: 2 | E30: мес. | G30: Высокая | H30: Продукт
A31: Месяцев до полного эффекта | B31: 3 | C31: 3 | D31: 3 | E31: мес. | G31: Низкая | H31: Продукт
A32: Разовые затраты (CAPEX / внедрение) | B32: 300000000 | C32: 500000000 | D32: 200000000 | E32: сум | F32: Маркетинг + КЦ + юр. | G32: Средняя | H32: IT / биллинг / маркетинг
A33: Постоянные затраты в месяц (OPEX) | B33: 20000000 | C33: 20000000 | D33: 20000000 | E33: сум/мес | G33: Низкая | H33: Владельцы затрат
A34: Переменные затраты на принявшего | B34: 400 | C34: 800 | D34: 200 | E34: сум/мес | G34: Низкая | H34: Сеть / финансы
A35: Маржинальность доп. выручки | B35: 1 | C35: 1 | D35: 1 | E35: % | G35: Высокая | H35: Финансы
A36: База для ΔARPU: абонентов | B36: 3520000 | C36: 3520000 | D36: 3520000 | E36: абон. | G36: Высокая | H36: Продукт
A37: База для ΔARPU: ARPU без НДС | B37: 18500 | C37: 18500 | D37: 18500 | E37: сум/мес | G37: Высокая | H37: Продукт
A39: 3. БЫСТРЫЙ РАСЧЁТ (sanity-check до финмодели; финансы уточнят NPV, налоги, амортизацию)
A40: Показатель | B40: База | C40: Пессимист | D40: Оптимист | E40: Ед. | F40: Как считается
A41: Принявших, абон. | B41: =B21*B22*B23*(1-B24) -> 693088 | C41: =IF(C21="",$B21,C21)*IF(C22="",$B22,C22)*IF(C23="",$B23,C23)*(1-IF(C24="",$B24,C24)) -> 513540 | D41: =IF(D21="",$B21,D21)*IF(D22="",$B22,D22)*IF(D23="",$B23,D23)*(1-IF(D24="",$B24,D24)) -> 869250 | E41: абон. | F41: Размер × охват × принятие × (1 − каннибализация)
A42: Даунгрейд, абон. | B42: =B21*B26 -> 61952 | C42: =IF(C21="",$B21,C21)*IF(C26="",$B26,C26) -> 95100 | D42: =IF(D21="",$B21,D21)*IF(D26="",$B26,D26) -> 36600 | E42: абон. | F42: Размер × доля даунгрейда
A43: Ушедших, абон. | B43: =B21*B28 -> 19360 | C43: =IF(C21="",$B21,C21)*IF(C28="",$B28,C28) -> 31700 | D43: =IF(D21="",$B21,D21)*IF(D28="",$B28,D28) -> 9150 | E43: абон. | F43: Размер × доп. отток
...

Sheet I3
A1: Карточка инициативы · I3
A2: Синее — ввод, чёрное — формулы. Блок 1 — для руководителя, блоки 2–4 — для передачи финансам.
A4: 1. ОДНОСТРАНИЧНИК ДЛЯ РУКОВОДИТЕЛЯ
A5: Название | B5: I3 Бустер при исчерпании трафика + роуминг-пакет по акции
A6: Владелец (PM) | B6: [ФИО, PM тарифных планов]
A7: Дата / версия | B7: 09.10.2026 · v0.3
A8: Статус | B8: Готово к финансам
A9: Проблема (1–2 предложения, с цифрой) | B9: ~15% архивной базы исчерпывают пакет до конца месяца; ~6% выезжают за рубеж (мигранты) и теряют связь / номер.
A10: Цель и метрика успеха | B10: +57 тыс. платящих за бустер / роуминг-пакет; LTV/CAC ≥ 5.
A11: Целевой сегмент | B11: Исчерпывающие пакет (D3/D5) + абоненты с роумингом / международными звонками (D9).
A12: Что делаем (механика) | B12: Триггер «осталось 20% / 0%» → +5 ГБ в 1 клик (автопродление только по согласию); «Musofir» −50% первый месяц.
A13: Почему сработает (бенчмарки, данные) | B13: Flytxt (+8% ARPU на контекстных офферах), бустеры Jio/Airtel; переводы мигрантов $18,9 млрд (2025).
A14: Гипотеза: «Если…, то…, потому что…» | B14: Если предложить пакет в момент исчерпания / выезда, то ≥ 10% купят, потому что потребность возникает прямо сейчас.
A15: Срок запуска и ключевые этапы | B15: Запуск A/B — дек 2026; масштаб — фев 2027.
A16: Ключевые риски и как снижаем | B16: Навязчивость (лимит 2 касания/мес., opt-in); каннибализация (holdout).
A17: Какое решение нужно от руководителя | B17: Утвердить запуск A/B в декабре.
A19: 2. ДРАЙВЕРЫ ДЛЯ ФИНАНСОВ (каждое число — с источником и уверенностью)
A20: Параметр | B20: База | C20: Пессимист | D20: Оптимист | E20: Ед. | F20: Источник / как получено | G20: Уверенность | H20: Кто даёт данные
A21: Размер целевой группы | B21: 739000 | C21: 600000 | D21: 900000 | E21: абон. | F21: Исчерпывающие 528 тыс. + роуминг 211 тыс. | G21: Средняя | H21: Аналитика
A22: Охват коммуникацией | B22: 0.88 | C22: 0.8 | D22: 0.93 | E22: % | G22: Высокая | H22: Продукт
A23: Принимают предложение / остаются на новом условии | B23: 0.14 | C23: 0.09 | D23: 0.2 | E23: % | F23: A/B в декабре | G23: Средняя | H23: Аналитика / пилот
A24: Каннибализация (сделали бы и без нас) | B24: 0.38 | C24: 0.5 | D24: 0.25 | E24: % | F24: Доля докупающих сами (D5) | G24: Средняя | H24: Аналитика
A25: Прирост платежа на принявшего, с НДС | B25: 8150 | C25: 6000 | D25: 12000 | E25: сум/мес | G25: Низкая | H25: Продукт / прайсинг
A26: Доля даунгрейда (уходят на ТП дешевле) | B26: 0 | C26: 0 | D26: 0 | E26: % | G26: Низкая | H26: Аналитика (D7)
A27: Потеря платежа при даунгрейде, с НДС | B27: 0 | C27: 0 | D27: 0 | E27: сум/мес | G27: Низкая | H27: Продукт
A28: Доп. отток из-за инициативы | B28: 0 | C28: 0 | D28: 0 | E28: % | G28: Низкая | H28: Аналитика (D7)
A29: Платёж уходящих, с НДС | B29: 0 | C29: 0 | D29: 0 | E29: сум/мес | G29: Низкая | H29: Продукт
A30: Месяц старта эффекта (1 = первый месяц программы) | B30: 2 | C30: 2 | D30: 2 | E30: мес. | G30: Высокая | H30: Продукт
A31: Месяцев до полного эффекта | B31: 3 | C31: 3 | D31: 3 | E31: мес. | G31: Низкая | H31: Продукт
A32: Разовые затраты (CAPEX / внедрение) | B32: 500000000 | C32: 800000000 | D32: 350000000 | E32: сум | G32: Низкая | H32: IT / биллинг / маркетинг
A33: Постоянные затраты в месяц (OPEX) | B33: 20000000 | C33: 20000000 | D33: 20000000 | E33: сум/мес | G33: Низкая | H33: Владельцы затрат
A34: Переменные затраты на принявшего | B34: 280 | C34: 500 | D34: 150 | E34: сум/мес | G34: Низкая | H34: Сеть / финансы
A35: Маржинальность доп. выручки | B35: 0.74 | C35: 0.65 | D35: 0.8 | E35: % | F35: Бустер 85%, роуминг 60% (оптовые затраты) | G35: Средняя | H35: Финансы
A36: База для ΔARPU: абонентов | B36: 3520000 | C36: 3520000 | D36: 3520000 | E36: абон. | G36: Высокая | H36: Продукт
A37: База для ΔARPU: ARPU без НДС | B37: 18500 | C37: 18500 | D37: 18500 | E37: сум/мес | G37: Высокая | H37: Продукт
A39: 3. БЫСТРЫЙ РАСЧЁТ (sanity-check до финмодели; финансы уточнят NPV, налоги, амортизацию)
A40: Показатель | B40: База | C40: Пессимист | D40: Оптимист | E40: Ед. | F40: Как считается
A41: Принявших, абон. | B41: =B21*B22*B23*(1-B24) -> 56447.776 | C41: =IF(C21="",$B21,C21)*IF(C22="",$B22,C22)*IF(C23="",$B23,C23)*(1-IF(C24="",$B24,C24)) -> 21600 | D41: =IF(D21="",$B21,D21)*IF(D22="",$B22,D22)*IF(D23="",$B23,D23)*(1-IF(D24="",$B24,D24)) -> 125550 | E41: абон. | F41: Размер × охват × принятие × (1 − каннибализация)
A42: Даунгрейд, абон. | B42: =B21*B26 -> 0 | C42: =IF(C21="",$B21,C21)*IF(C26="",$B26,C26) -> 0 | D42: =IF(D21="",$B21,D21)*IF(D26="",$B26,D26) -> 0 | E42: абон. | F42: Размер × доля даунгрейда
A43: Ушедших, абон. | B43: =B21*B28 -> 0 | C43: =IF(C21="",$B21,C21)*IF(C28="",$B28,C28) -> 0 | D43: =IF(D21="",$B21,D21)*IF(D28="",$B28,D28) -> 0 | E43: абон. | F43: Размер × доп. отток
...

Sheet I4
A1: Карточка инициативы · I4
A2: Синее — ввод, чёрное — формулы. Блок 1 — для руководителя, блоки 2–4 — для передачи финансам.
A4: 1. ОДНОСТРАНИЧНИК ДЛЯ РУКОВОДИТЕЛЯ
A5: Название | B5: I4 Ucell Club — программа лояльности (MVP → масштаб)
A6: Владелец (PM) | B6: [ФИО, PM тарифных планов]
A7: Дата / версия | B7: 09.10.2026 · v0.3
A8: Статус | B8: Discovery
A9: Проблема (1–2 предложения, с цифрой) | B9: Нет программы, поощряющей оплату вовремя и стаж; у конкурентов есть (Beeline BEEP, Mobiuz Bonus, розыгрыши авто).
A10: Цель и метрика успеха | B10: Оплата вовремя +2 п.п., отток участников −10%, переходы на ТП ≥ 60 тыс. +0,3 п.п./мес.; стоимость ≤ 1 900 сум на участника.
A11: Целевой сегмент | B11: Пользователи приложения (~1,5 млн при масштабе), из них ~20% архивные; MVP — 150 тыс.
A12: Что делаем (механика) | B12: Кэшбэк 3–5% за оплату вовремя; сундук каждый день; Weekly Wins (1 354 приза); Monthly Grand (авто, путешествия, умра) в прямом эфире.
A13: Почему сработает (бенчмарки, данные) | B13: Verizon Dollars 3% + Shine; T-Mobile Tuesdays (−27% оттока участников); Simon-Kucher: +43% CLTV у участников.
A14: Гипотеза: «Если…, то…, потому что…» | B14: Если давать кэшбэк за оплату вовремя и ежедневный гарантированный приз, то оплаты вовремя и удержание вырастут, потому что появится привычка и потеря при уходе.
A15: Срок запуска и ключевые этапы | B15: Разработка MVP — дек–фев; MVP — мар–май 2027; решение — 15.06.2027; масштаб — сен 2027.
A16: Ключевые риски и как снижаем | B16: Не окупается (MVP + стоп-правила); «никто не выигрывает» (массовые призы); юр. риск розыгрышей (без платы за шанс).
A17: Какое решение нужно от руководителя | B17: Утвердить бюджет MVP 3,5 млрд сум; масштаб — по итогам MVP.
A19: 2. ДРАЙВЕРЫ ДЛЯ ФИНАНСОВ (каждое число — с источником и уверенностью)
A20: Параметр | B20: База | C20: Пессимист | D20: Оптимист | E20: Ед. | F20: Источник / как получено | G20: Уверенность | H20: Кто даёт данные
A21: Размер целевой группы | B21: 1485000 | C21: 1000000 | D21: 2000000 | E21: абон. | F21: Участники при масштабе (MAU × вступление) | G21: Средняя | H21: Аналитика
A22: Охват коммуникацией | B22: 1 | C22: 1 | D22: 1 | E22: % | G22: Высокая | H22: Продукт
A23: Принимают предложение / остаются на новом условии | B23: 1 | C23: 1 | D23: 1 | E23: % | G23: Низкая | H23: Аналитика / пилот
A24: Каннибализация (сделали бы и без нас) | B24: 0 | C24: 0 | D24: 0 | E24: % | G24: Низкая | H24: Аналитика
A25: Прирост платежа на принявшего, с НДС | B25: 3000 | C25: 1500 | D25: 4500 | E25: сум/мес | F25: Упрощённо: эффект на участника в стационаре (удержание + оплата вовремя + переходы + допродажи + Pass); полная модель — v2/model | G25: Средняя | H25: Продукт / прайсинг
A26: Доля даунгрейда (уходят на ТП дешевле) | B26: 0 | C26: 0 | D26: 0 | E26: % | G26: Низкая | H26: Аналитика (D7)
A27: Потеря платежа при даунгрейде, с НДС | B27: 0 | C27: 0 | D27: 0 | E27: сум/мес | G27: Низкая | H27: Продукт
A28: Доп. отток из-за инициативы | B28: 0 | C28: 0 | D28: 0 | E28: % | G28: Низкая | H28: Аналитика (D7)
A29: Платёж уходящих, с НДС | B29: 0 | C29: 0 | D29: 0 | E29: сум/мес | G29: Низкая | H29: Продукт
A30: Месяц старта эффекта (1 = первый месяц программы) | B30: 11 | C30: 11 | D30: 11 | E30: мес. | G30: Высокая | H30: Продукт
A31: Месяцев до полного эффекта | B31: 6 | C31: 6 | D31: 6 | E31: мес. | G31: Низкая | H31: Продукт
A32: Разовые затраты (CAPEX / внедрение) | B32: 6500000000 | C32: 8000000000 | D32: 5000000000 | E32: сум | F32: MVP 1,8 + масштаб 3,0 + маркетинг запуска 1,75 млрд | G32: Средняя | H32: IT / биллинг / маркетинг
A33: Постоянные затраты в месяц (OPEX) | B33: 1082000000 | C33: 1250000000 | D33: 950000000 | E33: сум/мес | F33: Призы (инвентарь + Weekly + Grand) + команда + маркетинг | G33: Средняя | H33: Владельцы затрат
A34: Переменные затраты на принявшего | B34: 1037 | C34: 1250 | D34: 850 | E34: сум/мес | F34: Кэшбэк + цифровые призы сундука | G34: Средняя | H34: Сеть / финансы
A35: Маржинальность доп. выручки | B35: 0.85 | C35: 0.85 | D35: 0.85 | E35: % | G35: Высокая | H35: Финансы
A36: База для ΔARPU: абонентов | B36: 1485000 | C36: 1485000 | D36: 1485000 | E36: абон. | F36: ΔARPU — по участникам программы | G36: Средняя | H36: Продукт
A37: База для ΔARPU: ARPU без НДС | B37: 43929 | C37: 43929 | D37: 43929 | E37: сум/мес | G37: Высокая | H37: Продукт
A39: 3. БЫСТРЫЙ РАСЧЁТ (sanity-check до финмодели; финансы уточнят NPV, налоги, амортизацию)
A40: Показатель | B40: База | C40: Пессимист | D40: Оптимист | E40: Ед. | F40: Как считается
A41: Принявших, абон. | B41: =B21*B22*B23*(1-B24) -> 1485000 | C41: =IF(C21="",$B21,C21)*IF(C22="",$B22,C22)*IF(C23="",$B23,C23)*(1-IF(C24="",$B24,C24)) -> 1000000 | D41: =IF(D21="",$B21,D21)*IF(D22="",$B22,D22)*IF(D23="",$B23,D23)*(1-IF(D24="",$B24,D24)) -> 2000000 | E41: абон. | F41: Размер × охват × принятие × (1 − каннибализация)
A42: Даунгрейд, абон. | B42: =B21*B26 -> 0 | C42: =IF(C21="",$B21,C21)*IF(C26="",$B26,C26) -> 0 | D42: =IF(D21="",$B21,D21)*IF(D26="",$B26,D26) -> 0 | E42: абон. | F42: Размер × доля даунгрейда
A43: Ушедших, абон. | B43: =B21*B28 -> 0 | C43: =IF(C21="",$B21,C21)*IF(C28="",$B28,C28) -> 0 | D43: =IF(D21="",$B21,D21)*IF(D28="",$B28,D28) -> 0 | E43: абон. | F43: Размер × доп. отток
...

Sheet Пустой шаблон
A1: Карточка инициативы · Пустой шаблон
A2: Синее — ввод, чёрное — формулы. Блок 1 — для руководителя, блоки 2–4 — для передачи финансам.
A4: 1. ОДНОСТРАНИЧНИК ДЛЯ РУКОВОДИТЕЛЯ
A5: Название
A6: Владелец (PM)
A7: Дата / версия
A8: Статус
A9: Проблема (1–2 предложения, с цифрой)
A10: Цель и метрика успеха
A11: Целевой сегмент
A12: Что делаем (механика)
A13: Почему сработает (бенчмарки, данные)
... A19: 2. ДРАЙВЕРЫ ДЛЯ ФИНАНСОВ (каждое число — с источником и уверенностью)
A20: Параметр | B20: База | C20: Пессимист | D20: Оптимист | E20: Ед. | F20: Источник / как получено | G20: Уверенность | H20: Кто даёт данные
A21: Размер целевой группы | E21: абон. | H21: Аналитика
A22: Охват коммуникацией | E22: % | H22: Продукт
A23: Принимают предложение / остаются на новом условии | E23: % | H23: Аналитика / пилот
A24: Каннибализация (сделали бы и без нас) | E24: % | H24: Аналитика
A25: Прирост платежа на принявшего, с НДС | E25: сум/мес | H25: Продукт / прайсинг
A26: Доля даунгрейда (уходят на ТП дешевле) | E26: % | H26: Аналитика (D7)
A27: Потеря платежа при даунгрейде, с НДС | E27: сум/мес | H27: Продукт
A28: Доп. отток из-за инициативы | E28: % | H28: Аналитика (D7)
A29: Платёж уходящих, с НДС | E29: сум/мес | H29: Продукт
A30: Месяц старта эффекта (1 = первый месяц программы) | E30: мес. | H30: Продукт
A31: Месяцев до полного эффекта | E31: мес. | H31: Продукт
A32: Разовые затраты (CAPEX / внедрение) | E32: сум | H32: IT / биллинг / маркетинг
... A37: База для ΔARPU: ARPU без НДС | E37: сум/мес | H37: Продукт
A39: 3. БЫСТРЫЙ РАСЧЁТ (sanity-check до финмодели; финансы уточнят NPV, налоги, амортизацию)
A40: Показатель | B40: База | C40: Пессимист | D40: Оптимист | E40: Ед. | F40: Как считается
A41: Принявших, абон. | B41: =B21*B22*B23*(1-B24) -> 0 | C41: =IF(C21="",$B21,C21)*IF(C22="",$B22,C22)*IF(C23="",$B23,C23)*(1-IF(C24="",$B24,C24)) -> 0 | D41: =IF(D21="",$B21,D21)*IF(D22="",$B22,D22)*IF(D23="",$B23,D23)*(1-IF(D24="",$B24,D24)) -> 0 | E41: абон. | F41: Размер × охват × принятие × (1 − каннибализация)
A42: Даунгрейд, абон. | B42: =B21*B26 -> 0 | C42: =IF(C21="",$B21,C21)*IF(C26="",$B26,C26) -> 0 | D42: =IF(D21="",$B21,D21)*IF(D26="",$B26,D26) -> 0 | E42: абон. | F42: Размер × доля даунгрейда
A43: Ушедших, абон. | B43: =B21*B28 -> 0 | C43: =IF(C21="",$B21,C21)*IF(C28="",$B28,C28) -> 0 | D43: =IF(D21="",$B21,D21)*IF(D28="",$B28,D28) -> 0 | E43: абон. | F43: Размер × доп. отток
A44: Доп. выручка в месяц при полном эффекте, без НДС | B44: =(B41*B25-B42*B27-B43*B29)/(1+Портфель!$B$5) -> 0 | C44: =(C41*IF(C25="",$B25,C25)-C42*IF(C27="",$B27,C27)-C43*IF(C29="",$B29,C29))/(1+Портфель!$B$5) -> 0 | D44: =(D41*IF(D25="",$B25,D25)-D42*IF(D27="",$B27,D27)-D43*IF(D29="",$B29,D29))/(1+Портфель!$B$5) -> 0 | E44: сум/мес | F44: (Принявшие × прирост − даунгрейд × потеря − ушедшие × платёж) / (1 + НДС)
A45: Месяцев эффекта в 1-й год | B45: =MAX(0,12-B30+1) -> 13 | C45: =MAX(0,12-IF(C30="",$B30,C30)+1) -> 13 | D45: =MAX(0,12-IF(D30="",$B30,D30)+1) -> 13 | E45: мес. | F45: 12 − месяц старта + 1
A46: Эффективных месяцев в 1-й год (с набором) | B46: =IF(B45>=B31,(B31+1)/2+(B45-B31),B45*(B45+1)/(2*MAX(1,B31))) -> 13.5 | C46: =IF(C45>=IF(C31="",$B31,C31),(IF(C31="",$B31,C31)+1)/2+(C45-IF(C31="",$B31,C31)),C45*(C45+1)/(2*MAX(1,IF(C31="",$B31,C31)))) -> 13.5 | D46: =IF(D45>=IF(D31="",$B31,D31),(IF(D31="",$B31,D31)+1)/2+(D45-IF(D31="",$B31,D31)),D45*(D45+1)/(2*MAX(1,IF(D31="",$B31,D31)))) -> 13.5 | E46: мес. | F46: Учитывает линейный набор эффекта
A47: Месяцев эффекта за 24 мес. | B47: =MAX(0,24-B30+1) -> 25 | C47: =MAX(0,24-IF(C30="",$B30,C30)+1) -> 25 | D47: =MAX(0,24-IF(D30="",$B30,D30)+1) -> 25 | E47: мес. | F47: 24 − месяц старта + 1
A48: Эффективных месяцев за 24 мес. | B48: =IF(B47>=B31,(B31+1)/2+(B47-B31),B47*(B47+1)/(2*MAX(1,B31))) -> 25.5 | C48: =IF(C47>=IF(C31="",$B31,C31),(IF(C31="",$B31,C31)+1)/2+(C47-IF(C31="",$B31,C31)),C47*(C47+1)/(2*MAX(1,IF(C31="",$B31,C31)))) -> 25.5 | D48: =IF(D47>=IF(D31="",$B31,D31),(IF(D31="",$B31,D31)+1)/2+(D47-IF(D31="",$B31,D31)),D47*(D47+1)/(2*MAX(1,IF(D31="",$B31,D31)))) -> 25.5 | E48: мес.
A49: Доп. выручка за 1-й год | B49: =B44*B46 -> 0 | C49: =C44*C46 -> 0 | D49: =D44*D46 -> 0 | E49: сум | F49: Месячная × эффективные месяцы
A50: Доп. выручка за 24 мес. | B50: =B44*B48 -> 0 | C50: =C44*C48 -> 0 | D50: =D44*D48 -> 0 | E50: сум
A51: Затраты за 24 мес. | B51: =B32+B33*B47+B34*B41*B48 -> 0 | C51: =IF(C32="",$B32,C32)+IF(C33="",$B33,C33)*C47+IF(C34="",$B34,C34)*C41*C48 -> 0 | D51: =IF(D32="",$B32,D32)+IF(D33="",$B33,D33)*D47+IF(D34="",$B34,D34)*D41*D48 -> 0 | E51: сум | F51: CAPEX + OPEX × месяцы + перем. × принявшие × эфф. месяцы
...
