Workbook

Sheet README
A1: Ucell v2 — 4 инициативы роста ARPU архивной базы + Loyalty program
A3: I1 Sunset / Migration → ТП дороже на 10–15% · I2 More-for-More · I3 Бустер при исчерпании + роуминг-промо · I4 Loyalty (кэшбэк, Daily Drops, Weekly Wins, Monthly Grand)
A5: Как пользоваться
A6: 1. Жёлтые ячейки — гипотезы: заменить фактом из запроса данных (v2/docs/12_data_request_for_analysts.md).
A7: 2. Синие — параметры (меняйте по итогам пилотов и MVP). Чёрные — формулы. Зелёные — ссылки на другие листы.
A8: 3. Monthly_I и Loyalty_Monthly — помесячные движки на 36 мес. (M1 = ноябрь 2026).
A9: 4. Prizes и Daily_Drops — каталог призов в сумах, фонды Weekly/Monthly, таблица вероятностей сундука.
A10: 5. Thresholds — сравнение вариантов порога участия (O1–O5). MVP_Budget — бюджет пилота программы.
A11: 6. MC_Results — вероятности из Монте-Карло (python v2/model/model_v2.py), это значения, не формулы.
A13: Единицы: сумы без НДС 12% (цены призов и абонплаты — с НДС, где указано). ARPU — по когорте архивных абонентов T0.
A14: Excel повторяет детерминированный прогон Python на модальных значениях.

Sheet Inputs
A1: Базовые допущения (архивная когорта)
A3: Параметр | C3: Значение | D3: Ед. | E3: Источник / комментарий
A4: Абонентская база Ucell | C4: 11000000 | D4: абон. | E4: Ucell: >10,9 млн на начало 2026
A5: Доля абонентов на архивных ТП | C5: 0.4 | D5: % | E5: HYPOTHESIS — запрос D1
A6: Доля активных среди архивных | C6: 0.8 | D6: % | E6: HYPOTHESIS — запрос D1
A7: Активная архивная когорта (N) | C7: =C4*C5*C6 -> 3520000 | D7: абон. | E7: Формула
A8: ARPU архивной когорты (net) | C8: 18500 | D8: сум/мес | E8: HYPOTHESIS — запрос D2
A9: Месячный отток архивной когорты | C9: 0.015 | D9: % | E9: HYPOTHESIS — запрос D4
A10: НДС | C10: 0.12 | D10: % | E10: НК РУз: 12%
A11: Курс, сум за 1 USD | C11: 12100 | D11: сум | E11: ЦБ РУз, 2026
A12: Рынок мобильной связи, абонентов | C12: 36500000 | D12: абон. | E12: HYPOTHESIS
A13: Выручка когорты в месяц | C13: =C7*C8 -> 65120000000 | D13: сум/мес | E13: Формула
A14: Перекрытие эффектов I1–I3 | C14: 0.1 | D14: % | E14: Одни и те же абоненты в нескольких инициативах

Sheet Initiatives
A1: Инициативы I1–I3: параметры (синие) → производные → итоги (из Monthly_I)
A3: Параметр | B3: Ключ | C3: I1 | D3: I2 | E3: I3a | F3: I3b
A4: Название | B4: name | C4: Sunset / Migration старых неэффективных линеек → ТП дороже на 10–15% | D4: More-for-More: + абонплата и + трафик для когорты недооценённых линеек | E4: Пакет-бустер для исчерпывающих трафик (opt-in автопродление) | F4: Роуминг-пакет по акции (−50% первый месяц) для выезжающих
A5: Коротко | B5: short | C5: Sunset / Migration | D5: More-for-More | E5: Бустер при исчерпании | F5: Роуминг-промо
A6: Тип механики | B6: type | C6: reprice | D6: reprice | E6: adoption | F6: adoption
A7: Сложность биллинг/интеграции (1–5) | B7: complexity | C7: 4 | D7: 1 | E7: 2 | F7: 2
A8: ARPU целевого сегмента, сум | B8: segment_arpu | C8: 16000 | D8: 21000 | E8: 28000 | F8: 15000
A9: Доля целевой группы от когорты | B9: eligible_share | C9: 0.3 | D9: 0.22 | E9: 0.15 | F9: 0.06
A10: Новый ТП дороже на, % (I1) | B10: price_up_pct | C10: 0.125 | D10: 0 | E10: 0 | F10: 0
A11: Текущая абонплата мигрируемых линеек, с НДС (I1) | B11: base_fee_gross | C11: 20000 | D11: 0 | E11: 0 | F11: 0
A12: Повышение абонплаты, сум с НДС (I2) | B12: price_up_gross | C12: 0 | D12: 5000 | E12: 0 | F12: 0
A13: Доля выбравших ТП крупнее | B13: upsell_share | C13: 0.12 | D13: 0 | E13: 0 | F13: 0
A14: Доп. ARPU у выбравших крупнее, сум | B14: upsell_delta | C14: 10000 | D14: 0 | E14: 0 | F14: 0
A15: Доля даунгрейда | B15: downgrade | C15: 0.08 | D15: 0.08 | E15: 0 | F15: 0
A16: Δ выручки при даунгрейде, сум | B16: downgrade_delta | C16: -2000 | D16: -3000 | E16: 0 | F16: 0
A17: Доп. отток | B17: churn_incr | C17: 0.03 | D17: 0.025 | E17: 0 | F17: 0
A18: Себестоимость доп. трафика, сум/мес | B18: data_cost_m | C18: 300 | D18: 400 | E18: 0 | F18: 0
... A35: Вероятность запуска | B35: exec_prob | C35: 0.65 | D35: 0.8 | E35: 0.9 | F35: 0.9
A37: ПРОИЗВОДНЫЕ
A38: Целевая группа, абон. | B38: elig | C38: =Inputs!$C$7*C9 -> 1056000 | D38: =Inputs!$C$7*D9 -> 774400 | E38: =Inputs!$C$7*E9 -> 528000 | F38: =Inputs!$C$7*F9 -> 211200
A39: Охвачено, абон. | B39: contacted | C39: =IF(C6="adoption",C38*C20,C38) -> 1056000 | D39: =IF(D6="adoption",D38*D20,D38) -> 774400 | E39: =IF(E6="adoption",E38*E20,E38) -> 475200 | F39: =IF(F6="adoption",F38*F20,F38) -> 168960
A40: Адоптеры при полном наборе | B40: a_final | C40: =IF(C6="adoption",C39*C21*(1-C22),0) -> 0 | D40: =IF(D6="adoption",D39*D21*(1-D22),0) -> 0 | E40: =IF(E6="adoption",E39*E21*(1-E22),0) -> 31363.2 | F40: =IF(F6="adoption",F39*F21*(1-F22),0) -> 25344
A41: Повышение абонплаты net, сум | B41: up_net | C41: =IF(C10>0,C11*C10,C12)/(1+Inputs!$C$10) -> 2232.1429 | D41: =IF(D10>0,D11*D10,D12)/(1+Inputs!$C$10) -> 4464.2857 | E41: =IF(E10>0,E11*E10,E12)/(1+Inputs!$C$10) -> 0 | F41: =IF(F10>0,F11*F10,F12)/(1+Inputs!$C$10) -> 0
A42: Остаются и платят больше | B42: stay | C42: =IF(C6="reprice",C38*(1-C15-C17),0) -> 939840 | D42: =IF(D6="reprice",D38*(1-D15-D17),0) -> 693088 | E42: =IF(E6="reprice",E38*(1-E15-E17),0) -> 0 | F42: =IF(F6="reprice",F38*(1-F15-F17),0) -> 0
A43: Даунгрейд, абон. | B43: down | C43: =IF(C6="reprice",C38*C15,0) -> 84480 | D43: =IF(D6="reprice",D38*D15,0) -> 61952 | E43: =IF(E6="reprice",E38*E15,0) -> 0 | F43: =IF(F6="reprice",F38*F15,0) -> 0
A44: Доп. отток всего, абон. | B44: lost_total | C44: =C39*C17 -> 31680 | D44: =D39*D17 -> 19360 | E44: =E39*E17 -> 0 | F44: =F39*F17 -> 0
A45: Месяцев подготовки | B45: build | C45: =MAX(C31-1,1) -> 5 | D45: =MAX(D31-1,1) -> 1 | E45: =MAX(E31-1,1) -> 1 | F45: =MAX(F31-1,1) -> 1
A46: Месяц оценки (12-й после старта) | B46: eval_m | C46: =MIN(C31+11,36) -> 17 | D46: =MIN(D31+11,36) -> 13 | E46: =MIN(E31+11,36) -> 13 | F46: =MIN(F31+11,36) -> 13
A48: ИТОГИ
A49: Выручка Y1 | B49: rev1 | C49: =SUM(Monthly_I!C16:N16) -> 1.4494602e+10 | D49: =SUM(Monthly_I!C30:N30) -> 2.1823874e+10 | E49: =SUM(Monthly_I!C44:N44) -> 2.3391784e+09 | F49: =SUM(Monthly_I!C58:N58) -> 1.7286954e+09
A50: Выручка Y2 | B50: rev2 | C50: =SUM(Monthly_I!O16:Z16) -> 2.7332819e+10 | D50: =SUM(Monthly_I!O30:Z30) -> 2.4043884e+10 | E50: =SUM(Monthly_I!O44:Z44) -> 2.3467208e+09 | F50: =SUM(Monthly_I!O58:Z58) -> 1.9396764e+09
A51: Выручка Y3 | B51: rev3 | C51: =SUM(Monthly_I!AA16:AL16) -> 2.2799178e+10 | D51: =SUM(Monthly_I!AA30:AL30) -> 2.0055772e+10 | E51: =SUM(Monthly_I!AA44:AL44) -> 2.0388521e+09 | F51: =SUM(Monthly_I!AA58:AL58) -> 1.7901325e+09
A52: Run-rate/год на M24 | B52: runrate | C52: =Monthly_I!Z16*12 -> 2.5118447e+10 | D52: =Monthly_I!Z30*12 -> 2.2095965e+10 | E52: =Monthly_I!Z44*12 -> 2.1989019e+09 | F52: =Monthly_I!Z58*12 -> 1.8711774e+09
A53: Затраты 24 мес. | B53: cost24 | C53: =SUM(Monthly_I!C17:Z17) -> 9.0958994e+09 | D53: =SUM(Monthly_I!C31:Z31) -> 5.9037909e+09 | E53: =SUM(Monthly_I!C45:Z45) -> 9.0744142e+08 | F53: =SUM(Monthly_I!C59:Z59) -> 557408000
A54: Вклад 24 мес. | B54: contrib24 | C54: =SUM(Monthly_I!C18:Z18) -> 3.2731522e+10 | D54: =SUM(Monthly_I!C32:Z32) -> 3.9963968e+10 | E54: =SUM(Monthly_I!C46:Z46) -> 3.0755729e+09 | F54: =SUM(Monthly_I!C60:Z60) -> 1.6436151e+09
A55: Вклад 36 мес. | B55: contrib36 | C55: =SUM(Monthly_I!C18:AL18) -> 5.3496876e+10 | D55: =SUM(Monthly_I!C32:AL32) -> 5.7554455e+10 | E55: =SUM(Monthly_I!C46:AL46) -> 4.5625348e+09 | F55: =SUM(Monthly_I!C60:AL60) -> 2.5976946e+09
A56: ROI 24 мес. | B56: roi24 | C56: =IF(C53>0,C54/C53,0) -> 3.5984921 | D56: =IF(D53>0,D54/D53,0) -> 6.7692044 | E56: =IF(E53>0,E54/E53,0) -> 3.3892798 | F56: =IF(F53>0,F54/F53,0) -> 2.9486751
A57: ΔARPU когорты на месяц оценки | B57: upl_eval | C57: =(INDEX(Monthly_I!$C$5:$AL$5,1,C46)+INDEX(Monthly_I!$C$16:$AL$16,1,C46))/(INDEX(Monthly_I!$C$4:$AL$4,1,C46)+INDEX(Monthly_I!$C$19:$AL$19,1,C46))/Inputs!$C$8-1 -> 0.056936525 | D57: =(INDEX(Monthly_I!$C$5:$AL$5,1,D46)+INDEX(Monthly_I!$C$30:$AL$30,1,D46))/(INDEX(Monthly_I!$C$4:$AL$4,1,D46)+INDEX(Monthly_I!$C$33:$AL$33,1,D46))/Inputs!$C$8-1 -> 0.046783771 | E57: =(INDEX(Monthly_I!$C$5:$AL$5,1,E46)+INDEX(Monthly_I!$C$44:$AL$44,1,E46))/(INDEX(Monthly_I!$C$4:$AL$4,1,E46)+INDEX(Monthly_I!$C$47:$AL$47,1,E46))/Inputs!$C$8-1 -> 0.0038192832 | F57: =(INDEX(Monthly_I!$C$5:$AL$5,1,F46)+INDEX(Monthly_I!$C$58:$AL$58,1,F46))/(INDEX(Monthly_I!$C$4:$AL$4,1,F46)+INDEX(Monthly_I!$C$61:$AL$61,1,F46))/Inputs!$C$8-1 -> 0.0028942094
A58: ΔARPU когорты на M24 | B58: upl24 | C58: =(Monthly_I!Z$5+Monthly_I!Z16)/(Monthly_I!Z$4+Monthly_I!Z19)/Inputs!$C$8-1 -> 0.056936525 | D58: =(Monthly_I!Z$5+Monthly_I!Z30)/(Monthly_I!Z$4+Monthly_I!Z33)/Inputs!$C$8-1 -> 0.046783771 | E58: =(Monthly_I!Z$5+Monthly_I!Z44)/(Monthly_I!Z$4+Monthly_I!Z47)/Inputs!$C$8-1 -> 0.0038910367 | F58: =(Monthly_I!Z$5+Monthly_I!Z58)/(Monthly_I!Z$4+Monthly_I!Z61)/Inputs!$C$8-1 -> 0.0029434064
A59: Δ абонентов на M24 | B59: dsubs24 | C59: =Monthly_I!Z19 -> -24882.204 | D59: =Monthly_I!Z33 -> -14375.707 | E59: =Monthly_I!Z47 -> 373.84642 | F59: =Monthly_I!Z61 -> 1216.3559
...

Sheet Monthly_I
A1: Помесячный движок I1–I3 (36 мес., сум без НДС)
A3: Месяц | C3: 1 | D3: 2 | E3: 3 | F3: 4 | G3: 5 | H3: 6 | I3: 7 | J3: 8 | K3: 9 | L3: 10 | M3: 11 | N3: 12 | O3: 13 | P3: 14 | Q3: 15 | R3: 16 | S3: 17 | T3: 18 | U3: 19 | V3: 20 | W3: 21 | X3: 22 | Y3: 23 | Z3: 24 | AA3: 25 | AB3: 26 | AC3: 27 | AD3: 28 | AE3: 29 | AF3: 30 | AG3: 31 | AH3: 32 | AI3: 33 | AJ3: 34 | AK3: 35 | AL3: 36
A4: S0: абоненты когорты без инициатив | C4: =Inputs!$C$7*(1-Inputs!$C$9)^C$3 -> 3467200 | D4: =Inputs!$C$7*(1-Inputs!$C$9)^D$3 -> 3415192 | E4: =Inputs!$C$7*(1-Inputs!$C$9)^E$3 -> 3363964.1 | F4: =Inputs!$C$7*(1-Inputs!$C$9)^F$3 -> 3313504.7 | G4: =Inputs!$C$7*(1-Inputs!$C$9)^G$3 -> 3263802.1 | H4: =Inputs!$C$7*(1-Inputs!$C$9)^H$3 -> 3214845.1 | I4: =Inputs!$C$7*(1-Inputs!$C$9)^I$3 -> 3166622.4 | J4: =Inputs!$C$7*(1-Inputs!$C$9)^J$3 -> 3119123 | ... AL4: =Inputs!$C$7*(1-Inputs!$C$9)^AL$3 -> 2042899.3
A5: R0: выручка когорты без инициатив | C5: =C4*Inputs!$C$8 -> 64143200000 | D5: =D4*Inputs!$C$8 -> 63181052000 | E5: =E4*Inputs!$C$8 -> 62233336220 | F5: =F4*Inputs!$C$8 -> 6.1299836e+10 | G5: =G4*Inputs!$C$8 -> 6.0380339e+10 | H5: =H4*Inputs!$C$8 -> 5.9474634e+10 | I5: =I4*Inputs!$C$8 -> 5.8582514e+10 | J5: =J4*Inputs!$C$8 -> 5.7703776e+10 | ... AL5: =AL4*Inputs!$C$8 -> 3.7793637e+10
A7: I1 — Sunset / Migration старых неэффективных линеек → ТП дороже на 10–15%
A8: Доля набора | B8: f | C8: =IF(Initiatives!$C$6="adoption",IF(C$3<Initiatives!$C$31,0,MIN((C$3-Initiatives!$C$31+1)/Initiatives!$C$34,1)),0) -> 0 | D8: =IF(Initiatives!$C$6="adoption",IF(D$3<Initiatives!$C$31,0,MIN((D$3-Initiatives!$C$31+1)/Initiatives!$C$34,1)),0) -> 0 | E8: =IF(Initiatives!$C$6="adoption",IF(E$3<Initiatives!$C$31,0,MIN((E$3-Initiatives!$C$31+1)/Initiatives!$C$34,1)),0) -> 0 | F8: =IF(Initiatives!$C$6="adoption",IF(F$3<Initiatives!$C$31,0,MIN((F$3-Initiatives!$C$31+1)/Initiatives!$C$34,1)),0) -> 0 | G8: =IF(Initiatives!$C$6="adoption",IF(G$3<Initiatives!$C$31,0,MIN((G$3-Initiatives!$C$31+1)/Initiatives!$C$34,1)),0) -> 0 | H8: =IF(Initiatives!$C$6="adoption",IF(H$3<Initiatives!$C$31,0,MIN((H$3-Initiatives!$C$31+1)/Initiatives!$C$34,1)),0) -> 0 | I8: =IF(Initiatives!$C$6="adoption",IF(I$3<Initiatives!$C$31,0,MIN((I$3-Initiatives!$C$31+1)/Initiatives!$C$34,1)),0) -> 0 | J8: =IF(Initiatives!$C$6="adoption",IF(J$3<Initiatives!$C$31,0,MIN((J$3-Initiatives!$C$31+1)/Initiatives!$C$34,1)),0) -> 0 | ... AL8: =IF(Initiatives!$C$6="adoption",IF(AL$3<Initiatives!$C$31,0,MIN((AL$3-Initiatives!$C$31+1)/Initiatives!$C$34,1)),0) -> 0
A9: Адоптеры (цель) | B9: target | C9: =Initiatives!$C$40*C8 -> 0 | D9: =Initiatives!$C$40*D8 -> 0 | E9: =Initiatives!$C$40*E8 -> 0 | F9: =Initiatives!$C$40*F8 -> 0 | G9: =Initiatives!$C$40*G8 -> 0 | H9: =Initiatives!$C$40*H8 -> 0 | I9: =Initiatives!$C$40*I8 -> 0 | J9: =Initiatives!$C$40*J8 -> 0 | ... AL9: =Initiatives!$C$40*AL8 -> 0
A10: Новые адоптеры | B10: new | C10: =MAX(C9-N(B9),0) -> 0 | D10: =MAX(D9-N(C9),0) -> 0 | E10: =MAX(E9-N(D9),0) -> 0 | F10: =MAX(F9-N(E9),0) -> 0 | G10: =MAX(G9-N(F9),0) -> 0 | H10: =MAX(H9-N(G9),0) -> 0 | I10: =MAX(I9-N(H9),0) -> 0 | J10: =MAX(J9-N(I9),0) -> 0 | ... AL10: =MAX(AL9-N(AK9),0) -> 0
A11: Удержанные | B11: R | C11: =IF(Initiatives!$C$6="adoption",N(B11)*(1-Inputs!$C$9)+N(B12)*Inputs!$C$9*Initiatives!$C$24,0) -> 0 | D11: =IF(Initiatives!$C$6="adoption",N(C11)*(1-Inputs!$C$9)+N(C12)*Inputs!$C$9*Initiatives!$C$24,0) -> 0 | E11: =IF(Initiatives!$C$6="adoption",N(D11)*(1-Inputs!$C$9)+N(D12)*Inputs!$C$9*Initiatives!$C$24,0) -> 0 | F11: =IF(Initiatives!$C$6="adoption",N(E11)*(1-Inputs!$C$9)+N(E12)*Inputs!$C$9*Initiatives!$C$24,0) -> 0 | G11: =IF(Initiatives!$C$6="adoption",N(F11)*(1-Inputs!$C$9)+N(F12)*Inputs!$C$9*Initiatives!$C$24,0) -> 0 | H11: =IF(Initiatives!$C$6="adoption",N(G11)*(1-Inputs!$C$9)+N(G12)*Inputs!$C$9*Initiatives!$C$24,0) -> 0 | I11: =IF(Initiatives!$C$6="adoption",N(H11)*(1-Inputs!$C$9)+N(H12)*Inputs!$C$9*Initiatives!$C$24,0) -> 0 | J11: =IF(Initiatives!$C$6="adoption",N(I11)*(1-Inputs!$C$9)+N(I12)*Inputs!$C$9*Initiatives!$C$24,0) -> 0 | ... AL11: =IF(Initiatives!$C$6="adoption",N(AK11)*(1-Inputs!$C$9)+N(AK12)*Inputs!$C$9*Initiatives!$C$24,0) -> 0
A12: Пул адоптеров | B12: pool | C12: =N(B12)*(1-Inputs!$C$9*(1-Initiatives!$C$24))+C10 -> 0 | D12: =N(C12)*(1-Inputs!$C$9*(1-Initiatives!$C$24))+D10 -> 0 | E12: =N(D12)*(1-Inputs!$C$9*(1-Initiatives!$C$24))+E10 -> 0 | F12: =N(E12)*(1-Inputs!$C$9*(1-Initiatives!$C$24))+F10 -> 0 | G12: =N(F12)*(1-Inputs!$C$9*(1-Initiatives!$C$24))+G10 -> 0 | H12: =N(G12)*(1-Inputs!$C$9*(1-Initiatives!$C$24))+H10 -> 0 | I12: =N(H12)*(1-Inputs!$C$9*(1-Initiatives!$C$24))+I10 -> 0 | J12: =N(I12)*(1-Inputs!$C$9*(1-Initiatives!$C$24))+J10 -> 0 | ... AL12: =N(AK12)*(1-Inputs!$C$9*(1-Initiatives!$C$24))+AL10 -> 0
A13: Вес волн × затухание | B13: w | C13: =IF(Initiatives!$C$6="adoption",0,IF(C$3>=Initiatives!$C$31,Initiatives!$C$32*(1-Inputs!$C$9)^(C$3-Initiatives!$C$31),0)+IF(C$3>=Initiatives!$C$33,(1-Initiatives!$C$32)*(1-Inputs!$C$9)^(C$3-Initiatives!$C$33),0)) -> 0 | D13: =IF(Initiatives!$C$6="adoption",0,IF(D$3>=Initiatives!$C$31,Initiatives!$C$32*(1-Inputs!$C$9)^(D$3-Initiatives!$C$31),0)+IF(D$3>=Initiatives!$C$33,(1-Initiatives!$C$32)*(1-Inputs!$C$9)^(D$3-Initiatives!$C$33),0)) -> 0 | E13: =IF(Initiatives!$C$6="adoption",0,IF(E$3>=Initiatives!$C$31,Initiatives!$C$32*(1-Inputs!$C$9)^(E$3-Initiatives!$C$31),0)+IF(E$3>=Initiatives!$C$33,(1-Initiatives!$C$32)*(1-Inputs!$C$9)^(E$3-Initiatives!$C$33),0)) -> 0 | F13: =IF(Initiatives!$C$6="adoption",0,IF(F$3>=Initiatives!$C$31,Initiatives!$C$32*(1-Inputs!$C$9)^(F$3-Initiatives!$C$31),0)+IF(F$3>=Initiatives!$C$33,(1-Initiatives!$C$32)*(1-Inputs!$C$9)^(F$3-Initiatives!$C$33),0)) -> 0 | G13: =IF(Initiatives!$C$6="adoption",0,IF(G$3>=Initiatives!$C$31,Initiatives!$C$32*(1-Inputs!$C$9)^(G$3-Initiatives!$C$31),0)+IF(G$3>=Initiatives!$C$33,(1-Initiatives!$C$32)*(1-Inputs!$C$9)^(G$3-Initiatives!$C$33),0)) -> 0 | H13: =IF(Initiatives!$C$6="adoption",0,IF(H$3>=Initiatives!$C$31,Initiatives!$C$32*(1-Inputs!$C$9)^(H$3-Initiatives!$C$31),0)+IF(H$3>=Initiatives!$C$33,(1-Initiatives!$C$32)*(1-Inputs!$C$9)^(H$3-Initiatives!$C$33),0)) -> 0.5 | I13: =IF(Initiatives!$C$6="adoption",0,IF(I$3>=Initiatives!$C$31,Initiatives!$C$32*(1-Inputs!$C$9)^(I$3-Initiatives!$C$31),0)+IF(I$3>=Initiatives!$C$33,(1-Initiatives!$C$32)*(1-Inputs!$C$9)^(I$3-Initiatives!$C$33),0)) -> 0.4925 | J13: =IF(Initiatives!$C$6="adoption",0,IF(J$3>=Initiatives!$C$31,Initiatives!$C$32*(1-Inputs!$C$9)^(J$3-Initiatives!$C$31),0)+IF(J$3>=Initiatives!$C$33,(1-Initiatives!$C$32)*(1-Inputs!$C$9)^(J$3-Initiatives!$C$33),0)) -> 0.4851125 | ... AL13: =IF(Initiatives!$C$6="adoption",0,IF(AL$3>=Initiatives!$C$31,Initiatives!$C$32*(1-Inputs!$C$9)^(AL$3-Initiatives!$C$31),0)+IF(AL$3>=Initiatives!$C$33,(1-Initiatives!$C$32)*(1-Inputs!$C$9)^(AL$3-Initiatives!$C$33),0)) -> 0.6501958
A14: Новый доп. отток | B14: newlost | C14: =IF(Initiatives!$C$6="adoption",IF(AND(C$3>=Initiatives!$C$31,C$3<Initiatives!$C$31+3),Initiatives!$C$44/3,0),IF(AND(C$3>=Initiatives!$C$31,C$3<Initiatives!$C$31+2),Initiatives!$C$32*Initiatives!$C$44/2,0)+IF(AND(C$3>=Initiatives!$C$33,C$3<Initiatives!$C$33+2),(1-Initiatives!$C$32)*Initiatives!$C$44/2,0)) -> 0 | D14: =IF(Initiatives!$C$6="adoption",IF(AND(D$3>=Initiatives!$C$31,D$3<Initiatives!$C$31+3),Initiatives!$C$44/3,0),IF(AND(D$3>=Initiatives!$C$31,D$3<Initiatives!$C$31+2),Initiatives!$C$32*Initiatives!$C$44/2,0)+IF(AND(D$3>=Initiatives!$C$33,D$3<Initiatives!$C$33+2),(1-Initiatives!$C$32)*Initiatives!$C$44/2,0)) -> 0 | E14: =IF(Initiatives!$C$6="adoption",IF(AND(E$3>=Initiatives!$C$31,E$3<Initiatives!$C$31+3),Initiatives!$C$44/3,0),IF(AND(E$3>=Initiatives!$C$31,E$3<Initiatives!$C$31+2),Initiatives!$C$32*Initiatives!$C$44/2,0)+IF(AND(E$3>=Initiatives!$C$33,E$3<Initiatives!$C$33+2),(1-Initiatives!$C$32)*Initiatives!$C$44/2,0)) -> 0 | F14: =IF(Initiatives!$C$6="adoption",IF(AND(F$3>=Initiatives!$C$31,F$3<Initiatives!$C$31+3),Initiatives!$C$44/3,0),IF(AND(F$3>=Initiatives!$C$31,F$3<Initiatives!$C$31+2),Initiatives!$C$32*Initiatives!$C$44/2,0)+IF(AND(F$3>=Initiatives!$C$33,F$3<Initiatives!$C$33+2),(1-Initiatives!$C$32)*Initiatives!$C$44/2,0)) -> 0 | G14: =IF(Initiatives!$C$6="adoption",IF(AND(G$3>=Initiatives!$C$31,G$3<Initiatives!$C$31+3),Initiatives!$C$44/3,0),IF(AND(G$3>=Initiatives!$C$31,G$3<Initiatives!$C$31+2),Initiatives!$C$32*Initiatives!$C$44/2,0)+IF(AND(G$3>=Initiatives!$C$33,G$3<Initiatives!$C$33+2),(1-Initiatives!$C$32)*Initiatives!$C$44/2,0)) -> 0 | H14: =IF(Initiatives!$C$6="adoption",IF(AND(H$3>=Initiatives!$C$31,H$3<Initiatives!$C$31+3),Initiatives!$C$44/3,0),IF(AND(H$3>=Initiatives!$C$31,H$3<Initiatives!$C$31+2),Initiatives!$C$32*Initiatives!$C$44/2,0)+IF(AND(H$3>=Initiatives!$C$33,H$3<Initiatives!$C$33+2),(1-Initiatives!$C$32)*Initiatives!$C$44/2,0)) -> 7920 | I14: =IF(Initiatives!$C$6="adoption",IF(AND(I$3>=Initiatives!$C$31,I$3<Initiatives!$C$31+3),Initiatives!$C$44/3,0),IF(AND(I$3>=Initiatives!$C$31,I$3<Initiatives!$C$31+2),Initiatives!$C$32*Initiatives!$C$44/2,0)+IF(AND(I$3>=Initiatives!$C$33,I$3<Initiatives!$C$33+2),(1-Initiatives!$C$32)*Initiatives!$C$44/2,0)) -> 7920 | J14: =IF(Initiatives!$C$6="adoption",IF(AND(J$3>=Initiatives!$C$31,J$3<Initiatives!$C$31+3),Initiatives!$C$44/3,0),IF(AND(J$3>=Initiatives!$C$31,J$3<Initiatives!$C$31+2),Initiatives!$C$32*Initiatives!$C$44/2,0)+IF(AND(J$3>=Initiatives!$C$33,J$3<Initiatives!$C$33+2),(1-Initiatives!$C$32)*Initiatives!$C$44/2,0)) -> 0 | ... AL14: =IF(Initiatives!$C$6="adoption",IF(AND(AL$3>=Initiatives!$C$31,AL$3<Initiatives!$C$31+3),Initiatives!$C$44/3,0),IF(AND(AL$3>=Initiatives!$C$31,AL$3<Initiatives!$C$31+2),Initiatives!$C$32*Initiatives!$C$44/2,0)+IF(AND(AL$3>=Initiatives!$C$33,AL$3<Initiatives!$C$33+2),(1-Initiatives!$C$32)*Initiatives!$C$44/2,0)) -> 0
A15: Потерянные | B15: L | C15: =N(B15)*(1-Inputs!$C$9)+C14 -> 0 | D15: =N(C15)*(1-Inputs!$C$9)+D14 -> 0 | E15: =N(D15)*(1-Inputs!$C$9)+E14 -> 0 | F15: =N(E15)*(1-Inputs!$C$9)+F14 -> 0 | G15: =N(F15)*(1-Inputs!$C$9)+G14 -> 0 | H15: =N(G15)*(1-Inputs!$C$9)+H14 -> 7920 | I15: =N(H15)*(1-Inputs!$C$9)+I14 -> 15721.2 | J15: =N(I15)*(1-Inputs!$C$9)+J14 -> 15485.382 | ... AL15: =N(AK15)*(1-Inputs!$C$9)+AL14 -> 20755.042
A16: Инкр. выручка | B16: rev | C16: =IF(Initiatives!$C$6="adoption",C12*Initiatives!$C$23+C11*Initiatives!$C$8-C15*Initiatives!$C$8,(Initiatives!$C$42*Initiatives!$C$41+Initiatives!$C$38*Initiatives!$C$13*Initiatives!$C$14+Initiatives!$C$43*Initiatives!$C$16)*C13-C15*Initiatives!$C$8) -> 0 | D16: =IF(Initiatives!$C$6="adoption",D12*Initiatives!$C$23+D11*Initiatives!$C$8-D15*Initiatives!$C$8,(Initiatives!$C$42*Initiatives!$C$41+Initiatives!$C$38*Initiatives!$C$13*Initiatives!$C$14+Initiatives!$C$43*Initiatives!$C$16)*D13-D15*Initiatives!$C$8) -> 0 | E16: =IF(Initiatives!$C$6="adoption",E12*Initiatives!$C$23+E11*Initiatives!$C$8-E15*Initiatives!$C$8,(Initiatives!$C$42*Initiatives!$C$41+Initiatives!$C$38*Initiatives!$C$13*Initiatives!$C$14+Initiatives!$C$43*Initiatives!$C$16)*E13-E15*Initiatives!$C$8) -> 0 | F16: =IF(Initiatives!$C$6="adoption",F12*Initiatives!$C$23+F11*Initiatives!$C$8-F15*Initiatives!$C$8,(Initiatives!$C$42*Initiatives!$C$41+Initiatives!$C$38*Initiatives!$C$13*Initiatives!$C$14+Initiatives!$C$43*Initiatives!$C$16)*F13-F15*Initiatives!$C$8) -> 0 | G16: =IF(Initiatives!$C$6="adoption",G12*Initiatives!$C$23+G11*Initiatives!$C$8-G15*Initiatives!$C$8,(Initiatives!$C$42*Initiatives!$C$41+Initiatives!$C$38*Initiatives!$C$13*Initiatives!$C$14+Initiatives!$C$43*Initiatives!$C$16)*G13-G15*Initiatives!$C$8) -> 0 | H16: =IF(Initiatives!$C$6="adoption",H12*Initiatives!$C$23+H11*Initiatives!$C$8-H15*Initiatives!$C$8,(Initiatives!$C$42*Initiatives!$C$41+Initiatives!$C$38*Initiatives!$C$13*Initiatives!$C$14+Initiatives!$C$43*Initiatives!$C$16)*H13-H15*Initiatives!$C$8) -> 1.4713286e+09 | I16: =IF(Initiatives!$C$6="adoption",I12*Initiatives!$C$23+I11*Initiatives!$C$8-I15*Initiatives!$C$8,(Initiatives!$C$42*Initiatives!$C$41+Initiatives!$C$38*Initiatives!$C$13*Initiatives!$C$14+Initiatives!$C$43*Initiatives!$C$16)*I13-I15*Initiatives!$C$8) -> 1.3225386e+09 | J16: =IF(Initiatives!$C$6="adoption",J12*Initiatives!$C$23+J11*Initiatives!$C$8-J15*Initiatives!$C$8,(Initiatives!$C$42*Initiatives!$C$41+Initiatives!$C$38*Initiatives!$C$13*Initiatives!$C$14+Initiatives!$C$43*Initiatives!$C$16)*J13-J15*Initiatives!$C$8) -> 1.3027006e+09 | ... AL16: =IF(Initiatives!$C$6="adoption",AL12*Initiatives!$C$23+AL11*Initiatives!$C$8-AL15*Initiatives!$C$8,(Initiatives!$C$42*Initiatives!$C$41+Initiatives!$C$38*Initiatives!$C$13*Initiatives!$C$14+Initiatives!$C$43*Initiatives!$C$16)*AL13-AL15*Initiatives!$C$8) -> 1.7460083e+09
A17: Затраты | B17: cost | C17: =IF(C$3<=Initiatives!$C$45,Initiatives!$C$28/Initiatives!$C$45,0)+IF(Initiatives!$C$6="adoption",C10*Initiatives!$C$26+C12*Initiatives!$C$27+IF(C$3=Initiatives!$C$31,Initiatives!$C$39*Initiatives!$C$25,0)+IF(C$3>=Initiatives!$C$31,Initiatives!$C$29,0),Initiatives!$C$42*Initiatives!$C$18*C13+IF(C$3=Initiatives!$C$31,Initiatives!$C$32*Initiatives!$C$38*Initiatives!$C$25,0)+IF(C$3=Initiatives!$C$33,(1-Initiatives!$C$32)*Initiatives!$C$38*Initiatives!$C$25,0)+IF(C$3>=Initiatives!$C$31,Initiatives!$C$29-Initiatives!$C$19*(Initiatives!$C$32+IF(C$3>=Initiatives!$C$33,1-Initiatives!$C$32,0)),0)) -> 1000000000 | D17: =IF(D$3<=Initiatives!$C$45,Initiatives!$C$28/Initiatives!$C$45,0)+IF(Initiatives!$C$6="adoption",D10*Initiatives!$C$26+D12*Initiatives!$C$27+IF(D$3=Initiatives!$C$31,Initiatives!$C$39*Initiatives!$C$25,0)+IF(D$3>=Initiatives!$C$31,Initiatives!$C$29,0),Initiatives!$C$42*Initiatives!$C$18*D13+IF(D$3=Initiatives!$C$31,Initiatives!$C$32*Initiatives!$C$38*Initiatives!$C$25,0)+IF(D$3=Initiatives!$C$33,(1-Initiatives!$C$32)*Initiatives!$C$38*Initiatives!$C$25,0)+IF(D$3>=Initiatives!$C$31,Initiatives!$C$29-Initiatives!$C$19*(Initiatives!$C$32+IF(D$3>=Initiatives!$C$33,1-Initiatives!$C$32,0)),0)) -> 1000000000 | E17: =IF(E$3<=Initiatives!$C$45,Initiatives!$C$28/Initiatives!$C$45,0)+IF(Initiatives!$C$6="adoption",E10*Initiatives!$C$26+E12*Initiatives!$C$27+IF(E$3=Initiatives!$C$31,Initiatives!$C$39*Initiatives!$C$25,0)+IF(E$3>=Initiatives!$C$31,Initiatives!$C$29,0),Initiatives!$C$42*Initiatives!$C$18*E13+IF(E$3=Initiatives!$C$31,Initiatives!$C$32*Initiatives!$C$38*Initiatives!$C$25,0)+IF(E$3=Initiatives!$C$33,(1-Initiatives!$C$32)*Initiatives!$C$38*Initiatives!$C$25,0)+IF(E$3>=Initiatives!$C$31,Initiatives!$C$29-Initiatives!$C$19*(Initiatives!$C$32+IF(E$3>=Initiatives!$C$33,1-Initiatives!$C$32,0)),0)) -> 1000000000 | F17: =IF(F$3<=Initiatives!$C$45,Initiatives!$C$28/Initiatives!$C$45,0)+IF(Initiatives!$C$6="adoption",F10*Initiatives!$C$26+F12*Initiatives!$C$27+IF(F$3=Initiatives!$C$31,Initiatives!$C$39*Initiatives!$C$25,0)+IF(F$3>=Initiatives!$C$31,Initiatives!$C$29,0),Initiatives!$C$42*Initiatives!$C$18*F13+IF(F$3=Initiatives!$C$31,Initiatives!$C$32*Initiatives!$C$38*Initiatives!$C$25,0)+IF(F$3=Initiatives!$C$33,(1-Initiatives!$C$32)*Initiatives!$C$38*Initiatives!$C$25,0)+IF(F$3>=Initiatives!$C$31,Initiatives!$C$29-Initiatives!$C$19*(Initiatives!$C$32+IF(F$3>=Initiatives!$C$33,1-Initiatives!$C$32,0)),0)) -> 1000000000 | G17: =IF(G$3<=Initiatives!$C$45,Initiatives!$C$28/Initiatives!$C$45,0)+IF(Initiatives!$C$6="adoption",G10*Initiatives!$C$26+G12*Initiatives!$C$27+IF(G$3=Initiatives!$C$31,Initiatives!$C$39*Initiatives!$C$25,0)+IF(G$3>=Initiatives!$C$31,Initiatives!$C$29,0),Initiatives!$C$42*Initiatives!$C$18*G13+IF(G$3=Initiatives!$C$31,Initiatives!$C$32*Initiatives!$C$38*Initiatives!$C$25,0)+IF(G$3=Initiatives!$C$33,(1-Initiatives!$C$32)*Initiatives!$C$38*Initiatives!$C$25,0)+IF(G$3>=Initiatives!$C$31,Initiatives!$C$29-Initiatives!$C$19*(Initiatives!$C$32+IF(G$3>=Initiatives!$C$33,1-Initiatives!$C$32,0)),0)) -> 1000000000 | H17: =IF(H$3<=Initiatives!$C$45,Initiatives!$C$28/Initiatives!$C$45,0)+IF(Initiatives!$C$6="adoption",H10*Initiatives!$C$26+H12*Initiatives!$C$27+IF(H$3=Initiatives!$C$31,Initiatives!$C$39*Initiatives!$C$25,0)+IF(H$3>=Initiatives!$C$31,Initiatives!$C$29,0),Initiatives!$C$42*Initiatives!$C$18*H13+IF(H$3=Initiatives!$C$31,Initiatives!$C$32*Initiatives!$C$38*Initiatives!$C$25,0)+IF(H$3=Initiatives!$C$33,(1-Initiatives!$C$32)*Initiatives!$C$38*Initiatives!$C$25,0)+IF(H$3>=Initiatives!$C$31,Initiatives!$C$29-Initiatives!$C$19*(Initiatives!$C$32+IF(H$3>=Initiatives!$C$33,1-Initiatives!$C$32,0)),0)) -> 246576000 | I17: =IF(I$3<=Initiatives!$C$45,Initiatives!$C$28/Initiatives!$C$45,0)+IF(Initiatives!$C$6="adoption",I10*Initiatives!$C$26+I12*Initiatives!$C$27+IF(I$3=Initiatives!$C$31,Initiatives!$C$39*Initiatives!$C$25,0)+IF(I$3>=Initiatives!$C$31,Initiatives!$C$29,0),Initiatives!$C$42*Initiatives!$C$18*I13+IF(I$3=Initiatives!$C$31,Initiatives!$C$32*Initiatives!$C$38*Initiatives!$C$25,0)+IF(I$3=Initiatives!$C$33,(1-Initiatives!$C$32)*Initiatives!$C$38*Initiatives!$C$25,0)+IF(I$3>=Initiatives!$C$31,Initiatives!$C$29-Initiatives!$C$19*(Initiatives!$C$32+IF(I$3>=Initiatives!$C$33,1-Initiatives!$C$32,0)),0)) -> 138861360 | J17: =IF(J$3<=Initiatives!$C$45,Initiatives!$C$28/Initiatives!$C$45,0)+IF(Initiatives!$C$6="adoption",J10*Initiatives!$C$26+J12*Initiatives!$C$27+IF(J$3=Initiatives!$C$31,Initiatives!$C$39*Initiatives!$C$25,0)+IF(J$3>=Initiatives!$C$31,Initiatives!$C$29,0),Initiatives!$C$42*Initiatives!$C$18*J13+IF(J$3=Initiatives!$C$31,Initiatives!$C$32*Initiatives!$C$38*Initiatives!$C$25,0)+IF(J$3=Initiatives!$C$33,(1-Initiatives!$C$32)*Initiatives!$C$38*Initiatives!$C$25,0)+IF(J$3>=Initiatives!$C$31,Initiatives!$C$29-Initiatives!$C$19*(Initiatives!$C$32+IF(J$3>=Initiatives!$C$33,1-Initiatives!$C$32,0)),0)) -> 1.3677844e+08 | ... AL17: =IF(AL$3<=Initiatives!$C$45,Initiatives!$C$28/Initiatives!$C$45,0)+IF(Initiatives!$C$6="adoption",AL10*Initiatives!$C$26+AL12*Initiatives!$C$27+IF(AL$3=Initiatives!$C$31,Initiatives!$C$39*Initiatives!$C$25,0)+IF(AL$3>=Initiatives!$C$31,Initiatives!$C$29,0),Initiatives!$C$42*Initiatives!$C$18*AL13+IF(AL$3=Initiatives!$C$31,Initiatives!$C$32*Initiatives!$C$38*Initiatives!$C$25,0)+IF(AL$3=Initiatives!$C$33,(1-Initiatives!$C$32)*Initiatives!$C$38*Initiatives!$C$25,0)+IF(AL$3>=Initiatives!$C$31,Initiatives!$C$29-Initiatives!$C$19*(Initiatives!$C$32+IF(AL$3>=Initiatives!$C$33,1-Initiatives!$C$32,0)),0)) -> 1.5332401e+08
A18: Вклад | B18: contrib | C18: =C16*Initiatives!$C$30-C17 -> -1000000000 | D18: =D16*Initiatives!$C$30-D17 -> -1000000000 | E18: =E16*Initiatives!$C$30-E17 -> -1000000000 | F18: =F16*Initiatives!$C$30-F17 -> -1000000000 | G18: =G16*Initiatives!$C$30-G17 -> -1000000000 | H18: =H16*Initiatives!$C$30-H17 -> 1.2247526e+09 | I18: =I16*Initiatives!$C$30-I17 -> 1.1836773e+09 | J18: =J16*Initiatives!$C$30-J17 -> 1.1659221e+09 | ... AL18: =AL16*Initiatives!$C$30-AL17 -> 1.5926843e+09
A19: Δ абонентов | B19: dsubs | C19: =C11-C15 -> 0 | D19: =D11-D15 -> 0 | E19: =E11-E15 -> 0 | F19: =F11-F15 -> 0 | G19: =G11-G15 -> 0 | H19: =H11-H15 -> -7920 | I19: =I11-I15 -> -15721.2 | J19: =J11-J15 -> -15485.382 | ... AL19: =AL11-AL15 -> -20755.042
A21: I2 — More-for-More: + абонплата и + трафик для когорты недооценённых линеек
A22: Доля набора | B22: f | C22: =IF(Initiatives!$D$6="adoption",IF(C$3<Initiatives!$D$31,0,MIN((C$3-Initiatives!$D$31+1)/Initiatives!$D$34,1)),0) -> 0 | D22: =IF(Initiatives!$D$6="adoption",IF(D$3<Initiatives!$D$31,0,MIN((D$3-Initiatives!$D$31+1)/Initiatives!$D$34,1)),0) -> 0 | E22: =IF(Initiatives!$D$6="adoption",IF(E$3<Initiatives!$D$31,0,MIN((E$3-Initiatives!$D$31+1)/Initiatives!$D$34,1)),0) -> 0 | F22: =IF(Initiatives!$D$6="adoption",IF(F$3<Initiatives!$D$31,0,MIN((F$3-Initiatives!$D$31+1)/Initiatives!$D$34,1)),0) -> 0 | G22: =IF(Initiatives!$D$6="adoption",IF(G$3<Initiatives!$D$31,0,MIN((G$3-Initiatives!$D$31+1)/Initiatives!$D$34,1)),0) -> 0 | H22: =IF(Initiatives!$D$6="adoption",IF(H$3<Initiatives!$D$31,0,MIN((H$3-Initiatives!$D$31+1)/Initiatives!$D$34,1)),0) -> 0 | I22: =IF(Initiatives!$D$6="adoption",IF(I$3<Initiatives!$D$31,0,MIN((I$3-Initiatives!$D$31+1)/Initiatives!$D$34,1)),0) -> 0 | J22: =IF(Initiatives!$D$6="adoption",IF(J$3<Initiatives!$D$31,0,MIN((J$3-Initiatives!$D$31+1)/Initiatives!$D$34,1)),0) -> 0 | ... AL22: =IF(Initiatives!$D$6="adoption",IF(AL$3<Initiatives!$D$31,0,MIN((AL$3-Initiatives!$D$31+1)/Initiatives!$D$34,1)),0) -> 0
A23: Адоптеры (цель) | B23: target | C23: =Initiatives!$D$40*C22 -> 0 | D23: =Initiatives!$D$40*D22 -> 0 | E23: =Initiatives!$D$40*E22 -> 0 | F23: =Initiatives!$D$40*F22 -> 0 | G23: =Initiatives!$D$40*G22 -> 0 | H23: =Initiatives!$D$40*H22 -> 0 | I23: =Initiatives!$D$40*I22 -> 0 | J23: =Initiatives!$D$40*J22 -> 0 | ... AL23: =Initiatives!$D$40*AL22 -> 0
A24: Новые адоптеры | B24: new | C24: =MAX(C23-N(B23),0) -> 0 | D24: =MAX(D23-N(C23),0) -> 0 | E24: =MAX(E23-N(D23),0) -> 0 | F24: =MAX(F23-N(E23),0) -> 0 | G24: =MAX(G23-N(F23),0) -> 0 | H24: =MAX(H23-N(G23),0) -> 0 | I24: =MAX(I23-N(H23),0) -> 0 | J24: =MAX(J23-N(I23),0) -> 0 | ... AL24: =MAX(AL23-N(AK23),0) -> 0
A25: Удержанные | B25: R | C25: =IF(Initiatives!$D$6="adoption",N(B25)*(1-Inputs!$C$9)+N(B26)*Inputs!$C$9*Initiatives!$D$24,0) -> 0 | D25: =IF(Initiatives!$D$6="adoption",N(C25)*(1-Inputs!$C$9)+N(C26)*Inputs!$C$9*Initiatives!$D$24,0) -> 0 | E25: =IF(Initiatives!$D$6="adoption",N(D25)*(1-Inputs!$C$9)+N(D26)*Inputs!$C$9*Initiatives!$D$24,0) -> 0 | F25: =IF(Initiatives!$D$6="adoption",N(E25)*(1-Inputs!$C$9)+N(E26)*Inputs!$C$9*Initiatives!$D$24,0) -> 0 | G25: =IF(Initiatives!$D$6="adoption",N(F25)*(1-Inputs!$C$9)+N(F26)*Inputs!$C$9*Initiatives!$D$24,0) -> 0 | H25: =IF(Initiatives!$D$6="adoption",N(G25)*(1-Inputs!$C$9)+N(G26)*Inputs!$C$9*Initiatives!$D$24,0) -> 0 | I25: =IF(Initiatives!$D$6="adoption",N(H25)*(1-Inputs!$C$9)+N(H26)*Inputs!$C$9*Initiatives!$D$24,0) -> 0 | J25: =IF(Initiatives!$D$6="adoption",N(I25)*(1-Inputs!$C$9)+N(I26)*Inputs!$C$9*Initiatives!$D$24,0) -> 0 | ... AL25: =IF(Initiatives!$D$6="adoption",N(AK25)*(1-Inputs!$C$9)+N(AK26)*Inputs!$C$9*Initiatives!$D$24,0) -> 0
A26: Пул адоптеров | B26: pool | C26: =N(B26)*(1-Inputs!$C$9*(1-Initiatives!$D$24))+C24 -> 0 | D26: =N(C26)*(1-Inputs!$C$9*(1-Initiatives!$D$24))+D24 -> 0 | E26: =N(D26)*(1-Inputs!$C$9*(1-Initiatives!$D$24))+E24 -> 0 | F26: =N(E26)*(1-Inputs!$C$9*(1-Initiatives!$D$24))+F24 -> 0 | G26: =N(F26)*(1-Inputs!$C$9*(1-Initiatives!$D$24))+G24 -> 0 | H26: =N(G26)*(1-Inputs!$C$9*(1-Initiatives!$D$24))+H24 -> 0 | I26: =N(H26)*(1-Inputs!$C$9*(1-Initiatives!$D$24))+I24 -> 0 | J26: =N(I26)*(1-Inputs!$C$9*(1-Initiatives!$D$24))+J24 -> 0 | ... AL26: =N(AK26)*(1-Inputs!$C$9*(1-Initiatives!$D$24))+AL24 -> 0
A27: Вес волн × затухание | B27: w | C27: =IF(Initiatives!$D$6="adoption",0,IF(C$3>=Initiatives!$D$31,Initiatives!$D$32*(1-Inputs!$C$9)^(C$3-Initiatives!$D$31),0)+IF(C$3>=Initiatives!$D$33,(1-Initiatives!$D$32)*(1-Inputs!$C$9)^(C$3-Initiatives!$D$33),0)) -> 0 | D27: =IF(Initiatives!$D$6="adoption",0,IF(D$3>=Initiatives!$D$31,Initiatives!$D$32*(1-Inputs!$C$9)^(D$3-Initiatives!$D$31),0)+IF(D$3>=Initiatives!$D$33,(1-Initiatives!$D$32)*(1-Inputs!$C$9)^(D$3-Initiatives!$D$33),0)) -> 0.1 | E27: =IF(Initiatives!$D$6="adoption",0,IF(E$3>=Initiatives!$D$31,Initiatives!$D$32*(1-Inputs!$C$9)^(E$3-Initiatives!$D$31),0)+IF(E$3>=Initiatives!$D$33,(1-Initiatives!$D$32)*(1-Inputs!$C$9)^(E$3-Initiatives!$D$33),0)) -> 0.0985 | F27: =IF(Initiatives!$D$6="adoption",0,IF(F$3>=Initiatives!$D$31,Initiatives!$D$32*(1-Inputs!$C$9)^(F$3-Initiatives!$D$31),0)+IF(F$3>=Initiatives!$D$33,(1-Initiatives!$D$32)*(1-Inputs!$C$9)^(F$3-Initiatives!$D$33),0)) -> 0.9970225 | G27: =IF(Initiatives!$D$6="adoption",0,IF(G$3>=Initiatives!$D$31,Initiatives!$D$32*(1-Inputs!$C$9)^(G$3-Initiatives!$D$31),0)+IF(G$3>=Initiatives!$D$33,(1-Initiatives!$D$32)*(1-Inputs!$C$9)^(G$3-Initiatives!$D$33),0)) -> 0.98206716 | H27: =IF(Initiatives!$D$6="adoption",0,IF(H$3>=Initiatives!$D$31,Initiatives!$D$32*(1-Inputs!$C$9)^(H$3-Initiatives!$D$31),0)+IF(H$3>=Initiatives!$D$33,(1-Initiatives!$D$32)*(1-Inputs!$C$9)^(H$3-Initiatives!$D$33),0)) -> 0.96733616 | I27: =IF(Initiatives!$D$6="adoption",0,IF(I$3>=Initiatives!$D$31,Initiatives!$D$32*(1-Inputs!$C$9)^(I$3-Initiatives!$D$31),0)+IF(I$3>=Initiatives!$D$33,(1-Initiatives!$D$32)*(1-Inputs!$C$9)^(I$3-Initiatives!$D$33),0)) -> 0.95282611 | J27: =IF(Initiatives!$D$6="adoption",0,IF(J$3>=Initiatives!$D$31,Initiatives!$D$32*(1-Inputs!$C$9)^(J$3-Initiatives!$D$31),0)+IF(J$3>=Initiatives!$D$33,(1-Initiatives!$D$32)*(1-Inputs!$C$9)^(J$3-Initiatives!$D$33),0)) -> 0.93853372 | ... AL27: =IF(Initiatives!$D$6="adoption",0,IF(AL$3>=Initiatives!$D$31,Initiatives!$D$32*(1-Inputs!$C$9)^(AL$3-Initiatives!$D$31),0)+IF(AL$3>=Initiatives!$D$33,(1-Initiatives!$D$32)*(1-Inputs!$C$9)^(AL$3-Initiatives!$D$33),0)) -> 0.61470159
A28: Новый доп. отток | B28: newlost | C28: =IF(Initiatives!$D$6="adoption",IF(AND(C$3>=Initiatives!$D$31,C$3<Initiatives!$D$31+3),Initiatives!$D$44/3,0),IF(AND(C$3>=Initiatives!$D$31,C$3<Initiatives!$D$31+2),Initiatives!$D$32*Initiatives!$D$44/2,0)+IF(AND(C$3>=Initiatives!$D$33,C$3<Initiatives!$D$33+2),(1-Initiatives!$D$32)*Initiatives!$D$44/2,0)) -> 0 | D28: =IF(Initiatives!$D$6="adoption",IF(AND(D$3>=Initiatives!$D$31,D$3<Initiatives!$D$31+3),Initiatives!$D$44/3,0),IF(AND(D$3>=Initiatives!$D$31,D$3<Initiatives!$D$31+2),Initiatives!$D$32*Initiatives!$D$44/2,0)+IF(AND(D$3>=Initiatives!$D$33,D$3<Initiatives!$D$33+2),(1-Initiatives!$D$32)*Initiatives!$D$44/2,0)) -> 968 | E28: =IF(Initiatives!$D$6="adoption",IF(AND(E$3>=Initiatives!$D$31,E$3<Initiatives!$D$31+3),Initiatives!$D$44/3,0),IF(AND(E$3>=Initiatives!$D$31,E$3<Initiatives!$D$31+2),Initiatives!$D$32*Initiatives!$D$44/2,0)+IF(AND(E$3>=Initiatives!$D$33,E$3<Initiatives!$D$33+2),(1-Initiatives!$D$32)*Initiatives!$D$44/2,0)) -> 968 | F28: =IF(Initiatives!$D$6="adoption",IF(AND(F$3>=Initiatives!$D$31,F$3<Initiatives!$D$31+3),Initiatives!$D$44/3,0),IF(AND(F$3>=Initiatives!$D$31,F$3<Initiatives!$D$31+2),Initiatives!$D$32*Initiatives!$D$44/2,0)+IF(AND(F$3>=Initiatives!$D$33,F$3<Initiatives!$D$33+2),(1-Initiatives!$D$32)*Initiatives!$D$44/2,0)) -> 8712 | G28: =IF(Initiatives!$D$6="adoption",IF(AND(G$3>=Initiatives!$D$31,G$3<Initiatives!$D$31+3),Initiatives!$D$44/3,0),IF(AND(G$3>=Initiatives!$D$31,G$3<Initiatives!$D$31+2),Initiatives!$D$32*Initiatives!$D$44/2,0)+IF(AND(G$3>=Initiatives!$D$33,G$3<Initiatives!$D$33+2),(1-Initiatives!$D$32)*Initiatives!$D$44/2,0)) -> 8712 | H28: =IF(Initiatives!$D$6="adoption",IF(AND(H$3>=Initiatives!$D$31,H$3<Initiatives!$D$31+3),Initiatives!$D$44/3,0),IF(AND(H$3>=Initiatives!$D$31,H$3<Initiatives!$D$31+2),Initiatives!$D$32*Initiatives!$D$44/2,0)+IF(AND(H$3>=Initiatives!$D$33,H$3<Initiatives!$D$33+2),(1-Initiatives!$D$32)*Initiatives!$D$44/2,0)) -> 0 | I28: =IF(Initiatives!$D$6="adoption",IF(AND(I$3>=Initiatives!$D$31,I$3<Initiatives!$D$31+3),Initiatives!$D$44/3,0),IF(AND(I$3>=Initiatives!$D$31,I$3<Initiatives!$D$31+2),Initiatives!$D$32*Initiatives!$D$44/2,0)+IF(AND(I$3>=Initiatives!$D$33,I$3<Initiatives!$D$33+2),(1-Initiatives!$D$32)*Initiatives!$D$44/2,0)) -> 0 | J28: =IF(Initiatives!$D$6="adoption",IF(AND(J$3>=Initiatives!$D$31,J$3<Initiatives!$D$31+3),Initiatives!$D$44/3,0),IF(AND(J$3>=Initiatives!$D$31,J$3<Initiatives!$D$31+2),Initiatives!$D$32*Initiatives!$D$44/2,0)+IF(AND(J$3>=Initiatives!$D$33,J$3<Initiatives!$D$33+2),(1-Initiatives!$D$32)*Initiatives!$D$44/2,0)) -> 0 | ... AL28: =IF(Initiatives!$D$6="adoption",IF(AND(AL$3>=Initiatives!$D$31,AL$3<Initiatives!$D$31+3),Initiatives!$D$44/3,0),IF(AND(AL$3>=Initiatives!$D$31,AL$3<Initiatives!$D$31+2),Initiatives!$D$32*Initiatives!$D$44/2,0)+IF(AND(AL$3>=Initiatives!$D$33,AL$3<Initiatives!$D$33+2),(1-Initiatives!$D$32)*Initiatives!$D$44/2,0)) -> 0
A29: Потерянные | B29: L | C29: =N(B29)*(1-Inputs!$C$9)+C28 -> 0 | D29: =N(C29)*(1-Inputs!$C$9)+D28 -> 968 | E29: =N(D29)*(1-Inputs!$C$9)+E28 -> 1921.48 | F29: =N(E29)*(1-Inputs!$C$9)+F28 -> 10604.658 | G29: =N(F29)*(1-Inputs!$C$9)+G28 -> 19157.588 | H29: =N(G29)*(1-Inputs!$C$9)+H28 -> 18870.224 | I29: =N(H29)*(1-Inputs!$C$9)+I28 -> 18587.171 | J29: =N(I29)*(1-Inputs!$C$9)+J28 -> 18308.363 | ... AL29: =N(AK29)*(1-Inputs!$C$9)+AL28 -> 11991.237
A30: Инкр. выручка | B30: rev | C30: =IF(Initiatives!$D$6="adoption",C26*Initiatives!$D$23+C25*Initiatives!$D$8-C29*Initiatives!$D$8,(Initiatives!$D$42*Initiatives!$D$41+Initiatives!$D$38*Initiatives!$D$13*Initiatives!$D$14+Initiatives!$D$43*Initiatives!$D$16)*C27-C29*Initiatives!$D$8) -> 0 | D30: =IF(Initiatives!$D$6="adoption",D26*Initiatives!$D$23+D25*Initiatives!$D$8-D29*Initiatives!$D$8,(Initiatives!$D$42*Initiatives!$D$41+Initiatives!$D$38*Initiatives!$D$13*Initiatives!$D$14+Initiatives!$D$43*Initiatives!$D$16)*D27-D29*Initiatives!$D$8) -> 2.7050069e+08 | E30: =IF(Initiatives!$D$6="adoption",E26*Initiatives!$D$23+E25*Initiatives!$D$8-E29*Initiatives!$D$8,(Initiatives!$D$42*Initiatives!$D$41+Initiatives!$D$38*Initiatives!$D$13*Initiatives!$D$14+Initiatives!$D$43*Initiatives!$D$16)*E27-E29*Initiatives!$D$8) -> 2.4611518e+08 | F30: =IF(Initiatives!$D$6="adoption",F26*Initiatives!$D$23+F25*Initiatives!$D$8-F29*Initiatives!$D$8,(Initiatives!$D$42*Initiatives!$D$41+Initiatives!$D$38*Initiatives!$D$13*Initiatives!$D$14+Initiatives!$D$43*Initiatives!$D$16)*F27-F29*Initiatives!$D$8) -> 2.6769296e+09 | G30: =IF(Initiatives!$D$6="adoption",G26*Initiatives!$D$23+G25*Initiatives!$D$8-G29*Initiatives!$D$8,(Initiatives!$D$42*Initiatives!$D$41+Initiatives!$D$38*Initiatives!$D$13*Initiatives!$D$14+Initiatives!$D$43*Initiatives!$D$16)*G27-G29*Initiatives!$D$8) -> 2.4538237e+09 | H30: =IF(Initiatives!$D$6="adoption",H26*Initiatives!$D$23+H25*Initiatives!$D$8-H29*Initiatives!$D$8,(Initiatives!$D$42*Initiatives!$D$41+Initiatives!$D$38*Initiatives!$D$13*Initiatives!$D$14+Initiatives!$D$43*Initiatives!$D$16)*H27-H29*Initiatives!$D$8) -> 2.4170163e+09 | I30: =IF(Initiatives!$D$6="adoption",I26*Initiatives!$D$23+I25*Initiatives!$D$8-I29*Initiatives!$D$8,(Initiatives!$D$42*Initiatives!$D$41+Initiatives!$D$38*Initiatives!$D$13*Initiatives!$D$14+Initiatives!$D$43*Initiatives!$D$16)*I27-I29*Initiatives!$D$8) -> 2.3807611e+09 | J30: =IF(Initiatives!$D$6="adoption",J26*Initiatives!$D$23+J25*Initiatives!$D$8-J29*Initiatives!$D$8,(Initiatives!$D$42*Initiatives!$D$41+Initiatives!$D$38*Initiatives!$D$13*Initiatives!$D$14+Initiatives!$D$43*Initiatives!$D$16)*J27-J29*Initiatives!$D$8) -> 2.3450497e+09 | ... AL30: =IF(Initiatives!$D$6="adoption",AL26*Initiatives!$D$23+AL25*Initiatives!$D$8-AL29*Initiatives!$D$8,(Initiatives!$D$42*Initiatives!$D$41+Initiatives!$D$38*Initiatives!$D$13*Initiatives!$D$14+Initiatives!$D$43*Initiatives!$D$16)*AL27-AL29*Initiatives!$D$8) -> 1.5359126e+09
A31: Затраты | B31: cost | C31: =IF(C$3<=Initiatives!$D$45,Initiatives!$D$28/Initiatives!$D$45,0)+IF(Initiatives!$D$6="adoption",C24*Initiatives!$D$26+C26*Initiatives!$D$27+IF(C$3=Initiatives!$D$31,Initiatives!$D$39*Initiatives!$D$25,0)+IF(C$3>=Initiatives!$D$31,Initiatives!$D$29,0),Initiatives!$D$42*Initiatives!$D$18*C27+IF(C$3=Initiatives!$D$31,Initiatives!$D$32*Initiatives!$D$38*Initiatives!$D$25,0)+IF(C$3=Initiatives!$D$33,(1-Initiatives!$D$32)*Initiatives!$D$38*Initiatives!$D$25,0)+IF(C$3>=Initiatives!$D$31,Initiatives!$D$29-Initiatives!$D$19*(Initiatives!$D$32+IF(C$3>=Initiatives!$D$33,1-Initiatives!$D$32,0)),0)) -> 300000000 | D31: =IF(D$3<=Initiatives!$D$45,Initiatives!$D$28/Initiatives!$D$45,0)+IF(Initiatives!$D$6="adoption",D24*Initiatives!$D$26+D26*Initiatives!$D$27+IF(D$3=Initiatives!$D$31,Initiatives!$D$39*Initiatives!$D$25,0)+IF(D$3>=Initiatives!$D$31,Initiatives!$D$29,0),Initiatives!$D$42*Initiatives!$D$18*D27+IF(D$3=Initiatives!$D$31,Initiatives!$D$32*Initiatives!$D$38*Initiatives!$D$25,0)+IF(D$3=Initiatives!$D$33,(1-Initiatives!$D$32)*Initiatives!$D$38*Initiatives!$D$25,0)+IF(D$3>=Initiatives!$D$31,Initiatives!$D$29-Initiatives!$D$19*(Initiatives!$D$32+IF(D$3>=Initiatives!$D$33,1-Initiatives!$D$32,0)),0)) -> 55467520 | E31: =IF(E$3<=Initiatives!$D$45,Initiatives!$D$28/Initiatives!$D$45,0)+IF(Initiatives!$D$6="adoption",E24*Initiatives!$D$26+E26*Initiatives!$D$27+IF(E$3=Initiatives!$D$31,Initiatives!$D$39*Initiatives!$D$25,0)+IF(E$3>=Initiatives!$D$31,Initiatives!$D$29,0),Initiatives!$D$42*Initiatives!$D$18*E27+IF(E$3=Initiatives!$D$31,Initiatives!$D$32*Initiatives!$D$38*Initiatives!$D$25,0)+IF(E$3=Initiatives!$D$33,(1-Initiatives!$D$32)*Initiatives!$D$38*Initiatives!$D$25,0)+IF(E$3>=Initiatives!$D$31,Initiatives!$D$29-Initiatives!$D$19*(Initiatives!$D$32+IF(E$3>=Initiatives!$D$33,1-Initiatives!$D$32,0)),0)) -> 47307667 | F31: =IF(F$3<=Initiatives!$D$45,Initiatives!$D$28/Initiatives!$D$45,0)+IF(Initiatives!$D$6="adoption",F24*Initiatives!$D$26+F26*Initiatives!$D$27+IF(F$3=Initiatives!$D$31,Initiatives!$D$39*Initiatives!$D$25,0)+IF(F$3>=Initiatives!$D$31,Initiatives!$D$29,0),Initiatives!$D$42*Initiatives!$D$18*F27+IF(F$3=Initiatives!$D$31,Initiatives!$D$32*Initiatives!$D$38*Initiatives!$D$25,0)+IF(F$3=Initiatives!$D$33,(1-Initiatives!$D$32)*Initiatives!$D$38*Initiatives!$D$25,0)+IF(F$3>=Initiatives!$D$31,Initiatives!$D$29-Initiatives!$D$19*(Initiatives!$D$32+IF(F$3>=Initiatives!$D$33,1-Initiatives!$D$32,0)),0)) -> 3.6610573e+08 | G31: =IF(G$3<=Initiatives!$D$45,Initiatives!$D$28/Initiatives!$D$45,0)+IF(Initiatives!$D$6="adoption",G24*Initiatives!$D$26+G26*Initiatives!$D$27+IF(G$3=Initiatives!$D$31,Initiatives!$D$39*Initiatives!$D$25,0)+IF(G$3>=Initiatives!$D$31,Initiatives!$D$29,0),Initiatives!$D$42*Initiatives!$D$18*G27+IF(G$3=Initiatives!$D$31,Initiatives!$D$32*Initiatives!$D$38*Initiatives!$D$25,0)+IF(G$3=Initiatives!$D$33,(1-Initiatives!$D$32)*Initiatives!$D$38*Initiatives!$D$25,0)+IF(G$3>=Initiatives!$D$31,Initiatives!$D$29-Initiatives!$D$19*(Initiatives!$D$32+IF(G$3>=Initiatives!$D$33,1-Initiatives!$D$32,0)),0)) -> 2.9226359e+08 | H31: =IF(H$3<=Initiatives!$D$45,Initiatives!$D$28/Initiatives!$D$45,0)+IF(Initiatives!$D$6="adoption",H24*Initiatives!$D$26+H26*Initiatives!$D$27+IF(H$3=Initiatives!$D$31,Initiatives!$D$39*Initiatives!$D$25,0)+IF(H$3>=Initiatives!$D$31,Initiatives!$D$29,0),Initiatives!$D$42*Initiatives!$D$18*H27+IF(H$3=Initiatives!$D$31,Initiatives!$D$32*Initiatives!$D$38*Initiatives!$D$25,0)+IF(H$3=Initiatives!$D$33,(1-Initiatives!$D$32)*Initiatives!$D$38*Initiatives!$D$25,0)+IF(H$3>=Initiatives!$D$31,Initiatives!$D$29-Initiatives!$D$19*(Initiatives!$D$32+IF(H$3>=Initiatives!$D$33,1-Initiatives!$D$32,0)),0)) -> 2.8817963e+08 | I31: =IF(I$3<=Initiatives!$D$45,Initiatives!$D$28/Initiatives!$D$45,0)+IF(Initiatives!$D$6="adoption",I24*Initiatives!$D$26+I26*Initiatives!$D$27+IF(I$3=Initiatives!$D$31,Initiatives!$D$39*Initiatives!$D$25,0)+IF(I$3>=Initiatives!$D$31,Initiatives!$D$29,0),Initiatives!$D$42*Initiatives!$D$18*I27+IF(I$3=Initiatives!$D$31,Initiatives!$D$32*Initiatives!$D$38*Initiatives!$D$25,0)+IF(I$3=Initiatives!$D$33,(1-Initiatives!$D$32)*Initiatives!$D$38*Initiatives!$D$25,0)+IF(I$3>=Initiatives!$D$31,Initiatives!$D$29-Initiatives!$D$19*(Initiatives!$D$32+IF(I$3>=Initiatives!$D$33,1-Initiatives!$D$32,0)),0)) -> 2.8415694e+08 | J31: =IF(J$3<=Initiatives!$D$45,Initiatives!$D$28/Initiatives!$D$45,0)+IF(Initiatives!$D$6="adoption",J24*Initiatives!$D$26+J26*Initiatives!$D$27+IF(J$3=Initiatives!$D$31,Initiatives!$D$39*Initiatives!$D$25,0)+IF(J$3>=Initiatives!$D$31,Initiatives!$D$29,0),Initiatives!$D$42*Initiatives!$D$18*J27+IF(J$3=Initiatives!$D$31,Initiatives!$D$32*Initiatives!$D$38*Initiatives!$D$25,0)+IF(J$3=Initiatives!$D$33,(1-Initiatives!$D$32)*Initiatives!$D$38*Initiatives!$D$25,0)+IF(J$3>=Initiatives!$D$31,Initiatives!$D$29-Initiatives!$D$19*(Initiatives!$D$32+IF(J$3>=Initiatives!$D$33,1-Initiatives!$D$32,0)),0)) -> 2.8019458e+08 | ... AL31: =IF(AL$3<=Initiatives!$D$45,Initiatives!$D$28/Initiatives!$D$45,0)+IF(Initiatives!$D$6="adoption",AL24*Initiatives!$D$26+AL26*Initiatives!$D$27+IF(AL$3=Initiatives!$D$31,Initiatives!$D$39*Initiatives!$D$25,0)+IF(AL$3>=Initiatives!$D$31,Initiatives!$D$29,0),Initiatives!$D$42*Initiatives!$D$18*AL27+IF(AL$3=Initiatives!$D$31,Initiatives!$D$32*Initiatives!$D$38*Initiatives!$D$25,0)+IF(AL$3=Initiatives!$D$33,(1-Initiatives!$D$32)*Initiatives!$D$38*Initiatives!$D$25,0)+IF(AL$3>=Initiatives!$D$31,Initiatives!$D$29-Initiatives!$D$19*(Initiatives!$D$32+IF(AL$3>=Initiatives!$D$33,1-Initiatives!$D$32,0)),0)) -> 1.9041692e+08
A32: Вклад | B32: contrib | C32: =C30*Initiatives!$D$30-C31 -> -300000000 | D32: =D30*Initiatives!$D$30-D31 -> 2.1503317e+08 | E32: =E30*Initiatives!$D$30-E31 -> 1.9880751e+08 | F32: =F30*Initiatives!$D$30-F31 -> 2.3108239e+09 | G32: =G30*Initiatives!$D$30-G31 -> 2.1615601e+09 | H32: =H30*Initiatives!$D$30-H31 -> 2.1288367e+09 | I32: =I30*Initiatives!$D$30-I31 -> 2.0966041e+09 | J32: =J30*Initiatives!$D$30-J31 -> 2.0648551e+09 | ... AL32: =AL30*Initiatives!$D$30-AL31 -> 1.3454957e+09
A33: Δ абонентов | B33: dsubs | C33: =C25-C29 -> 0 | D33: =D25-D29 -> -968 | E33: =E25-E29 -> -1921.48 | F33: =F25-F29 -> -10604.658 | G33: =G25-G29 -> -19157.588 | H33: =H25-H29 -> -18870.224 | I33: =I25-I29 -> -18587.171 | J33: =J25-J29 -> -18308.363 | ... AL33: =AL25-AL29 -> -11991.237
A35: I3a — Пакет-бустер для исчерпывающих трафик (opt-in автопродление)
A36: Доля набора | B36: f | C36: =IF(Initiatives!$E$6="adoption",IF(C$3<Initiatives!$E$31,0,MIN((C$3-Initiatives!$E$31+1)/Initiatives!$E$34,1)),0) -> 0 | D36: =IF(Initiatives!$E$6="adoption",IF(D$3<Initiatives!$E$31,0,MIN((D$3-Initiatives!$E$31+1)/Initiatives!$E$34,1)),0) -> 0.5 | E36: =IF(Initiatives!$E$6="adoption",IF(E$3<Initiatives!$E$31,0,MIN((E$3-Initiatives!$E$31+1)/Initiatives!$E$34,1)),0) -> 1 | F36: =IF(Initiatives!$E$6="adoption",IF(F$3<Initiatives!$E$31,0,MIN((F$3-Initiatives!$E$31+1)/Initiatives!$E$34,1)),0) -> 1 | G36: =IF(Initiatives!$E$6="adoption",IF(G$3<Initiatives!$E$31,0,MIN((G$3-Initiatives!$E$31+1)/Initiatives!$E$34,1)),0) -> 1 | H36: =IF(Initiatives!$E$6="adoption",IF(H$3<Initiatives!$E$31,0,MIN((H$3-Initiatives!$E$31+1)/Initiatives!$E$34,1)),0) -> 1 | I36: =IF(Initiatives!$E$6="adoption",IF(I$3<Initiatives!$E$31,0,MIN((I$3-Initiatives!$E$31+1)/Initiatives!$E$34,1)),0) -> 1 | J36: =IF(Initiatives!$E$6="adoption",IF(J$3<Initiatives!$E$31,0,MIN((J$3-Initiatives!$E$31+1)/Initiatives!$E$34,1)),0) -> 1 | ... AL36: =IF(Initiatives!$E$6="adoption",IF(AL$3<Initiatives!$E$31,0,MIN((AL$3-Initiatives!$E$31+1)/Initiatives!$E$34,1)),0) -> 1
A37: Адоптеры (цель) | B37: target | C37: =Initiatives!$E$40*C36 -> 0 | D37: =Initiatives!$E$40*D36 -> 15681.6 | E37: =Initiatives!$E$40*E36 -> 31363.2 | F37: =Initiatives!$E$40*F36 -> 31363.2 | G37: =Initiatives!$E$40*G36 -> 31363.2 | H37: =Initiatives!$E$40*H36 -> 31363.2 | I37: =Initiatives!$E$40*I36 -> 31363.2 | J37: =Initiatives!$E$40*J36 -> 31363.2 | ... AL37: =Initiatives!$E$40*AL36 -> 31363.2
A38: Новые адоптеры | B38: new | C38: =MAX(C37-N(B37),0) -> 0 | D38: =MAX(D37-N(C37),0) -> 15681.6 | E38: =MAX(E37-N(D37),0) -> 15681.6 | F38: =MAX(F37-N(E37),0) -> 0 | G38: =MAX(G37-N(F37),0) -> 0 | H38: =MAX(H37-N(G37),0) -> 0 | I38: =MAX(I37-N(H37),0) -> 0 | J38: =MAX(J37-N(I37),0) -> 0 | ... AL38: =MAX(AL37-N(AK37),0) -> 0
A39: Удержанные | B39: R | C39: =IF(Initiatives!$E$6="adoption",N(B39)*(1-Inputs!$C$9)+N(B40)*Inputs!$C$9*Initiatives!$E$24,0) -> 0 | D39: =IF(Initiatives!$E$6="adoption",N(C39)*(1-Inputs!$C$9)+N(C40)*Inputs!$C$9*Initiatives!$E$24,0) -> 0 | E39: =IF(Initiatives!$E$6="adoption",N(D39)*(1-Inputs!$C$9)+N(D40)*Inputs!$C$9*Initiatives!$E$24,0) -> 11.7612 | F39: =IF(Initiatives!$E$6="adoption",N(E39)*(1-Inputs!$C$9)+N(E40)*Inputs!$C$9*Initiatives!$E$24,0) -> 34.939585 | G39: =IF(Initiatives!$E$6="adoption",N(F39)*(1-Inputs!$C$9)+N(F40)*Inputs!$C$9*Initiatives!$E$24,0) -> 57.437488 | H39: =IF(Initiatives!$E$6="adoption",N(G39)*(1-Inputs!$C$9)+N(G40)*Inputs!$C$9*Initiatives!$E$24,0) -> 79.269859 | I39: =IF(Initiatives!$E$6="adoption",N(H39)*(1-Inputs!$C$9)+N(H40)*Inputs!$C$9*Initiatives!$E$24,0) -> 100.45136 | J39: =IF(Initiatives!$E$6="adoption",N(I39)*(1-Inputs!$C$9)+N(I40)*Inputs!$C$9*Initiatives!$E$24,0) -> 120.99635 | ... AL39: =IF(Initiatives!$E$6="adoption",N(AK39)*(1-Inputs!$C$9)+N(AK40)*Inputs!$C$9*Initiatives!$E$24,0) -> 488.1477
A40: Пул адоптеров | B40: pool | C40: =N(B40)*(1-Inputs!$C$9*(1-Initiatives!$E$24))+C38 -> 0 | D40: =N(C40)*(1-Inputs!$C$9*(1-Initiatives!$E$24))+D38 -> 15681.6 | E40: =N(D40)*(1-Inputs!$C$9*(1-Initiatives!$E$24))+E38 -> 31139.737 | F40: =N(E40)*(1-Inputs!$C$9*(1-Initiatives!$E$24))+F38 -> 30695.996 | G40: =N(F40)*(1-Inputs!$C$9*(1-Initiatives!$E$24))+G38 -> 30258.578 | H40: =N(G40)*(1-Inputs!$C$9*(1-Initiatives!$E$24))+H38 -> 29827.393 | I40: =N(H40)*(1-Inputs!$C$9*(1-Initiatives!$E$24))+I38 -> 29402.353 | J40: =N(I40)*(1-Inputs!$C$9*(1-Initiatives!$E$24))+J38 -> 28983.369 | ... AL40: =N(AK40)*(1-Inputs!$C$9*(1-Initiatives!$E$24))+AL38 -> 19391.833
A41: Вес волн × затухание | B41: w | C41: =IF(Initiatives!$E$6="adoption",0,IF(C$3>=Initiatives!$E$31,Initiatives!$E$32*(1-Inputs!$C$9)^(C$3-Initiatives!$E$31),0)+IF(C$3>=Initiatives!$E$33,(1-Initiatives!$E$32)*(1-Inputs!$C$9)^(C$3-Initiatives!$E$33),0)) -> 0 | D41: =IF(Initiatives!$E$6="adoption",0,IF(D$3>=Initiatives!$E$31,Initiatives!$E$32*(1-Inputs!$C$9)^(D$3-Initiatives!$E$31),0)+IF(D$3>=Initiatives!$E$33,(1-Initiatives!$E$32)*(1-Inputs!$C$9)^(D$3-Initiatives!$E$33),0)) -> 0 | E41: =IF(Initiatives!$E$6="adoption",0,IF(E$3>=Initiatives!$E$31,Initiatives!$E$32*(1-Inputs!$C$9)^(E$3-Initiatives!$E$31),0)+IF(E$3>=Initiatives!$E$33,(1-Initiatives!$E$32)*(1-Inputs!$C$9)^(E$3-Initiatives!$E$33),0)) -> 0 | F41: =IF(Initiatives!$E$6="adoption",0,IF(F$3>=Initiatives!$E$31,Initiatives!$E$32*(1-Inputs!$C$9)^(F$3-Initiatives!$E$31),0)+IF(F$3>=Initiatives!$E$33,(1-Initiatives!$E$32)*(1-Inputs!$C$9)^(F$3-Initiatives!$E$33),0)) -> 0 | G41: =IF(Initiatives!$E$6="adoption",0,IF(G$3>=Initiatives!$E$31,Initiatives!$E$32*(1-Inputs!$C$9)^(G$3-Initiatives!$E$31),0)+IF(G$3>=Initiatives!$E$33,(1-Initiatives!$E$32)*(1-Inputs!$C$9)^(G$3-Initiatives!$E$33),0)) -> 0 | H41: =IF(Initiatives!$E$6="adoption",0,IF(H$3>=Initiatives!$E$31,Initiatives!$E$32*(1-Inputs!$C$9)^(H$3-Initiatives!$E$31),0)+IF(H$3>=Initiatives!$E$33,(1-Initiatives!$E$32)*(1-Inputs!$C$9)^(H$3-Initiatives!$E$33),0)) -> 0 | I41: =IF(Initiatives!$E$6="adoption",0,IF(I$3>=Initiatives!$E$31,Initiatives!$E$32*(1-Inputs!$C$9)^(I$3-Initiatives!$E$31),0)+IF(I$3>=Initiatives!$E$33,(1-Initiatives!$E$32)*(1-Inputs!$C$9)^(I$3-Initiatives!$E$33),0)) -> 0 | J41: =IF(Initiatives!$E$6="adoption",0,IF(J$3>=Initiatives!$E$31,Initiatives!$E$32*(1-Inputs!$C$9)^(J$3-Initiatives!$E$31),0)+IF(J$3>=Initiatives!$E$33,(1-Initiatives!$E$32)*(1-Inputs!$C$9)^(J$3-Initiatives!$E$33),0)) -> 0 | ... AL41: =IF(Initiatives!$E$6="adoption",0,IF(AL$3>=Initiatives!$E$31,Initiatives!$E$32*(1-Inputs!$C$9)^(AL$3-Initiatives!$E$31),0)+IF(AL$3>=Initiatives!$E$33,(1-Initiatives!$E$32)*(1-Inputs!$C$9)^(AL$3-Initiatives!$E$33),0)) -> 0
A42: Новый доп. отток | B42: newlost | C42: =IF(Initiatives!$E$6="adoption",IF(AND(C$3>=Initiatives!$E$31,C$3<Initiatives!$E$31+3),Initiatives!$E$44/3,0),IF(AND(C$3>=Initiatives!$E$31,C$3<Initiatives!$E$31+2),Initiatives!$E$32*Initiatives!$E$44/2,0)+IF(AND(C$3>=Initiatives!$E$33,C$3<Initiatives!$E$33+2),(1-Initiatives!$E$32)*Initiatives!$E$44/2,0)) -> 0 | D42: =IF(Initiatives!$E$6="adoption",IF(AND(D$3>=Initiatives!$E$31,D$3<Initiatives!$E$31+3),Initiatives!$E$44/3,0),IF(AND(D$3>=Initiatives!$E$31,D$3<Initiatives!$E$31+2),Initiatives!$E$32*Initiatives!$E$44/2,0)+IF(AND(D$3>=Initiatives!$E$33,D$3<Initiatives!$E$33+2),(1-Initiatives!$E$32)*Initiatives!$E$44/2,0)) -> 0 | E42: =IF(Initiatives!$E$6="adoption",IF(AND(E$3>=Initiatives!$E$31,E$3<Initiatives!$E$31+3),Initiatives!$E$44/3,0),IF(AND(E$3>=Initiatives!$E$31,E$3<Initiatives!$E$31+2),Initiatives!$E$32*Initiatives!$E$44/2,0)+IF(AND(E$3>=Initiatives!$E$33,E$3<Initiatives!$E$33+2),(1-Initiatives!$E$32)*Initiatives!$E$44/2,0)) -> 0 | F42: =IF(Initiatives!$E$6="adoption",IF(AND(F$3>=Initiatives!$E$31,F$3<Initiatives!$E$31+3),Initiatives!$E$44/3,0),IF(AND(F$3>=Initiatives!$E$31,F$3<Initiatives!$E$31+2),Initiatives!$E$32*Initiatives!$E$44/2,0)+IF(AND(F$3>=Initiatives!$E$33,F$3<Initiatives!$E$33+2),(1-Initiatives!$E$32)*Initiatives!$E$44/2,0)) -> 0 | G42: =IF(Initiatives!$E$6="adoption",IF(AND(G$3>=Initiatives!$E$31,G$3<Initiatives!$E$31+3),Initiatives!$E$44/3,0),IF(AND(G$3>=Initiatives!$E$31,G$3<Initiatives!$E$31+2),Initiatives!$E$32*Initiatives!$E$44/2,0)+IF(AND(G$3>=Initiatives!$E$33,G$3<Initiatives!$E$33+2),(1-Initiatives!$E$32)*Initiatives!$E$44/2,0)) -> 0 | H42: =IF(Initiatives!$E$6="adoption",IF(AND(H$3>=Initiatives!$E$31,H$3<Initiatives!$E$31+3),Initiatives!$E$44/3,0),IF(AND(H$3>=Initiatives!$E$31,H$3<Initiatives!$E$31+2),Initiatives!$E$32*Initiatives!$E$44/2,0)+IF(AND(H$3>=Initiatives!$E$33,H$3<Initiatives!$E$33+2),(1-Initiatives!$E$32)*Initiatives!$E$44/2,0)) -> 0 | I42: =IF(Initiatives!$E$6="adoption",IF(AND(I$3>=Initiatives!$E$31,I$3<Initiatives!$E$31+3),Initiatives!$E$44/3,0),IF(AND(I$3>=Initiatives!$E$31,I$3<Initiatives!$E$31+2),Initiatives!$E$32*Initiatives!$E$44/2,0)+IF(AND(I$3>=Initiatives!$E$33,I$3<Initiatives!$E$33+2),(1-Initiatives!$E$32)*Initiatives!$E$44/2,0)) -> 0 | J42: =IF(Initiatives!$E$6="adoption",IF(AND(J$3>=Initiatives!$E$31,J$3<Initiatives!$E$31+3),Initiatives!$E$44/3,0),IF(AND(J$3>=Initiatives!$E$31,J$3<Initiatives!$E$31+2),Initiatives!$E$32*Initiatives!$E$44/2,0)+IF(AND(J$3>=Initiatives!$E$33,J$3<Initiatives!$E$33+2),(1-Initiatives!$E$32)*Initiatives!$E$44/2,0)) -> 0 | ... AL42: =IF(Initiatives!$E$6="adoption",IF(AND(AL$3>=Initiatives!$E$31,AL$3<Initiatives!$E$31+3),Initiatives!$E$44/3,0),IF(AND(AL$3>=Initiatives!$E$31,AL$3<Initiatives!$E$31+2),Initiatives!$E$32*Initiatives!$E$44/2,0)+IF(AND(AL$3>=Initiatives!$E$33,AL$3<Initiatives!$E$33+2),(1-Initiatives!$E$32)*Initiatives!$E$44/2,0)) -> 0
A43: Потерянные | B43: L | C43: =N(B43)*(1-Inputs!$C$9)+C42 -> 0 | D43: =N(C43)*(1-Inputs!$C$9)+D42 -> 0 | E43: =N(D43)*(1-Inputs!$C$9)+E42 -> 0 | F43: =N(E43)*(1-Inputs!$C$9)+F42 -> 0 | G43: =N(F43)*(1-Inputs!$C$9)+G42 -> 0 | H43: =N(G43)*(1-Inputs!$C$9)+H42 -> 0 | I43: =N(H43)*(1-Inputs!$C$9)+I42 -> 0 | J43: =N(I43)*(1-Inputs!$C$9)+J42 -> 0 | ... AL43: =N(AK43)*(1-Inputs!$C$9)+AL42 -> 0
A44: Инкр. выручка | B44: rev | C44: =IF(Initiatives!$E$6="adoption",C40*Initiatives!$E$23+C39*Initiatives!$E$8-C43*Initiatives!$E$8,(Initiatives!$E$42*Initiatives!$E$41+Initiatives!$E$38*Initiatives!$E$13*Initiatives!$E$14+Initiatives!$E$43*Initiatives!$E$16)*C41-C43*Initiatives!$E$8) -> 0 | D44: =IF(Initiatives!$E$6="adoption",D40*Initiatives!$E$23+D39*Initiatives!$E$8-D43*Initiatives!$E$8,(Initiatives!$E$42*Initiatives!$E$41+Initiatives!$E$38*Initiatives!$E$13*Initiatives!$E$14+Initiatives!$E$43*Initiatives!$E$16)*D41-D43*Initiatives!$E$8) -> 117612000 | E44: =IF(Initiatives!$E$6="adoption",E40*Initiatives!$E$23+E39*Initiatives!$E$8-E43*Initiatives!$E$8,(Initiatives!$E$42*Initiatives!$E$41+Initiatives!$E$38*Initiatives!$E$13*Initiatives!$E$14+Initiatives!$E$43*Initiatives!$E$16)*E41-E43*Initiatives!$E$8) -> 2.3387734e+08 | F44: =IF(Initiatives!$E$6="adoption",F40*Initiatives!$E$23+F39*Initiatives!$E$8-F43*Initiatives!$E$8,(Initiatives!$E$42*Initiatives!$E$41+Initiatives!$E$38*Initiatives!$E$13*Initiatives!$E$14+Initiatives!$E$43*Initiatives!$E$16)*F41-F43*Initiatives!$E$8) -> 2.3119828e+08 | G44: =IF(Initiatives!$E$6="adoption",G40*Initiatives!$E$23+G39*Initiatives!$E$8-G43*Initiatives!$E$8,(Initiatives!$E$42*Initiatives!$E$41+Initiatives!$E$38*Initiatives!$E$13*Initiatives!$E$14+Initiatives!$E$43*Initiatives!$E$16)*G41-G43*Initiatives!$E$8) -> 2.2854758e+08 | H44: =IF(Initiatives!$E$6="adoption",H40*Initiatives!$E$23+H39*Initiatives!$E$8-H43*Initiatives!$E$8,(Initiatives!$E$42*Initiatives!$E$41+Initiatives!$E$38*Initiatives!$E$13*Initiatives!$E$14+Initiatives!$E$43*Initiatives!$E$16)*H41-H43*Initiatives!$E$8) -> 2.2592501e+08 | I44: =IF(Initiatives!$E$6="adoption",I40*Initiatives!$E$23+I39*Initiatives!$E$8-I43*Initiatives!$E$8,(Initiatives!$E$42*Initiatives!$E$41+Initiatives!$E$38*Initiatives!$E$13*Initiatives!$E$14+Initiatives!$E$43*Initiatives!$E$16)*I41-I43*Initiatives!$E$8) -> 2.2333028e+08 | J44: =IF(Initiatives!$E$6="adoption",J40*Initiatives!$E$23+J39*Initiatives!$E$8-J43*Initiatives!$E$8,(Initiatives!$E$42*Initiatives!$E$41+Initiatives!$E$38*Initiatives!$E$13*Initiatives!$E$14+Initiatives!$E$43*Initiatives!$E$16)*J41-J43*Initiatives!$E$8) -> 2.2076317e+08 | ... AL44: =IF(Initiatives!$E$6="adoption",AL40*Initiatives!$E$23+AL39*Initiatives!$E$8-AL43*Initiatives!$E$8,(Initiatives!$E$42*Initiatives!$E$41+Initiatives!$E$38*Initiatives!$E$13*Initiatives!$E$14+Initiatives!$E$43*Initiatives!$E$16)*AL41-AL43*Initiatives!$E$8) -> 1.5910689e+08
...

Sheet Loyalty_Inputs
A1: Loyalty program: параметры
A3: Параметр | B3: Ключ | C3: Значение | D3: Комментарий
A4: MAU приложения / база | B4: app_mau_share | C4: 0.27 | D4: HYPOTHESIS — запрос L1
A5: Вступили в программу из MAU | B5: enroll_of_mau | C5: 0.5 | D5: HYPOTHESIS; проверяется MVP
A6: Доля архивных среди участников | B6: archive_share_members | C6: 0.2 | D6: HYPOTHESIS — запрос L1
A7: Участников MVP | B7: mvp_participants | C7: 150000 | D7: Стратифицированная выборка
A8: Месяц старта MVP (M5 = март 2027) | B8: mvp_start | C8: 5
A9: Длительность MVP, мес. | B9: mvp_months | C9: 3
A10: Месяц старта масштаба (M11 = сентябрь 2027) | B10: scale_start | C10: 11
A11: Набор участников при масштабе, мес. | B11: scale_ramp | C11: 6
A12: Доля оплат вовремя (кэшбэк только им) | B12: ontime_share | C12: 0.85 | D12: запрос L3
A13: Breakage: монеты не потрачены (12 мес.) | B13: breakage | C13: 0.3 | D13: Бенчмарки 25–40%
A14: Себестоимость погашения монет | B14: redeem_cost_ratio | C14: 0.515 | D14: 50% услуги×0,15 + 30% счёт×1 + 20% мерч×0,7
A15: Ежедневно открывают сундук (доля участников) | B15: drops_dau_share | C15: 0.3 | D15: проверяется MVP
A16: Призовые фонды MVP, доля от масштаба | B16: mvp_prize_share | C16: 0.3
A17: Разработка MVP, сум | B17: mvp_build | C17: 1800000000 | D17: web-view в приложении
A18: Разработка масштаба, сум | B18: scale_build | C18: 3000000000
A19: OPEX MVP, сум/мес | B19: mvp_opex_m | C19: 120000000
A20: OPEX программы, сум/мес | B20: opex_m | C20: 250000000 | D20: команда, лицензии, фулфилмент, КЦ
A21: Маркетинг, сум/мес | B21: marketing_m | C21: 150000000
A22: Маркетинг запуска масштаба, сум | B22: launch_marketing | C22: 1500000000
A23: Маркетинг MVP, сум | B23: mvp_marketing | C23: 250000000
A24: Месячный отток участников (база) | B24: member_churn_base | C24: 0.012 | D24: запрос L4
A25: Снижение оттока участников (отн.) | B25: churn_reduction | C25: 0.15 | D25: T-Mobile Tuesdays −27% (с самоотбором)
A26: Рост выручки от оплат вовремя | B26: ontime_rev_uplift | C26: 0.015 | D26: H2 MVP
A27: Доп. переходы на ТП ≥ 60 тыс., в мес. | B27: upgrade_rate_m | C27: 0.004 | D27: H1 MVP — главный драйвер
A28: ΔARPU при переходе, сум | B28: upgrade_delta | C28: 20000
A29: Club+ Pass: доля участников < 60 тыс. | B29: pass_adoption | C29: 0.03 | D29: H3 MVP
A30: Club+ Pass: цена с НДС, сум/мес | B30: pass_price_gross | C30: 9999
A31: Себестоимость ценности Pass | B31: pass_value_cost | C31: 0.25 | D31: ГБ, ×1,5 кэшбэк
